Workbook

Sheet History
B2: ROM_MAP PRO Update History
B5: History
B6: Date | C6: Name | D6: Comment
B7: 41218 | C7: K.Yokoyama | D7: 新規作成（RS_M9MO_DICAベース）
B8: 41263 | C8: M.Nagakura | D8: SV/EV連動対応
B9: 41264 | C9: M.Nagakura | D9: Bayer Noise Reduction 1をMonitor, Still, HD, Full HDの4種類を持たせられるように
B10: 41264 | C10: T.Aizawa | D10: Bayer resize率 6段対応
B11: 41266 | C11: Y.Hanazono | D11: SyncSV/EVコミット直前の本線の値を取り込み
B12: 41266 | C12: Ikushima | D12: ABGAR,ABGAG,ABGABの初期値を0x0000にして色収差をOFFにする
B13: 41267 | C13: ikeda | D13: CAG初期値入力
B14: 41267 | C14: S.Takahashi | D14: Knee/Deknee table 変更
B15: 41267 | C15: ikeda | D15: BayerResize対応Memmap初期値入力
B16: 41267 | C16: ikeda | D16: BayerResize対応Memmap調整値入力
B17: 41271 | C17: Yanagisawa | D17: ParamManageからパラメータ展開した1st FW(動作確認ＯＫ)
B18: 41274 | C18: ikeda | D18: CES向け preview indoor tuning
... B36: 41831 | C36: K.Aso | D36: Smartisanのテーブルマージ。Used by Touch AE以降に追加。
BV145: s

Sheet ROM_MAP
C1: ROM_MAP PROマクロ
B5: Section | C5: Group | D5: Byte 数 | E5: MACRO | F5: address | G5: Name | I5: Init Value | J5: Update | K5: note
G6: 15 (even) 8 | H6: 7 (odd) 0 | I6: hexadecimal
B7: 1 | C7: AE Weight Table | E7: JDSPRO | F7: 0x00000000 | G7: AE_BLOCK_WEIGHT_0 | H7: AE_BLOCK_WEIGHT_1 | I7: ="0x"&AE_w_WORK!D6 -> 0xFFFF | J7: 40473 | K7: All block integral
B8: 2 | E8: JDSPRO | F8: 0x00000002 | G8: AE_BLOCK_WEIGHT_2 | H8: AE_BLOCK_WEIGHT_3 | I8: ="0x"&AE_w_WORK!D7 -> 0xFFFF | J8: 40473
B9: 3 | E9: JDSPRO | F9: 0x00000004 | G9: AE_BLOCK_WEIGHT_4 | H9: AE_BLOCK_WEIGHT_5 | I9: ="0x"&AE_w_WORK!D8 -> 0xFFFF | J9: 40473
B10: 4 | E10: JDSPRO | F10: 0x00000006 | G10: AE_BLOCK_WEIGHT_6 | H10: AE_BLOCK_WEIGHT_7 | I10: ="0x"&AE_w_WORK!D9 -> 0xFFFF | J10: 40473
B11: 5 | E11: JDSPRO | F11: 0x00000008 | G11: AE_BLOCK_WEIGHT_8 | H11: AE_BLOCK_WEIGHT_9 | I11: ="0x"&AE_w_WORK!D10 -> 0xFFFF | J11: 40473
B12: 6 | E12: JDSPRO | F12: 0x0000000A | G12: AE_BLOCK_WEIGHT_10 | H12: AE_BLOCK_WEIGHT_11 | I12: ="0x"&AE_w_WORK!D11 -> 0xFFFF | J12: 40473
B13: 7 | E13: JDSPRO | F13: 0x0000000C | G13: AE_BLOCK_WEIGHT_12 | H13: AE_BLOCK_WEIGHT_13 | I13: ="0x"&AE_w_WORK!D12 -> 0xFFFF | J13: 40473
B14: 8 | E14: JDSPRO | F14: 0x0000000E | G14: AE_BLOCK_WEIGHT_14 | H14: AE_BLOCK_WEIGHT_15 | I14: ="0x"&AE_w_WORK!D13 -> 0xFFFF | J14: 40473
B15: 9 | E15: JDSPRO | F15: 0x00000010 | G15: AE_BLOCK_WEIGHT_16 | H15: AE_BLOCK_WEIGHT_17 | I15: ="0x"&AE_w_WORK!D14 -> 0xFFFF | J15: 40473
B16: 10 | E16: JDSPRO | F16: 0x00000012 | G16: AE_BLOCK_WEIGHT_18 | H16: AE_BLOCK_WEIGHT_19 | I16: ="0x"&AE_w_WORK!D15 -> 0xFFFF | J16: 40473
B17: 11 | E17: JDSPRO | F17: 0x00000014 | G17: AE_BLOCK_WEIGHT_20 | H17: AE_BLOCK_WEIGHT_21 | I17: ="0x"&AE_w_WORK!D16 -> 0xFFFF | J17: 40473
B18: 12 | E18: JDSPRO | F18: 0x00000016 | G18: AE_BLOCK_WEIGHT_22 | H18: AE_BLOCK_WEIGHT_23 | I18: ="0x"&AE_w_WORK!D17 -> 0xFFFF | J18: 40473
B19: 13 | E19: JDSPRO | F19: 0x00000018 | G19: AE_BLOCK_WEIGHT_24 | H19: AE_BLOCK_WEIGHT_25 | I19: ="0x"&AE_w_WORK!D18 -> 0xFFFF | J19: 40473
... B134: 128 | E134: JDSPRO | F134: 0x000000FE | G134: AE_BLOCK_WEIGHT_254 | H134: AE_BLOCK_WEIGHT_255 | I134: ="0x"&AE_w_WORK!D133 -> 0xFFFF | J134: 40473
B135: 129 | E135: JDSPRO | F135: 0x00000100 | G135: AE_BLOCK_WEIGHT_0 | H135: AE_BLOCK_WEIGHT_1 | I135: ="0x"&AE_w_WORK!E6 -> 0x0000 | J135: 40473 | K135: Center-weighted average 1
B136: 130 | E136: JDSPRO | F136: 0x00000102 | G136: AE_BLOCK_WEIGHT_2 | H136: AE_BLOCK_WEIGHT_3 | I136: ="0x"&AE_w_WORK!E7 -> 0x0000 | J136: 40473
B137: 131 | E137: JDSPRO | F137: 0x00000104 | G137: AE_BLOCK_WEIGHT_4 | H137: AE_BLOCK_WEIGHT_5 | I137: ="0x"&AE_w_WORK!E8 -> 0x0000 | J137: 40473
B138: 132 | E138: JDSPRO | F138: 0x00000106 | G138: AE_BLOCK_WEIGHT_6 | H138: AE_BLOCK_WEIGHT_7 | I138: ="0x"&AE_w_WORK!E9 -> 0x0000 | J138: 40473
B139: 133 | E139: JDSPRO | F139: 0x00000108 | G139: AE_BLOCK_WEIGHT_8 | H139: AE_BLOCK_WEIGHT_9 | I139: ="0x"&AE_w_WORK!E10 -> 0x0000 | J139: 40473
B140: 134 | E140: JDSPRO | F140: 0x0000010A | G140: AE_BLOCK_WEIGHT_10 | H140: AE_BLOCK_WEIGHT_11 | I140: ="0x"&AE_w_WORK!E11 -> 0x0000 | J140: 40473
B141: 135 | E141: JDSPRO | F141: 0x0000010C | G141: AE_BLOCK_WEIGHT_12 | H141: AE_BLOCK_WEIGHT_13 | I141: ="0x"&AE_w_WORK!E12 -> 0x0000 | J141: 40473
B142: 136 | E142: JDSPRO | F142: 0x0000010E | G142: AE_BLOCK_WEIGHT_14 | H142: AE_BLOCK_WEIGHT_15 | I142: ="0x"&AE_w_WORK!E13 -> 0x0000 | J142: 40473
B143: 137 | E143: JDSPRO | F143: 0x00000110 | G143: AE_BLOCK_WEIGHT_16 | H143: AE_BLOCK_WEIGHT_17 | I143: ="0x"&AE_w_WORK!E14 -> 0x0000 | J143: 40473
B144: 138 | E144: JDSPRO | F144: 0x00000112 | G144: AE_BLOCK_WEIGHT_18 | H144: AE_BLOCK_WEIGHT_19 | I144: ="0x"&AE_w_WORK!E15 -> 0x0000 | J144: 40473
B145: 139 | E145: JDSPRO | F145: 0x00000114 | G145: AE_BLOCK_WEIGHT_20 | H145: AE_BLOCK_WEIGHT_21 | I145: ="0x"&AE_w_WORK!E16 -> 0x0000 | J145: 40473
B146: 140 | E146: JDSPRO | F146: 0x00000116 | G146: AE_BLOCK_WEIGHT_22 | H146: AE_BLOCK_WEIGHT_23 | I146: ="0x"&AE_w_WORK!E17 -> 0x0000 | J146: 40473
B147: 141 | E147: JDSPRO | F147: 0x00000118 | G147: AE_BLOCK_WEIGHT_24 | H147: AE_BLOCK_WEIGHT_25 | I147: ="0x"&AE_w_WORK!E18 -> 0x0000 | J147: 40473
... B262: 256 | E262: JDSPRO | F262: 0x000001FE | G262: AE_BLOCK_WEIGHT_254 | H262: AE_BLOCK_WEIGHT_255 | I262: ="0x"&AE_w_WORK!E133 -> 0x0000 | J262: 40473
B263: 257 | E263: JDSPRO | F263: 0x00000200 | G263: AE_BLOCK_WEIGHT_0 | H263: AE_BLOCK_WEIGHT_1 | I263: ="0x"&AE_w_WORK!F6 -> 0x0000 | J263: 40473 | K263: Center-weighted average 2
B264: 258 | E264: JDSPRO | F264: 0x00000202 | G264: AE_BLOCK_WEIGHT_2 | H264: AE_BLOCK_WEIGHT_3 | I264: ="0x"&AE_w_WORK!F7 -> 0x0000 | J264: 40473
B265: 259 | E265: JDSPRO | F265: 0x00000204 | G265: AE_BLOCK_WEIGHT_4 | H265: AE_BLOCK_WEIGHT_5 | I265: ="0x"&AE_w_WORK!F8 -> 0x0000 | J265: 40473
B266: 260 | E266: JDSPRO | F266: 0x00000206 | G266: AE_BLOCK_WEIGHT_6 | H266: AE_BLOCK_WEIGHT_7 | I266: ="0x"&AE_w_WORK!F9 -> 0x0000 | J266: 40473
B267: 261 | E267: JDSPRO | F267: 0x00000208 | G267: AE_BLOCK_WEIGHT_8 | H267: AE_BLOCK_WEIGHT_9 | I267: ="0x"&AE_w_WORK!F10 -> 0x0000 | J267: 40473
B268: 262 | E268: JDSPRO | F268: 0x0000020A | G268: AE_BLOCK_WEIGHT_10 | H268: AE_BLOCK_WEIGHT_11 | I268: ="0x"&AE_w_WORK!F11 -> 0x0000 | J268: 40473
B269: 263 | E269: JDSPRO | F269: 0x0000020C | G269: AE_BLOCK_WEIGHT_12 | H269: AE_BLOCK_WEIGHT_13 | I269: ="0x"&AE_w_WORK!F12 -> 0x0000 | J269: 40473
B270: 264 | E270: JDSPRO | F270: 0x0000020E | G270: AE_BLOCK_WEIGHT_14 | H270: AE_BLOCK_WEIGHT_15 | I270: ="0x"&AE_w_WORK!F13 -> 0x0000 | J270: 40473
B271: 265 | E271: JDSPRO | F271: 0x00000210 | G271: AE_BLOCK_WEIGHT_16 | H271: AE_BLOCK_WEIGHT_17 | I271: ="0x"&AE_w_WORK!F14 -> 0x0000 | J271: 40473
...

Sheet ROM_WORK
B6: Whole of ROM structure | C6: Name of BIN file | D6: AE_WEIGHT_MAP.BIN | F6: Detail:Detail information cell name(At the jump destination)
C7: Name of Header file | D7: ae_weight_map.h | F7: Structures:Structure:1 = array, 2 = structure, 3 = Register map, 4 = Menber
C8: Name of Memory File | D8: ae_weight_map.c | F8: Siz: Size: When using array, size of basic type
C9: Memory Map Address | D9: 0x0 | F9: Number of parameter set:When using 2 dimensional array, Number of elements of output data arrays
C10: Nameof Section | D10: AE_WEIGHT_MAP_SECTION | F10: Number of complete set:When using 3 dimensional array, Number of elements of output data arrays
C11: Name of variable | D11: AE_WEIGHT_MEM
C12: Name of Structure | D12: _AE_Weight_map
C13: Name of RAM MAP Add. | D13: ram_map.h
K14: Init Value
B15: Name | C15: Address | D15: Name of Structure | E15: Name of member variable | F15: Detail | G15: Strucures | H15: Size | I15: Number of parameter set | J15: Number of complete set | K15: Sheet | L15: Cell
B16: AE Weight Table | C16: =VLOOKUP(B16,ROM_MAP!$C$1:$F$27535,4,FALSE) -> 0x00000000 | D16: _ae_weight | E16: AE_WEIGHT | F16: ="B"&ROW(B23) -> B23 | G16: 2 | I16: 13
B17: End Address + 1 | C17: =VLOOKUP(B17,ROM_MAP!$C$7:$F$27535,4,FALSE) -> 0x00000D00
B19: Data for detail refer
B22: Detail of AE Weight Table structure
B23: AE Weight Table | C23: =VLOOKUP(B23,B16:C16,2,FALSE) -> 0x00000000 | D23: _ae_weight | E23: AE_W | G23: 1 | H23: 1 | I23: 1 | J23: 1
B24: End Address + 1 | C24: ="0x"&DEC2HEX(HEX2DEC(REPLACE(C23,1,2,""))+256,8) -> 0x00000100

Sheet AE_weight
A1: Setting of AE Weight Table
A2: * Only the value of a black, bold above the line is reflected in "ROM_MAP"sheet. The value of a possible setting is 0-7. | U2: =A1&"Work領域" -> Setting of AE Weight TableWork領域 | AA2: テーブル色塗り範囲指定
A3: 1.All block integral (Storage to ROM) | U3: =A3 -> 1.All block integral (Storage to ROM) | AA3: 下限 | AB3: 上限
C4: 0 | D4: 1 | E4: 2 | F4: 3 | G4: 4 | H4: 5 | I4: 6 | J4: 7 | K4: 8 | L4: 9 | M4: 10 | N4: 11 | O4: 12 | P4: 13 | Q4: 14 | R4: 15 | V4: =C4&D4&E4&F4 -> 0123 | W4: =G4&H4&I4&J4 -> 4567 | X4: =K4&L4&M4&N4 -> 891011 | Y4: =O4&P4&Q4&R4 -> 12131415 | AA4: 15 | AB4: 15
B5: 0 | C5: 15 | D5: 15 | E5: 15 | F5: 15 | G5: 15 | H5: 15 | I5: 15 | J5: 15 | K5: 15 | L5: 15 | M5: 15 | N5: 15 | O5: 15 | P5: 15 | Q5: 15 | R5: 15 | U5: =B5 -> 0 | V5: =DEC2HEX(C5)&DEC2HEX(D5)&DEC2HEX(E5)&DEC2HEX(F5) -> FFFF | W5: =DEC2HEX(G5)&DEC2HEX(H5)&DEC2HEX(I5)&DEC2HEX(J5) -> FFFF | X5: =DEC2HEX(K5)&DEC2HEX(L5)&DEC2HEX(M5)&DEC2HEX(N5) -> FFFF | Y5: =DEC2HEX(O5)&DEC2HEX(P5)&DEC2HEX(Q5)&DEC2HEX(R5) -> FFFF | AA5: 13 | AB5: 13
B6: 1 | C6: 15 | D6: 15 | E6: 15 | F6: 15 | G6: 15 | H6: 15 | I6: 15 | J6: 15 | K6: 15 | L6: 15 | M6: 15 | N6: 15 | O6: 15 | P6: 15 | Q6: 15 | R6: 15 | U6: =B6 -> 1 | V6: =DEC2HEX(C6)&DEC2HEX(D6)&DEC2HEX(E6)&DEC2HEX(F6) -> FFFF | W6: =DEC2HEX(G6)&DEC2HEX(H6)&DEC2HEX(I6)&DEC2HEX(J6) -> FFFF | X6: =DEC2HEX(K6)&DEC2HEX(L6)&DEC2HEX(M6)&DEC2HEX(N6) -> FFFF | Y6: =DEC2HEX(O6)&DEC2HEX(P6)&DEC2HEX(Q6)&DEC2HEX(R6) -> FFFF | AA6: 11 | AB6: 11
B7: 2 | C7: 15 | D7: 15 | E7: 15 | F7: 15 | G7: 15 | H7: 15 | I7: 15 | J7: 15 | K7: 15 | L7: 15 | M7: 15 | N7: 15 | O7: 15 | P7: 15 | Q7: 15 | R7: 15 | U7: =B7 -> 2 | V7: =DEC2HEX(C7)&DEC2HEX(D7)&DEC2HEX(E7)&DEC2HEX(F7) -> FFFF | W7: =DEC2HEX(G7)&DEC2HEX(H7)&DEC2HEX(I7)&DEC2HEX(J7) -> FFFF | X7: =DEC2HEX(K7)&DEC2HEX(L7)&DEC2HEX(M7)&DEC2HEX(N7) -> FFFF | Y7: =DEC2HEX(O7)&DEC2HEX(P7)&DEC2HEX(Q7)&DEC2HEX(R7) -> FFFF | AA7: 8 | AB7: 8
B8: 3 | C8: 15 | D8: 15 | E8: 15 | F8: 15 | G8: 15 | H8: 15 | I8: 15 | J8: 15 | K8: 15 | L8: 15 | M8: 15 | N8: 15 | O8: 15 | P8: 15 | Q8: 15 | R8: 15 | U8: =B8 -> 3 | V8: =DEC2HEX(C8)&DEC2HEX(D8)&DEC2HEX(E8)&DEC2HEX(F8) -> FFFF | W8: =DEC2HEX(G8)&DEC2HEX(H8)&DEC2HEX(I8)&DEC2HEX(J8) -> FFFF | X8: =DEC2HEX(K8)&DEC2HEX(L8)&DEC2HEX(M8)&DEC2HEX(N8) -> FFFF | Y8: =DEC2HEX(O8)&DEC2HEX(P8)&DEC2HEX(Q8)&DEC2HEX(R8) -> FFFF | AA8: 6 | AB8: 6
B9: 4 | C9: 15 | D9: 15 | E9: 15 | F9: 15 | G9: 15 | H9: 15 | I9: 15 | J9: 15 | K9: 15 | L9: 15 | M9: 15 | N9: 15 | O9: 15 | P9: 15 | Q9: 15 | R9: 15 | U9: =B9 -> 4 | V9: =DEC2HEX(C9)&DEC2HEX(D9)&DEC2HEX(E9)&DEC2HEX(F9) -> FFFF | W9: =DEC2HEX(G9)&DEC2HEX(H9)&DEC2HEX(I9)&DEC2HEX(J9) -> FFFF | X9: =DEC2HEX(K9)&DEC2HEX(L9)&DEC2HEX(M9)&DEC2HEX(N9) -> FFFF | Y9: =DEC2HEX(O9)&DEC2HEX(P9)&DEC2HEX(Q9)&DEC2HEX(R9) -> FFFF | AA9: 4 | AB9: 4
B10: 5 | C10: 15 | D10: 15 | E10: 15 | F10: 15 | G10: 15 | H10: 15 | I10: 15 | J10: 15 | K10: 15 | L10: 15 | M10: 15 | N10: 15 | O10: 15 | P10: 15 | Q10: 15 | R10: 15 | U10: =B10 -> 5 | V10: =DEC2HEX(C10)&DEC2HEX(D10)&DEC2HEX(E10)&DEC2HEX(F10) -> FFFF | W10: =DEC2HEX(G10)&DEC2HEX(H10)&DEC2HEX(I10)&DEC2HEX(J10) -> FFFF | X10: =DEC2HEX(K10)&DEC2HEX(L10)&DEC2HEX(M10)&DEC2HEX(N10) -> FFFF | Y10: =DEC2HEX(O10)&DEC2HEX(P10)&DEC2HEX(Q10)&DEC2HEX(R10) -> FFFF | AA10: 2 | AB10: 3
B11: 6 | C11: 15 | D11: 15 | E11: 15 | F11: 15 | G11: 15 | H11: 15 | I11: 15 | J11: 15 | K11: 15 | L11: 15 | M11: 15 | N11: 15 | O11: 15 | P11: 15 | Q11: 15 | R11: 15 | U11: =B11 -> 6 | V11: =DEC2HEX(C11)&DEC2HEX(D11)&DEC2HEX(E11)&DEC2HEX(F11) -> FFFF | W11: =DEC2HEX(G11)&DEC2HEX(H11)&DEC2HEX(I11)&DEC2HEX(J11) -> FFFF | X11: =DEC2HEX(K11)&DEC2HEX(L11)&DEC2HEX(M11)&DEC2HEX(N11) -> FFFF | Y11: =DEC2HEX(O11)&DEC2HEX(P11)&DEC2HEX(Q11)&DEC2HEX(R11) -> FFFF | AA11: 1 | AB11: 1
B12: 7 | C12: 15 | D12: 15 | E12: 15 | F12: 15 | G12: 15 | H12: 15 | I12: 15 | J12: 15 | K12: 15 | L12: 15 | M12: 15 | N12: 15 | O12: 15 | P12: 15 | Q12: 15 | R12: 15 | U12: =B12 -> 7 | V12: =DEC2HEX(C12)&DEC2HEX(D12)&DEC2HEX(E12)&DEC2HEX(F12) -> FFFF | W12: =DEC2HEX(G12)&DEC2HEX(H12)&DEC2HEX(I12)&DEC2HEX(J12) -> FFFF | X12: =DEC2HEX(K12)&DEC2HEX(L12)&DEC2HEX(M12)&DEC2HEX(N12) -> FFFF | Y12: =DEC2HEX(O12)&DEC2HEX(P12)&DEC2HEX(Q12)&DEC2HEX(R12) -> FFFF
B13: 8 | C13: 15 | D13: 15 | E13: 15 | F13: 15 | G13: 15 | H13: 15 | I13: 15 | J13: 15 | K13: 15 | L13: 15 | M13: 15 | N13: 15 | O13: 15 | P13: 15 | Q13: 15 | R13: 15 | U13: =B13 -> 8 | V13: =DEC2HEX(C13)&DEC2HEX(D13)&DEC2HEX(E13)&DEC2HEX(F13) -> FFFF | W13: =DEC2HEX(G13)&DEC2HEX(H13)&DEC2HEX(I13)&DEC2HEX(J13) -> FFFF | X13: =DEC2HEX(K13)&DEC2HEX(L13)&DEC2HEX(M13)&DEC2HEX(N13) -> FFFF | Y13: =DEC2HEX(O13)&DEC2HEX(P13)&DEC2HEX(Q13)&DEC2HEX(R13) -> FFFF | AA13: 重み係数指定
B14: 9 | C14: 15 | D14: 15 | E14: 15 | F14: 15 | G14: 15 | H14: 15 | I14: 15 | J14: 15 | K14: 15 | L14: 15 | M14: 15 | N14: 15 | O14: 15 | P14: 15 | Q14: 15 | R14: 15 | U14: =B14 -> 9 | V14: =DEC2HEX(C14)&DEC2HEX(D14)&DEC2HEX(E14)&DEC2HEX(F14) -> FFFF | W14: =DEC2HEX(G14)&DEC2HEX(H14)&DEC2HEX(I14)&DEC2HEX(J14) -> FFFF | X14: =DEC2HEX(K14)&DEC2HEX(L14)&DEC2HEX(M14)&DEC2HEX(N14) -> FFFF | Y14: =DEC2HEX(O14)&DEC2HEX(P14)&DEC2HEX(Q14)&DEC2HEX(R14) -> FFFF | AA14: 設定値 | AB14: 重み係数
B15: 10 | C15: 15 | D15: 15 | E15: 15 | F15: 15 | G15: 15 | H15: 15 | I15: 15 | J15: 15 | K15: 15 | L15: 15 | M15: 15 | N15: 15 | O15: 15 | P15: 15 | Q15: 15 | R15: 15 | U15: =B15 -> 10 | V15: =DEC2HEX(C15)&DEC2HEX(D15)&DEC2HEX(E15)&DEC2HEX(F15) -> FFFF | W15: =DEC2HEX(G15)&DEC2HEX(H15)&DEC2HEX(I15)&DEC2HEX(J15) -> FFFF | X15: =DEC2HEX(K15)&DEC2HEX(L15)&DEC2HEX(M15)&DEC2HEX(N15) -> FFFF | Y15: =DEC2HEX(O15)&DEC2HEX(P15)&DEC2HEX(Q15)&DEC2HEX(R15) -> FFFF | AA15: 0 | AB15: 積算しない
B16: 11 | C16: 15 | D16: 15 | E16: 15 | F16: 15 | G16: 15 | H16: 15 | I16: 15 | J16: 15 | K16: 15 | L16: 15 | M16: 15 | N16: 15 | O16: 15 | P16: 15 | Q16: 15 | R16: 15 | U16: =B16 -> 11 | V16: =DEC2HEX(C16)&DEC2HEX(D16)&DEC2HEX(E16)&DEC2HEX(F16) -> FFFF | W16: =DEC2HEX(G16)&DEC2HEX(H16)&DEC2HEX(I16)&DEC2HEX(J16) -> FFFF | X16: =DEC2HEX(K16)&DEC2HEX(L16)&DEC2HEX(M16)&DEC2HEX(N16) -> FFFF | Y16: =DEC2HEX(O16)&DEC2HEX(P16)&DEC2HEX(Q16)&DEC2HEX(R16) -> FFFF | AA16: 1 | AB16: 積算結果 * 1/16
B17: 12 | C17: 15 | D17: 15 | E17: 15 | F17: 15 | G17: 15 | H17: 15 | I17: 15 | J17: 15 | K17: 15 | L17: 15 | M17: 15 | N17: 15 | O17: 15 | P17: 15 | Q17: 15 | R17: 15 | U17: =B17 -> 12 | V17: =DEC2HEX(C17)&DEC2HEX(D17)&DEC2HEX(E17)&DEC2HEX(F17) -> FFFF | W17: =DEC2HEX(G17)&DEC2HEX(H17)&DEC2HEX(I17)&DEC2HEX(J17) -> FFFF | X17: =DEC2HEX(K17)&DEC2HEX(L17)&DEC2HEX(M17)&DEC2HEX(N17) -> FFFF | Y17: =DEC2HEX(O17)&DEC2HEX(P17)&DEC2HEX(Q17)&DEC2HEX(R17) -> FFFF | AA17: 2 | AB17: 積算結果 * 2/16
B18: 13 | C18: 15 | D18: 15 | E18: 15 | F18: 15 | G18: 15 | H18: 15 | I18: 15 | J18: 15 | K18: 15 | L18: 15 | M18: 15 | N18: 15 | O18: 15 | P18: 15 | Q18: 15 | R18: 15 | U18: =B18 -> 13 | V18: =DEC2HEX(C18)&DEC2HEX(D18)&DEC2HEX(E18)&DEC2HEX(F18) -> FFFF | W18: =DEC2HEX(G18)&DEC2HEX(H18)&DEC2HEX(I18)&DEC2HEX(J18) -> FFFF | X18: =DEC2HEX(K18)&DEC2HEX(L18)&DEC2HEX(M18)&DEC2HEX(N18) -> FFFF | Y18: =DEC2HEX(O18)&DEC2HEX(P18)&DEC2HEX(Q18)&DEC2HEX(R18) -> FFFF | AA18: 3 | AB18: 積算結果 * 3/16
B19: 14 | C19: 15 | D19: 15 | E19: 15 | F19: 15 | G19: 15 | H19: 15 | I19: 15 | J19: 15 | K19: 15 | L19: 15 | M19: 15 | N19: 15 | O19: 15 | P19: 15 | Q19: 15 | R19: 15 | U19: =B19 -> 14 | V19: =DEC2HEX(C19)&DEC2HEX(D19)&DEC2HEX(E19)&DEC2HEX(F19) -> FFFF | W19: =DEC2HEX(G19)&DEC2HEX(H19)&DEC2HEX(I19)&DEC2HEX(J19) -> FFFF | X19: =DEC2HEX(K19)&DEC2HEX(L19)&DEC2HEX(M19)&DEC2HEX(N19) -> FFFF | Y19: =DEC2HEX(O19)&DEC2HEX(P19)&DEC2HEX(Q19)&DEC2HEX(R19) -> FFFF | AA19: 4 | AB19: 積算結果 * 4/16
B20: 15 | C20: 15 | D20: 15 | E20: 15 | F20: 15 | G20: 15 | H20: 15 | I20: 15 | J20: 15 | K20: 15 | L20: 15 | M20: 15 | N20: 15 | O20: 15 | P20: 15 | Q20: 15 | R20: 15 | U20: =B20 -> 15 | V20: =DEC2HEX(C20)&DEC2HEX(D20)&DEC2HEX(E20)&DEC2HEX(F20) -> FFFF | W20: =DEC2HEX(G20)&DEC2HEX(H20)&DEC2HEX(I20)&DEC2HEX(J20) -> FFFF | X20: =DEC2HEX(K20)&DEC2HEX(L20)&DEC2HEX(M20)&DEC2HEX(N20) -> FFFF | Y20: =DEC2HEX(O20)&DEC2HEX(P20)&DEC2HEX(Q20)&DEC2HEX(R20) -> FFFF | AA20: 5 | AB20: 積算結果 * 5/16
B21: 16 | C21: 15 | D21: 15 | E21: 15 | F21: 15 | G21: 15 | H21: 15 | I21: 15 | J21: 15 | K21: 15 | L21: 15 | M21: 15 | N21: 15 | O21: 15 | P21: 15 | Q21: 15 | R21: 15 | U21: =B21 -> 16 | V21: =DEC2HEX(C21)&DEC2HEX(D21)&DEC2HEX(E21)&DEC2HEX(F21) -> FFFF | W21: =DEC2HEX(G21)&DEC2HEX(H21)&DEC2HEX(I21)&DEC2HEX(J21) -> FFFF | X21: =DEC2HEX(K21)&DEC2HEX(L21)&DEC2HEX(M21)&DEC2HEX(N21) -> FFFF | Y21: =DEC2HEX(O21)&DEC2HEX(P21)&DEC2HEX(Q21)&DEC2HEX(R21) -> FFFF | AA21: 6 | AB21: 積算結果 * 6/16
B22: 17 | C22: 15 | D22: 15 | E22: 15 | F22: 15 | G22: 15 | H22: 15 | I22: 15 | J22: 15 | K22: 15 | L22: 15 | M22: 15 | N22: 15 | O22: 15 | P22: 15 | Q22: 15 | R22: 15 | U22: =B22 -> 17 | V22: =DEC2HEX(C22)&DEC2HEX(D22)&DEC2HEX(E22)&DEC2HEX(F22) -> FFFF | W22: =DEC2HEX(G22)&DEC2HEX(H22)&DEC2HEX(I22)&DEC2HEX(J22) -> FFFF | X22: =DEC2HEX(K22)&DEC2HEX(L22)&DEC2HEX(M22)&DEC2HEX(N22) -> FFFF | Y22: =DEC2HEX(O22)&DEC2HEX(P22)&DEC2HEX(Q22)&DEC2HEX(R22) -> FFFF | AA22: 7 | AB22: 積算結果 * 7/16
B23: 18 | C23: 15 | D23: 15 | E23: 15 | F23: 15 | G23: 15 | H23: 15 | I23: 15 | J23: 15 | K23: 15 | L23: 15 | M23: 15 | N23: 15 | O23: 15 | P23: 15 | Q23: 15 | R23: 15 | U23: =B23 -> 18 | V23: =DEC2HEX(C23)&DEC2HEX(D23)&DEC2HEX(E23)&DEC2HEX(F23) -> FFFF | W23: =DEC2HEX(G23)&DEC2HEX(H23)&DEC2HEX(I23)&DEC2HEX(J23) -> FFFF | X23: =DEC2HEX(K23)&DEC2HEX(L23)&DEC2HEX(M23)&DEC2HEX(N23) -> FFFF | Y23: =DEC2HEX(O23)&DEC2HEX(P23)&DEC2HEX(Q23)&DEC2HEX(R23) -> FFFF | AA23: 8 | AB23: 積算結果 * 8/16
B24: 19 | C24: 15 | D24: 15 | E24: 15 | F24: 15 | G24: 15 | H24: 15 | I24: 15 | J24: 15 | K24: 15 | L24: 15 | M24: 15 | N24: 15 | O24: 15 | P24: 15 | Q24: 15 | R24: 15 | U24: =B24 -> 19 | V24: =DEC2HEX(C24)&DEC2HEX(D24)&DEC2HEX(E24)&DEC2HEX(F24) -> FFFF | W24: =DEC2HEX(G24)&DEC2HEX(H24)&DEC2HEX(I24)&DEC2HEX(J24) -> FFFF | X24: =DEC2HEX(K24)&DEC2HEX(L24)&DEC2HEX(M24)&DEC2HEX(N24) -> FFFF | Y24: =DEC2HEX(O24)&DEC2HEX(P24)&DEC2HEX(Q24)&DEC2HEX(R24) -> FFFF | AA24: 9 | AB24: 積算結果 * 9/16
B25: 20 | C25: 15 | D25: 15 | E25: 15 | F25: 15 | G25: 15 | H25: 15 | I25: 15 | J25: 15 | K25: 15 | L25: 15 | M25: 15 | N25: 15 | O25: 15 | P25: 15 | Q25: 15 | R25: 15 | U25: =B25 -> 20 | V25: =DEC2HEX(C25)&DEC2HEX(D25)&DEC2HEX(E25)&DEC2HEX(F25) -> FFFF | W25: =DEC2HEX(G25)&DEC2HEX(H25)&DEC2HEX(I25)&DEC2HEX(J25) -> FFFF | X25: =DEC2HEX(K25)&DEC2HEX(L25)&DEC2HEX(M25)&DEC2HEX(N25) -> FFFF | Y25: =DEC2HEX(O25)&DEC2HEX(P25)&DEC2HEX(Q25)&DEC2HEX(R25) -> FFFF | AA25: 10 | AB25: 積算結果 * 10/16
B26: 21 | C26: 15 | D26: 15 | E26: 15 | F26: 15 | G26: 15 | H26: 15 | I26: 15 | J26: 15 | K26: 15 | L26: 15 | M26: 15 | N26: 15 | O26: 15 | P26: 15 | Q26: 15 | R26: 15 | U26: =B26 -> 21 | V26: =DEC2HEX(C26)&DEC2HEX(D26)&DEC2HEX(E26)&DEC2HEX(F26) -> FFFF | W26: =DEC2HEX(G26)&DEC2HEX(H26)&DEC2HEX(I26)&DEC2HEX(J26) -> FFFF | X26: =DEC2HEX(K26)&DEC2HEX(L26)&DEC2HEX(M26)&DEC2HEX(N26) -> FFFF | Y26: =DEC2HEX(O26)&DEC2HEX(P26)&DEC2HEX(Q26)&DEC2HEX(R26) -> FFFF | AA26: 11 | AB26: 積算結果 * 11/16
... B30: 25 | C30: 15 | D30: 15 | E30: 15 | F30: 15 | G30: 15 | H30: 15 | I30: 15 | J30: 15 | K30: 15 | L30: 15 | M30: 15 | N30: 15 | O30: 15 | P30: 15 | Q30: 15 | R30: 15 | U30: =B30 -> 25 | V30: =DEC2HEX(C30)&DEC2HEX(D30)&DEC2HEX(E30)&DEC2HEX(F30) -> FFFF | W30: =DEC2HEX(G30)&DEC2HEX(H30)&DEC2HEX(I30)&DEC2HEX(J30) -> FFFF | X30: =DEC2HEX(K30)&DEC2HEX(L30)&DEC2HEX(M30)&DEC2HEX(N30) -> FFFF | Y30: =DEC2HEX(O30)&DEC2HEX(P30)&DEC2HEX(Q30)&DEC2HEX(R30) -> FFFF | AA30: 15 | AB30: 積算結果 * 15/16
B31: 26 | C31: 15 | D31: 15 | E31: 15 | F31: 15 | G31: 15 | H31: 15 | I31: 15 | J31: 15 | K31: 15 | L31: 15 | M31: 15 | N31: 15 | O31: 15 | P31: 15 | Q31: 15 | R31: 15 | U31: =B31 -> 26 | V31: =DEC2HEX(C31)&DEC2HEX(D31)&DEC2HEX(E31)&DEC2HEX(F31) -> FFFF | W31: =DEC2HEX(G31)&DEC2HEX(H31)&DEC2HEX(I31)&DEC2HEX(J31) -> FFFF | X31: =DEC2HEX(K31)&DEC2HEX(L31)&DEC2HEX(M31)&DEC2HEX(N31) -> FFFF | Y31: =DEC2HEX(O31)&DEC2HEX(P31)&DEC2HEX(Q31)&DEC2HEX(R31) -> FFFF
B32: 27 | C32: 15 | D32: 15 | E32: 15 | F32: 15 | G32: 15 | H32: 15 | I32: 15 | J32: 15 | K32: 15 | L32: 15 | M32: 15 | N32: 15 | O32: 15 | P32: 15 | Q32: 15 | R32: 15 | U32: =B32 -> 27 | V32: =DEC2HEX(C32)&DEC2HEX(D32)&DEC2HEX(E32)&DEC2HEX(F32) -> FFFF | W32: =DEC2HEX(G32)&DEC2HEX(H32)&DEC2HEX(I32)&DEC2HEX(J32) -> FFFF | X32: =DEC2HEX(K32)&DEC2HEX(L32)&DEC2HEX(M32)&DEC2HEX(N32) -> FFFF | Y32: =DEC2HEX(O32)&DEC2HEX(P32)&DEC2HEX(Q32)&DEC2HEX(R32) -> FFFF | AA32: ※AE/AWB検波サイズが16x16の時は、
B33: 28 | C33: 15 | D33: 15 | E33: 15 | F33: 15 | G33: 15 | H33: 15 | I33: 15 | J33: 15 | K33: 15 | L33: 15 | M33: 15 | N33: 15 | O33: 15 | P33: 15 | Q33: 15 | R33: 15 | U33: =B33 -> 28 | V33: =DEC2HEX(C33)&DEC2HEX(D33)&DEC2HEX(E33)&DEC2HEX(F33) -> FFFF | W33: =DEC2HEX(G33)&DEC2HEX(H33)&DEC2HEX(I33)&DEC2HEX(J33) -> FFFF | X33: =DEC2HEX(K33)&DEC2HEX(L33)&DEC2HEX(M33)&DEC2HEX(N33) -> FFFF | Y33: =DEC2HEX(O33)&DEC2HEX(P33)&DEC2HEX(Q33)&DEC2HEX(R33) -> FFFF | AA33: 垂直方向を1/2に間引いて設定するため
B34: 29 | C34: 15 | D34: 15 | E34: 15 | F34: 15 | G34: 15 | H34: 15 | I34: 15 | J34: 15 | K34: 15 | L34: 15 | M34: 15 | N34: 15 | O34: 15 | P34: 15 | Q34: 15 | R34: 15 | U34: =B34 -> 29 | V34: =DEC2HEX(C34)&DEC2HEX(D34)&DEC2HEX(E34)&DEC2HEX(F34) -> FFFF | W34: =DEC2HEX(G34)&DEC2HEX(H34)&DEC2HEX(I34)&DEC2HEX(J34) -> FFFF | X34: =DEC2HEX(K34)&DEC2HEX(L34)&DEC2HEX(M34)&DEC2HEX(N34) -> FFFF | Y34: =DEC2HEX(O34)&DEC2HEX(P34)&DEC2HEX(Q34)&DEC2HEX(R34) -> FFFF | AA34: 奇数列を使用しないのでご注意ください。
B35: 30 | C35: 15 | D35: 15 | E35: 15 | F35: 15 | G35: 15 | H35: 15 | I35: 15 | J35: 15 | K35: 15 | L35: 15 | M35: 15 | N35: 15 | O35: 15 | P35: 15 | Q35: 15 | R35: 15 | U35: =B35 -> 30 | V35: =DEC2HEX(C35)&DEC2HEX(D35)&DEC2HEX(E35)&DEC2HEX(F35) -> FFFF | W35: =DEC2HEX(G35)&DEC2HEX(H35)&DEC2HEX(I35)&DEC2HEX(J35) -> FFFF | X35: =DEC2HEX(K35)&DEC2HEX(L35)&DEC2HEX(M35)&DEC2HEX(N35) -> FFFF | Y35: =DEC2HEX(O35)&DEC2HEX(P35)&DEC2HEX(Q35)&DEC2HEX(R35) -> FFFF
B36: 31 | C36: 15 | D36: 15 | E36: 15 | F36: 15 | G36: 15 | H36: 15 | I36: 15 | J36: 15 | K36: 15 | L36: 15 | M36: 15 | N36: 15 | O36: 15 | P36: 15 | Q36: 15 | R36: 15 | U36: =B36 -> 31 | V36: =DEC2HEX(C36)&DEC2HEX(D36)&DEC2HEX(E36)&DEC2HEX(F36) -> FFFF | W36: =DEC2HEX(G36)&DEC2HEX(H36)&DEC2HEX(I36)&DEC2HEX(J36) -> FFFF | X36: =DEC2HEX(K36)&DEC2HEX(L36)&DEC2HEX(M36)&DEC2HEX(N36) -> FFFF | Y36: =DEC2HEX(O36)&DEC2HEX(P36)&DEC2HEX(Q36)&DEC2HEX(R36) -> FFFF | AA36: ※重み係数はWD.cで変更できます。
A39: 2.Center-weighted average 1 (Storage to ROM) | U39: =A39 -> 2.Center-weighted average 1 (Storage to ROM)
C40: 0 | D40: 1 | E40: 2 | F40: 3 | G40: 4 | H40: 5 | I40: 6 | J40: 7 | K40: 8 | L40: 9 | M40: 10 | N40: 11 | O40: 12 | P40: 13 | Q40: 14 | R40: 15 | V40: =C40&D40&E40&F40 -> 0123 | W40: =G40&H40&I40&J40 -> 4567 | X40: =K40&L40&M40&N40 -> 891011 | Y40: =O40&P40&Q40&R40 -> 12131415
B41: 0 | C41: 0 | D41: 0 | E41: 0 | F41: 0 | G41: 0 | H41: 0 | I41: 0 | J41: 0 | K41: 0 | L41: 0 | M41: 0 | N41: 0 | O41: 0 | P41: 0 | Q41: 0 | R41: 0 | U41: =B41 -> 0 | V41: =DEC2HEX(C41)&DEC2HEX(D41)&DEC2HEX(E41)&DEC2HEX(F41) -> 0000 | W41: =DEC2HEX(G41)&DEC2HEX(H41)&DEC2HEX(I41)&DEC2HEX(J41) -> 0000 | X41: =DEC2HEX(K41)&DEC2HEX(L41)&DEC2HEX(M41)&DEC2HEX(N41) -> 0000 | Y41: =DEC2HEX(O41)&DEC2HEX(P41)&DEC2HEX(Q41)&DEC2HEX(R41) -> 0000
B42: 1 | C42: 0 | D42: 0 | E42: 0 | F42: 0 | G42: 0 | H42: 0 | I42: 0 | J42: 0 | K42: 0 | L42: 0 | M42: 0 | N42: 0 | O42: 0 | P42: 0 | Q42: 0 | R42: 0 | U42: =B42 -> 1 | V42: =DEC2HEX(C42)&DEC2HEX(D42)&DEC2HEX(E42)&DEC2HEX(F42) -> 0000 | W42: =DEC2HEX(G42)&DEC2HEX(H42)&DEC2HEX(I42)&DEC2HEX(J42) -> 0000 | X42: =DEC2HEX(K42)&DEC2HEX(L42)&DEC2HEX(M42)&DEC2HEX(N42) -> 0000 | Y42: =DEC2HEX(O42)&DEC2HEX(P42)&DEC2HEX(Q42)&DEC2HEX(R42) -> 0000
B43: 2 | C43: 0 | D43: 0 | E43: 0 | F43: 0 | G43: 0 | H43: 0 | I43: 0 | J43: 0 | K43: 0 | L43: 0 | M43: 0 | N43: 0 | O43: 0 | P43: 0 | Q43: 0 | R43: 0 | U43: =B43 -> 2 | V43: =DEC2HEX(C43)&DEC2HEX(D43)&DEC2HEX(E43)&DEC2HEX(F43) -> 0000 | W43: =DEC2HEX(G43)&DEC2HEX(H43)&DEC2HEX(I43)&DEC2HEX(J43) -> 0000 | X43: =DEC2HEX(K43)&DEC2HEX(L43)&DEC2HEX(M43)&DEC2HEX(N43) -> 0000 | Y43: =DEC2HEX(O43)&DEC2HEX(P43)&DEC2HEX(Q43)&DEC2HEX(R43) -> 0000
B44: 3 | C44: 0 | D44: 0 | E44: 0 | F44: 0 | G44: 0 | H44: 0 | I44: 0 | J44: 0 | K44: 0 | L44: 0 | M44: 0 | N44: 0 | O44: 0 | P44: 0 | Q44: 0 | R44: 0 | U44: =B44 -> 3 | V44: =DEC2HEX(C44)&DEC2HEX(D44)&DEC2HEX(E44)&DEC2HEX(F44) -> 0000 | W44: =DEC2HEX(G44)&DEC2HEX(H44)&DEC2HEX(I44)&DEC2HEX(J44) -> 0000 | X44: =DEC2HEX(K44)&DEC2HEX(L44)&DEC2HEX(M44)&DEC2HEX(N44) -> 0000 | Y44: =DEC2HEX(O44)&DEC2HEX(P44)&DEC2HEX(Q44)&DEC2HEX(R44) -> 0000
B45: 4 | C45: 0 | D45: 0 | E45: 0 | F45: 0 | G45: 0 | H45: 0 | I45: 0 | J45: 0 | K45: 0 | L45: 0 | M45: 0 | N45: 0 | O45: 0 | P45: 0 | Q45: 0 | R45: 0 | U45: =B45 -> 4 | V45: =DEC2HEX(C45)&DEC2HEX(D45)&DEC2HEX(E45)&DEC2HEX(F45) -> 0000 | W45: =DEC2HEX(G45)&DEC2HEX(H45)&DEC2HEX(I45)&DEC2HEX(J45) -> 0000 | X45: =DEC2HEX(K45)&DEC2HEX(L45)&DEC2HEX(M45)&DEC2HEX(N45) -> 0000 | Y45: =DEC2HEX(O45)&DEC2HEX(P45)&DEC2HEX(Q45)&DEC2HEX(R45) -> 0000
...

Sheet AE_w_WORK
B2: Don't change the this sheet becouse of work area.
D4: 1 | E4: 2 | F4: 3 | G4: 4 | H4: 5 | I4: 6 | J4: 7 | K4: 8 | L4: 9 | M4: 10 | N4: 11 | O4: 12 | P4: 13
A5: No | B5: 縦 | C5: 横
A6: 1 | B6: 0 | C6: 1 | D6: =VLOOKUP(B6,AE_weight!$U$4:$Y$36,C6+1) -> FFFF | E6: =VLOOKUP(B6,AE_weight!$U$40:$Y$72,C6+1) -> 0000 | F6: =VLOOKUP(B6,AE_weight!$U$76:$Y$108,C6+1) -> 0000 | G6: =VLOOKUP(B6,AE_weight!$U$112:$Y$144,C6+1) -> 2222 | H6: =VLOOKUP(B6,AE_weight!$U$149:$Y$180,C6+1) -> 0000 | I6: =VLOOKUP(B6,AE_weight!$U$185:$Y$216,C6+1) -> 0000 | J6: =VLOOKUP(B6,AE_weight!$U$221:$Y$252,C6+1) -> 0000 | K6: =VLOOKUP(B6,AE_weight!$U$257:$Y$288,C6+1) -> 0000 | L6: =VLOOKUP(B6,AE_weight!$U$293:$Y$324,C6+1) -> 0000 | M6: =VLOOKUP(B6,AE_weight!$U$329:$Y$360,C6+1) -> 0000 | N6: =VLOOKUP(B6,AE_weight!$U$365:$Y$396,C6+1) -> 0000 | O6: =VLOOKUP(B6,AE_weight!$U$401:$Y$432,C6+1) -> 0112 | P6: =VLOOKUP(B6,AE_weight!$U$437:$Y$468,C6+1) -> 0000
A7: =A6+1 -> 2 | B7: =B6 -> 0 | C7: 2 | D7: =VLOOKUP(B7,AE_weight!$U$4:$Y$36,C7+1) -> FFFF | E7: =VLOOKUP(B7,AE_weight!$U$40:$Y$72,C7+1) -> 0000 | F7: =VLOOKUP(B7,AE_weight!$U$76:$Y$108,C7+1) -> 0000 | G7: =VLOOKUP(B7,AE_weight!$U$112:$Y$144,C7+1) -> 2222 | H7: =VLOOKUP(B7,AE_weight!$U$149:$Y$180,C7+1) -> 0000 | I7: =VLOOKUP(B7,AE_weight!$U$185:$Y$216,C7+1) -> 0000 | J7: =VLOOKUP(B7,AE_weight!$U$221:$Y$252,C7+1) -> 0000 | K7: =VLOOKUP(B7,AE_weight!$U$257:$Y$288,C7+1) -> 0000 | L7: =VLOOKUP(B7,AE_weight!$U$293:$Y$324,C7+1) -> 0000 | M7: =VLOOKUP(B7,AE_weight!$U$329:$Y$360,C7+1) -> 0000 | N7: =VLOOKUP(B7,AE_weight!$U$365:$Y$396,C7+1) -> 0000 | O7: =VLOOKUP(B7,AE_weight!$U$401:$Y$432,C7+1) -> 3334 | P7: =VLOOKUP(B7,AE_weight!$U$437:$Y$468,C7+1) -> 0000
A8: =A7+1 -> 3 | B8: =B7 -> 0 | C8: 3 | D8: =VLOOKUP(B8,AE_weight!$U$4:$Y$36,C8+1) -> FFFF | E8: =VLOOKUP(B8,AE_weight!$U$40:$Y$72,C8+1) -> 0000 | F8: =VLOOKUP(B8,AE_weight!$U$76:$Y$108,C8+1) -> 0000 | G8: =VLOOKUP(B8,AE_weight!$U$112:$Y$144,C8+1) -> 2222 | H8: =VLOOKUP(B8,AE_weight!$U$149:$Y$180,C8+1) -> 0000 | I8: =VLOOKUP(B8,AE_weight!$U$185:$Y$216,C8+1) -> 0000 | J8: =VLOOKUP(B8,AE_weight!$U$221:$Y$252,C8+1) -> 0000 | K8: =VLOOKUP(B8,AE_weight!$U$257:$Y$288,C8+1) -> 0000 | L8: =VLOOKUP(B8,AE_weight!$U$293:$Y$324,C8+1) -> 0000 | M8: =VLOOKUP(B8,AE_weight!$U$329:$Y$360,C8+1) -> 0000 | N8: =VLOOKUP(B8,AE_weight!$U$365:$Y$396,C8+1) -> 0000 | O8: =VLOOKUP(B8,AE_weight!$U$401:$Y$432,C8+1) -> 4333 | P8: =VLOOKUP(B8,AE_weight!$U$437:$Y$468,C8+1) -> 0000
A9: =A8+1 -> 4 | B9: =B8 -> 0 | C9: 4 | D9: =VLOOKUP(B9,AE_weight!$U$4:$Y$36,C9+1) -> FFFF | E9: =VLOOKUP(B9,AE_weight!$U$40:$Y$72,C9+1) -> 0000 | F9: =VLOOKUP(B9,AE_weight!$U$76:$Y$108,C9+1) -> 0000 | G9: =VLOOKUP(B9,AE_weight!$U$112:$Y$144,C9+1) -> 2222 | H9: =VLOOKUP(B9,AE_weight!$U$149:$Y$180,C9+1) -> 0000 | I9: =VLOOKUP(B9,AE_weight!$U$185:$Y$216,C9+1) -> 0000 | J9: =VLOOKUP(B9,AE_weight!$U$221:$Y$252,C9+1) -> 0000 | K9: =VLOOKUP(B9,AE_weight!$U$257:$Y$288,C9+1) -> 0000 | L9: =VLOOKUP(B9,AE_weight!$U$293:$Y$324,C9+1) -> 0000 | M9: =VLOOKUP(B9,AE_weight!$U$329:$Y$360,C9+1) -> 0000 | N9: =VLOOKUP(B9,AE_weight!$U$365:$Y$396,C9+1) -> 0000 | O9: =VLOOKUP(B9,AE_weight!$U$401:$Y$432,C9+1) -> 2110 | P9: =VLOOKUP(B9,AE_weight!$U$437:$Y$468,C9+1) -> 0000
A10: =A9+1 -> 5 | B10: =B6+1 -> 1 | C10: 1 | D10: =VLOOKUP(B10,AE_weight!$U$4:$Y$36,C10+1) -> FFFF | E10: =VLOOKUP(B10,AE_weight!$U$40:$Y$72,C10+1) -> 0000 | F10: =VLOOKUP(B10,AE_weight!$U$76:$Y$108,C10+1) -> 0000 | G10: =VLOOKUP(B10,AE_weight!$U$112:$Y$144,C10+1) -> 2222 | H10: =VLOOKUP(B10,AE_weight!$U$149:$Y$180,C10+1) -> 0000 | I10: =VLOOKUP(B10,AE_weight!$U$185:$Y$216,C10+1) -> 0000 | J10: =VLOOKUP(B10,AE_weight!$U$221:$Y$252,C10+1) -> 0000 | K10: =VLOOKUP(B10,AE_weight!$U$257:$Y$288,C10+1) -> 0000 | L10: =VLOOKUP(B10,AE_weight!$U$293:$Y$324,C10+1) -> 0000 | M10: =VLOOKUP(B10,AE_weight!$U$329:$Y$360,C10+1) -> 0000 | N10: =VLOOKUP(B10,AE_weight!$U$365:$Y$396,C10+1) -> 0000 | O10: =VLOOKUP(B10,AE_weight!$U$401:$Y$432,C10+1) -> 0112 | P10: =VLOOKUP(B10,AE_weight!$U$437:$Y$468,C10+1) -> 0000
A11: =A10+1 -> 6 | B11: =B10 -> 1 | C11: 2 | D11: =VLOOKUP(B11,AE_weight!$U$4:$Y$36,C11+1) -> FFFF | E11: =VLOOKUP(B11,AE_weight!$U$40:$Y$72,C11+1) -> 0000 | F11: =VLOOKUP(B11,AE_weight!$U$76:$Y$108,C11+1) -> 0000 | G11: =VLOOKUP(B11,AE_weight!$U$112:$Y$144,C11+1) -> 2222 | H11: =VLOOKUP(B11,AE_weight!$U$149:$Y$180,C11+1) -> 0000 | I11: =VLOOKUP(B11,AE_weight!$U$185:$Y$216,C11+1) -> 0000 | J11: =VLOOKUP(B11,AE_weight!$U$221:$Y$252,C11+1) -> 0000 | K11: =VLOOKUP(B11,AE_weight!$U$257:$Y$288,C11+1) -> 0000 | L11: =VLOOKUP(B11,AE_weight!$U$293:$Y$324,C11+1) -> 0000 | M11: =VLOOKUP(B11,AE_weight!$U$329:$Y$360,C11+1) -> 0000 | N11: =VLOOKUP(B11,AE_weight!$U$365:$Y$396,C11+1) -> 0000 | O11: =VLOOKUP(B11,AE_weight!$U$401:$Y$432,C11+1) -> 3344 | P11: =VLOOKUP(B11,AE_weight!$U$437:$Y$468,C11+1) -> 0000
A12: =A11+1 -> 7 | B12: =B11 -> 1 | C12: 3 | D12: =VLOOKUP(B12,AE_weight!$U$4:$Y$36,C12+1) -> FFFF | E12: =VLOOKUP(B12,AE_weight!$U$40:$Y$72,C12+1) -> 0000 | F12: =VLOOKUP(B12,AE_weight!$U$76:$Y$108,C12+1) -> 0000 | G12: =VLOOKUP(B12,AE_weight!$U$112:$Y$144,C12+1) -> 2222 | H12: =VLOOKUP(B12,AE_weight!$U$149:$Y$180,C12+1) -> 0000 | I12: =VLOOKUP(B12,AE_weight!$U$185:$Y$216,C12+1) -> 0000 | J12: =VLOOKUP(B12,AE_weight!$U$221:$Y$252,C12+1) -> 0000 | K12: =VLOOKUP(B12,AE_weight!$U$257:$Y$288,C12+1) -> 0000 | L12: =VLOOKUP(B12,AE_weight!$U$293:$Y$324,C12+1) -> 0000 | M12: =VLOOKUP(B12,AE_weight!$U$329:$Y$360,C12+1) -> 0000 | N12: =VLOOKUP(B12,AE_weight!$U$365:$Y$396,C12+1) -> 0000 | O12: =VLOOKUP(B12,AE_weight!$U$401:$Y$432,C12+1) -> 4433 | P12: =VLOOKUP(B12,AE_weight!$U$437:$Y$468,C12+1) -> 0000
A13: =A12+1 -> 8 | B13: =B12 -> 1 | C13: 4 | D13: =VLOOKUP(B13,AE_weight!$U$4:$Y$36,C13+1) -> FFFF | E13: =VLOOKUP(B13,AE_weight!$U$40:$Y$72,C13+1) -> 0000 | F13: =VLOOKUP(B13,AE_weight!$U$76:$Y$108,C13+1) -> 0000 | G13: =VLOOKUP(B13,AE_weight!$U$112:$Y$144,C13+1) -> 2222 | H13: =VLOOKUP(B13,AE_weight!$U$149:$Y$180,C13+1) -> 0000 | I13: =VLOOKUP(B13,AE_weight!$U$185:$Y$216,C13+1) -> 0000 | J13: =VLOOKUP(B13,AE_weight!$U$221:$Y$252,C13+1) -> 0000 | K13: =VLOOKUP(B13,AE_weight!$U$257:$Y$288,C13+1) -> 0000 | L13: =VLOOKUP(B13,AE_weight!$U$293:$Y$324,C13+1) -> 0000 | M13: =VLOOKUP(B13,AE_weight!$U$329:$Y$360,C13+1) -> 0000 | N13: =VLOOKUP(B13,AE_weight!$U$365:$Y$396,C13+1) -> 0000 | O13: =VLOOKUP(B13,AE_weight!$U$401:$Y$432,C13+1) -> 2110 | P13: =VLOOKUP(B13,AE_weight!$U$437:$Y$468,C13+1) -> 0000
A14: =A13+1 -> 9 | B14: =B10+1 -> 2 | C14: 1 | D14: =VLOOKUP(B14,AE_weight!$U$4:$Y$36,C14+1) -> FFFF | E14: =VLOOKUP(B14,AE_weight!$U$40:$Y$72,C14+1) -> 0000 | F14: =VLOOKUP(B14,AE_weight!$U$76:$Y$108,C14+1) -> 0000 | G14: =VLOOKUP(B14,AE_weight!$U$112:$Y$144,C14+1) -> 2222 | H14: =VLOOKUP(B14,AE_weight!$U$149:$Y$180,C14+1) -> 0000 | I14: =VLOOKUP(B14,AE_weight!$U$185:$Y$216,C14+1) -> 0000 | J14: =VLOOKUP(B14,AE_weight!$U$221:$Y$252,C14+1) -> 0000 | K14: =VLOOKUP(B14,AE_weight!$U$257:$Y$288,C14+1) -> 0000 | L14: =VLOOKUP(B14,AE_weight!$U$293:$Y$324,C14+1) -> 0000 | M14: =VLOOKUP(B14,AE_weight!$U$329:$Y$360,C14+1) -> 0000 | N14: =VLOOKUP(B14,AE_weight!$U$365:$Y$396,C14+1) -> 0000 | O14: =VLOOKUP(B14,AE_weight!$U$401:$Y$432,C14+1) -> 0112 | P14: =VLOOKUP(B14,AE_weight!$U$437:$Y$468,C14+1) -> 1111
A15: =A14+1 -> 10 | B15: =B14 -> 2 | C15: 2 | D15: =VLOOKUP(B15,AE_weight!$U$4:$Y$36,C15+1) -> FFFF | E15: =VLOOKUP(B15,AE_weight!$U$40:$Y$72,C15+1) -> 0000 | F15: =VLOOKUP(B15,AE_weight!$U$76:$Y$108,C15+1) -> 0000 | G15: =VLOOKUP(B15,AE_weight!$U$112:$Y$144,C15+1) -> 2222 | H15: =VLOOKUP(B15,AE_weight!$U$149:$Y$180,C15+1) -> 0000 | I15: =VLOOKUP(B15,AE_weight!$U$185:$Y$216,C15+1) -> 0000 | J15: =VLOOKUP(B15,AE_weight!$U$221:$Y$252,C15+1) -> 0000 | K15: =VLOOKUP(B15,AE_weight!$U$257:$Y$288,C15+1) -> 0000 | L15: =VLOOKUP(B15,AE_weight!$U$293:$Y$324,C15+1) -> 0000 | M15: =VLOOKUP(B15,AE_weight!$U$329:$Y$360,C15+1) -> 0000 | N15: =VLOOKUP(B15,AE_weight!$U$365:$Y$396,C15+1) -> 0011 | O15: =VLOOKUP(B15,AE_weight!$U$401:$Y$432,C15+1) -> 3344 | P15: =VLOOKUP(B15,AE_weight!$U$437:$Y$468,C15+1) -> 1111
A16: =A15+1 -> 11 | B16: =B15 -> 2 | C16: 3 | D16: =VLOOKUP(B16,AE_weight!$U$4:$Y$36,C16+1) -> FFFF | E16: =VLOOKUP(B16,AE_weight!$U$40:$Y$72,C16+1) -> 0000 | F16: =VLOOKUP(B16,AE_weight!$U$76:$Y$108,C16+1) -> 0000 | G16: =VLOOKUP(B16,AE_weight!$U$112:$Y$144,C16+1) -> 2222 | H16: =VLOOKUP(B16,AE_weight!$U$149:$Y$180,C16+1) -> 0000 | I16: =VLOOKUP(B16,AE_weight!$U$185:$Y$216,C16+1) -> 0000 | J16: =VLOOKUP(B16,AE_weight!$U$221:$Y$252,C16+1) -> 0000 | K16: =VLOOKUP(B16,AE_weight!$U$257:$Y$288,C16+1) -> 0000 | L16: =VLOOKUP(B16,AE_weight!$U$293:$Y$324,C16+1) -> 0000 | M16: =VLOOKUP(B16,AE_weight!$U$329:$Y$360,C16+1) -> 0000 | N16: =VLOOKUP(B16,AE_weight!$U$365:$Y$396,C16+1) -> 1111 | O16: =VLOOKUP(B16,AE_weight!$U$401:$Y$432,C16+1) -> 4433 | P16: =VLOOKUP(B16,AE_weight!$U$437:$Y$468,C16+1) -> 1100
A17: =A16+1 -> 12 | B17: =B16 -> 2 | C17: 4 | D17: =VLOOKUP(B17,AE_weight!$U$4:$Y$36,C17+1) -> FFFF | E17: =VLOOKUP(B17,AE_weight!$U$40:$Y$72,C17+1) -> 0000 | F17: =VLOOKUP(B17,AE_weight!$U$76:$Y$108,C17+1) -> 0000 | G17: =VLOOKUP(B17,AE_weight!$U$112:$Y$144,C17+1) -> 2222 | H17: =VLOOKUP(B17,AE_weight!$U$149:$Y$180,C17+1) -> 0000 | I17: =VLOOKUP(B17,AE_weight!$U$185:$Y$216,C17+1) -> 0000 | J17: =VLOOKUP(B17,AE_weight!$U$221:$Y$252,C17+1) -> 0000 | K17: =VLOOKUP(B17,AE_weight!$U$257:$Y$288,C17+1) -> 0000 | L17: =VLOOKUP(B17,AE_weight!$U$293:$Y$324,C17+1) -> 0000 | M17: =VLOOKUP(B17,AE_weight!$U$329:$Y$360,C17+1) -> 0000 | N17: =VLOOKUP(B17,AE_weight!$U$365:$Y$396,C17+1) -> 1111 | O17: =VLOOKUP(B17,AE_weight!$U$401:$Y$432,C17+1) -> 2110 | P17: =VLOOKUP(B17,AE_weight!$U$437:$Y$468,C17+1) -> 0000
A18: =A17+1 -> 13 | B18: =B14+1 -> 3 | C18: 1 | D18: =VLOOKUP(B18,AE_weight!$U$4:$Y$36,C18+1) -> FFFF | E18: =VLOOKUP(B18,AE_weight!$U$40:$Y$72,C18+1) -> 0000 | F18: =VLOOKUP(B18,AE_weight!$U$76:$Y$108,C18+1) -> 0000 | G18: =VLOOKUP(B18,AE_weight!$U$112:$Y$144,C18+1) -> 2222 | H18: =VLOOKUP(B18,AE_weight!$U$149:$Y$180,C18+1) -> 0000 | I18: =VLOOKUP(B18,AE_weight!$U$185:$Y$216,C18+1) -> 0000 | J18: =VLOOKUP(B18,AE_weight!$U$221:$Y$252,C18+1) -> 0000 | K18: =VLOOKUP(B18,AE_weight!$U$257:$Y$288,C18+1) -> 0000 | L18: =VLOOKUP(B18,AE_weight!$U$293:$Y$324,C18+1) -> 0000 | M18: =VLOOKUP(B18,AE_weight!$U$329:$Y$360,C18+1) -> 0000 | N18: =VLOOKUP(B18,AE_weight!$U$365:$Y$396,C18+1) -> 0000 | O18: =VLOOKUP(B18,AE_weight!$U$401:$Y$432,C18+1) -> 0112 | P18: =VLOOKUP(B18,AE_weight!$U$437:$Y$468,C18+1) -> 1111
A19: =A18+1 -> 14 | B19: =B18 -> 3 | C19: 2 | D19: =VLOOKUP(B19,AE_weight!$U$4:$Y$36,C19+1) -> FFFF | E19: =VLOOKUP(B19,AE_weight!$U$40:$Y$72,C19+1) -> 0000 | F19: =VLOOKUP(B19,AE_weight!$U$76:$Y$108,C19+1) -> 0000 | G19: =VLOOKUP(B19,AE_weight!$U$112:$Y$144,C19+1) -> 2222 | H19: =VLOOKUP(B19,AE_weight!$U$149:$Y$180,C19+1) -> 0000 | I19: =VLOOKUP(B19,AE_weight!$U$185:$Y$216,C19+1) -> 0000 | J19: =VLOOKUP(B19,AE_weight!$U$221:$Y$252,C19+1) -> 0000 | K19: =VLOOKUP(B19,AE_weight!$U$257:$Y$288,C19+1) -> 0000 | L19: =VLOOKUP(B19,AE_weight!$U$293:$Y$324,C19+1) -> 0000 | M19: =VLOOKUP(B19,AE_weight!$U$329:$Y$360,C19+1) -> 0011 | N19: =VLOOKUP(B19,AE_weight!$U$365:$Y$396,C19+1) -> 0111 | O19: =VLOOKUP(B19,AE_weight!$U$401:$Y$432,C19+1) -> 3444 | P19: =VLOOKUP(B19,AE_weight!$U$437:$Y$468,C19+1) -> 1111
A20: =A19+1 -> 15 | B20: =B19 -> 3 | C20: 3 | D20: =VLOOKUP(B20,AE_weight!$U$4:$Y$36,C20+1) -> FFFF | E20: =VLOOKUP(B20,AE_weight!$U$40:$Y$72,C20+1) -> 0000 | F20: =VLOOKUP(B20,AE_weight!$U$76:$Y$108,C20+1) -> 0000 | G20: =VLOOKUP(B20,AE_weight!$U$112:$Y$144,C20+1) -> 2222 | H20: =VLOOKUP(B20,AE_weight!$U$149:$Y$180,C20+1) -> 0000 | I20: =VLOOKUP(B20,AE_weight!$U$185:$Y$216,C20+1) -> 0000 | J20: =VLOOKUP(B20,AE_weight!$U$221:$Y$252,C20+1) -> 0000 | K20: =VLOOKUP(B20,AE_weight!$U$257:$Y$288,C20+1) -> 0000 | L20: =VLOOKUP(B20,AE_weight!$U$293:$Y$324,C20+1) -> 0000 | M20: =VLOOKUP(B20,AE_weight!$U$329:$Y$360,C20+1) -> 1100 | N20: =VLOOKUP(B20,AE_weight!$U$365:$Y$396,C20+1) -> 1111 | O20: =VLOOKUP(B20,AE_weight!$U$401:$Y$432,C20+1) -> 4443 | P20: =VLOOKUP(B20,AE_weight!$U$437:$Y$468,C20+1) -> 1110
A21: =A20+1 -> 16 | B21: =B20 -> 3 | C21: 4 | D21: =VLOOKUP(B21,AE_weight!$U$4:$Y$36,C21+1) -> FFFF | E21: =VLOOKUP(B21,AE_weight!$U$40:$Y$72,C21+1) -> 0000 | F21: =VLOOKUP(B21,AE_weight!$U$76:$Y$108,C21+1) -> 0000 | G21: =VLOOKUP(B21,AE_weight!$U$112:$Y$144,C21+1) -> 2222 | H21: =VLOOKUP(B21,AE_weight!$U$149:$Y$180,C21+1) -> 0000 | I21: =VLOOKUP(B21,AE_weight!$U$185:$Y$216,C21+1) -> 0000 | J21: =VLOOKUP(B21,AE_weight!$U$221:$Y$252,C21+1) -> 0000 | K21: =VLOOKUP(B21,AE_weight!$U$257:$Y$288,C21+1) -> 0000 | L21: =VLOOKUP(B21,AE_weight!$U$293:$Y$324,C21+1) -> 0000 | M21: =VLOOKUP(B21,AE_weight!$U$329:$Y$360,C21+1) -> 0000 | N21: =VLOOKUP(B21,AE_weight!$U$365:$Y$396,C21+1) -> 1111 | O21: =VLOOKUP(B21,AE_weight!$U$401:$Y$432,C21+1) -> 2110 | P21: =VLOOKUP(B21,AE_weight!$U$437:$Y$468,C21+1) -> 0000
A22: =A21+1 -> 17 | B22: =B18+1 -> 4 | C22: 1 | D22: =VLOOKUP(B22,AE_weight!$U$4:$Y$36,C22+1) -> FFFF | E22: =VLOOKUP(B22,AE_weight!$U$40:$Y$72,C22+1) -> 0000 | F22: =VLOOKUP(B22,AE_weight!$U$76:$Y$108,C22+1) -> 0000 | G22: =VLOOKUP(B22,AE_weight!$U$112:$Y$144,C22+1) -> 2222 | H22: =VLOOKUP(B22,AE_weight!$U$149:$Y$180,C22+1) -> 0000 | I22: =VLOOKUP(B22,AE_weight!$U$185:$Y$216,C22+1) -> 0000 | J22: =VLOOKUP(B22,AE_weight!$U$221:$Y$252,C22+1) -> 0000 | K22: =VLOOKUP(B22,AE_weight!$U$257:$Y$288,C22+1) -> 0000 | L22: =VLOOKUP(B22,AE_weight!$U$293:$Y$324,C22+1) -> 0000 | M22: =VLOOKUP(B22,AE_weight!$U$329:$Y$360,C22+1) -> 0000 | N22: =VLOOKUP(B22,AE_weight!$U$365:$Y$396,C22+1) -> 0000 | O22: =VLOOKUP(B22,AE_weight!$U$401:$Y$432,C22+1) -> 0112 | P22: =VLOOKUP(B22,AE_weight!$U$437:$Y$468,C22+1) -> 1112
A23: =A22+1 -> 18 | B23: =B22 -> 4 | C23: 2 | D23: =VLOOKUP(B23,AE_weight!$U$4:$Y$36,C23+1) -> FFFF | E23: =VLOOKUP(B23,AE_weight!$U$40:$Y$72,C23+1) -> 0000 | F23: =VLOOKUP(B23,AE_weight!$U$76:$Y$108,C23+1) -> 0022 | G23: =VLOOKUP(B23,AE_weight!$U$112:$Y$144,C23+1) -> 2222 | H23: =VLOOKUP(B23,AE_weight!$U$149:$Y$180,C23+1) -> 0000 | I23: =VLOOKUP(B23,AE_weight!$U$185:$Y$216,C23+1) -> 0000 | J23: =VLOOKUP(B23,AE_weight!$U$221:$Y$252,C23+1) -> 0000 | K23: =VLOOKUP(B23,AE_weight!$U$257:$Y$288,C23+1) -> 0000 | L23: =VLOOKUP(B23,AE_weight!$U$293:$Y$324,C23+1) -> 0000 | M23: =VLOOKUP(B23,AE_weight!$U$329:$Y$360,C23+1) -> 0111 | N23: =VLOOKUP(B23,AE_weight!$U$365:$Y$396,C23+1) -> 1122 | O23: =VLOOKUP(B23,AE_weight!$U$401:$Y$432,C23+1) -> 3445 | P23: =VLOOKUP(B23,AE_weight!$U$437:$Y$468,C23+1) -> 2222
A24: =A23+1 -> 19 | B24: =B23 -> 4 | C24: 3 | D24: =VLOOKUP(B24,AE_weight!$U$4:$Y$36,C24+1) -> FFFF | E24: =VLOOKUP(B24,AE_weight!$U$40:$Y$72,C24+1) -> 0000 | F24: =VLOOKUP(B24,AE_weight!$U$76:$Y$108,C24+1) -> 2200 | G24: =VLOOKUP(B24,AE_weight!$U$112:$Y$144,C24+1) -> 2222 | H24: =VLOOKUP(B24,AE_weight!$U$149:$Y$180,C24+1) -> 0000 | I24: =VLOOKUP(B24,AE_weight!$U$185:$Y$216,C24+1) -> 0000 | J24: =VLOOKUP(B24,AE_weight!$U$221:$Y$252,C24+1) -> 0000 | K24: =VLOOKUP(B24,AE_weight!$U$257:$Y$288,C24+1) -> 0000 | L24: =VLOOKUP(B24,AE_weight!$U$293:$Y$324,C24+1) -> 0000 | M24: =VLOOKUP(B24,AE_weight!$U$329:$Y$360,C24+1) -> 1110 | N24: =VLOOKUP(B24,AE_weight!$U$365:$Y$396,C24+1) -> 2222 | O24: =VLOOKUP(B24,AE_weight!$U$401:$Y$432,C24+1) -> 5443 | P24: =VLOOKUP(B24,AE_weight!$U$437:$Y$468,C24+1) -> 2211
A25: =A24+1 -> 20 | B25: =B24 -> 4 | C25: 4 | D25: =VLOOKUP(B25,AE_weight!$U$4:$Y$36,C25+1) -> FFFF | E25: =VLOOKUP(B25,AE_weight!$U$40:$Y$72,C25+1) -> 0000 | F25: =VLOOKUP(B25,AE_weight!$U$76:$Y$108,C25+1) -> 0000 | G25: =VLOOKUP(B25,AE_weight!$U$112:$Y$144,C25+1) -> 2222 | H25: =VLOOKUP(B25,AE_weight!$U$149:$Y$180,C25+1) -> 0000 | I25: =VLOOKUP(B25,AE_weight!$U$185:$Y$216,C25+1) -> 0000 | J25: =VLOOKUP(B25,AE_weight!$U$221:$Y$252,C25+1) -> 0000 | K25: =VLOOKUP(B25,AE_weight!$U$257:$Y$288,C25+1) -> 0000 | L25: =VLOOKUP(B25,AE_weight!$U$293:$Y$324,C25+1) -> 0000 | M25: =VLOOKUP(B25,AE_weight!$U$329:$Y$360,C25+1) -> 0000 | N25: =VLOOKUP(B25,AE_weight!$U$365:$Y$396,C25+1) -> 2111 | O25: =VLOOKUP(B25,AE_weight!$U$401:$Y$432,C25+1) -> 2110 | P25: =VLOOKUP(B25,AE_weight!$U$437:$Y$468,C25+1) -> 0000
A26: =A25+1 -> 21 | B26: =B22+1 -> 5 | C26: 1 | D26: =VLOOKUP(B26,AE_weight!$U$4:$Y$36,C26+1) -> FFFF | E26: =VLOOKUP(B26,AE_weight!$U$40:$Y$72,C26+1) -> 0000 | F26: =VLOOKUP(B26,AE_weight!$U$76:$Y$108,C26+1) -> 0000 | G26: =VLOOKUP(B26,AE_weight!$U$112:$Y$144,C26+1) -> 2222 | H26: =VLOOKUP(B26,AE_weight!$U$149:$Y$180,C26+1) -> 0000 | I26: =VLOOKUP(B26,AE_weight!$U$185:$Y$216,C26+1) -> 0000 | J26: =VLOOKUP(B26,AE_weight!$U$221:$Y$252,C26+1) -> 0000 | K26: =VLOOKUP(B26,AE_weight!$U$257:$Y$288,C26+1) -> 0000 | L26: =VLOOKUP(B26,AE_weight!$U$293:$Y$324,C26+1) -> 0000 | M26: =VLOOKUP(B26,AE_weight!$U$329:$Y$360,C26+1) -> 0000 | N26: =VLOOKUP(B26,AE_weight!$U$365:$Y$396,C26+1) -> 0000 | O26: =VLOOKUP(B26,AE_weight!$U$401:$Y$432,C26+1) -> 0112 | P26: =VLOOKUP(B26,AE_weight!$U$437:$Y$468,C26+1) -> 2222
A27: =A26+1 -> 22 | B27: =B26 -> 5 | C27: 2 | D27: =VLOOKUP(B27,AE_weight!$U$4:$Y$36,C27+1) -> FFFF | E27: =VLOOKUP(B27,AE_weight!$U$40:$Y$72,C27+1) -> 0000 | F27: =VLOOKUP(B27,AE_weight!$U$76:$Y$108,C27+1) -> 0022 | G27: =VLOOKUP(B27,AE_weight!$U$112:$Y$144,C27+1) -> 2222 | H27: =VLOOKUP(B27,AE_weight!$U$149:$Y$180,C27+1) -> 0000 | I27: =VLOOKUP(B27,AE_weight!$U$185:$Y$216,C27+1) -> 0000 | J27: =VLOOKUP(B27,AE_weight!$U$221:$Y$252,C27+1) -> 0000 | K27: =VLOOKUP(B27,AE_weight!$U$257:$Y$288,C27+1) -> 0001 | L27: =VLOOKUP(B27,AE_weight!$U$293:$Y$324,C27+1) -> 0000 | M27: =VLOOKUP(B27,AE_weight!$U$329:$Y$360,C27+1) -> 1122 | N27: =VLOOKUP(B27,AE_weight!$U$365:$Y$396,C27+1) -> 1222 | O27: =VLOOKUP(B27,AE_weight!$U$401:$Y$432,C27+1) -> 3455 | P27: =VLOOKUP(B27,AE_weight!$U$437:$Y$468,C27+1) -> 2222
A28: =A27+1 -> 23 | B28: =B27 -> 5 | C28: 3 | D28: =VLOOKUP(B28,AE_weight!$U$4:$Y$36,C28+1) -> FFFF | E28: =VLOOKUP(B28,AE_weight!$U$40:$Y$72,C28+1) -> 0000 | F28: =VLOOKUP(B28,AE_weight!$U$76:$Y$108,C28+1) -> 2200 | G28: =VLOOKUP(B28,AE_weight!$U$112:$Y$144,C28+1) -> 2222 | H28: =VLOOKUP(B28,AE_weight!$U$149:$Y$180,C28+1) -> 0000 | I28: =VLOOKUP(B28,AE_weight!$U$185:$Y$216,C28+1) -> 0000 | J28: =VLOOKUP(B28,AE_weight!$U$221:$Y$252,C28+1) -> 0000 | K28: =VLOOKUP(B28,AE_weight!$U$257:$Y$288,C28+1) -> 1000 | L28: =VLOOKUP(B28,AE_weight!$U$293:$Y$324,C28+1) -> 0000 | M28: =VLOOKUP(B28,AE_weight!$U$329:$Y$360,C28+1) -> 2211 | N28: =VLOOKUP(B28,AE_weight!$U$365:$Y$396,C28+1) -> 2222 | O28: =VLOOKUP(B28,AE_weight!$U$401:$Y$432,C28+1) -> 5543 | P28: =VLOOKUP(B28,AE_weight!$U$437:$Y$468,C28+1) -> 2221
A29: =A28+1 -> 24 | B29: =B28 -> 5 | C29: 4 | D29: =VLOOKUP(B29,AE_weight!$U$4:$Y$36,C29+1) -> FFFF | E29: =VLOOKUP(B29,AE_weight!$U$40:$Y$72,C29+1) -> 0000 | F29: =VLOOKUP(B29,AE_weight!$U$76:$Y$108,C29+1) -> 0000 | G29: =VLOOKUP(B29,AE_weight!$U$112:$Y$144,C29+1) -> 2222 | H29: =VLOOKUP(B29,AE_weight!$U$149:$Y$180,C29+1) -> 0000 | I29: =VLOOKUP(B29,AE_weight!$U$185:$Y$216,C29+1) -> 0000 | J29: =VLOOKUP(B29,AE_weight!$U$221:$Y$252,C29+1) -> 0000 | K29: =VLOOKUP(B29,AE_weight!$U$257:$Y$288,C29+1) -> 0000 | L29: =VLOOKUP(B29,AE_weight!$U$293:$Y$324,C29+1) -> 0000 | M29: =VLOOKUP(B29,AE_weight!$U$329:$Y$360,C29+1) -> 0000 | N29: =VLOOKUP(B29,AE_weight!$U$365:$Y$396,C29+1) -> 2222 | O29: =VLOOKUP(B29,AE_weight!$U$401:$Y$432,C29+1) -> 2110 | P29: =VLOOKUP(B29,AE_weight!$U$437:$Y$468,C29+1) -> 0000
A30: =A29+1 -> 25 | B30: =B26+1 -> 6 | C30: 1 | D30: =VLOOKUP(B30,AE_weight!$U$4:$Y$36,C30+1) -> FFFF | E30: =VLOOKUP(B30,AE_weight!$U$40:$Y$72,C30+1) -> 0000 | F30: =VLOOKUP(B30,AE_weight!$U$76:$Y$108,C30+1) -> 0000 | G30: =VLOOKUP(B30,AE_weight!$U$112:$Y$144,C30+1) -> 2222 | H30: =VLOOKUP(B30,AE_weight!$U$149:$Y$180,C30+1) -> 0000 | I30: =VLOOKUP(B30,AE_weight!$U$185:$Y$216,C30+1) -> 0000 | J30: =VLOOKUP(B30,AE_weight!$U$221:$Y$252,C30+1) -> 0000 | K30: =VLOOKUP(B30,AE_weight!$U$257:$Y$288,C30+1) -> 0000 | L30: =VLOOKUP(B30,AE_weight!$U$293:$Y$324,C30+1) -> 0000 | M30: =VLOOKUP(B30,AE_weight!$U$329:$Y$360,C30+1) -> 0001 | N30: =VLOOKUP(B30,AE_weight!$U$365:$Y$396,C30+1) -> 0001 | O30: =VLOOKUP(B30,AE_weight!$U$401:$Y$432,C30+1) -> 0112 | P30: =VLOOKUP(B30,AE_weight!$U$437:$Y$468,C30+1) -> 2223
A31: =A30+1 -> 26 | B31: =B30 -> 6 | C31: 2 | D31: =VLOOKUP(B31,AE_weight!$U$4:$Y$36,C31+1) -> FFFF | E31: =VLOOKUP(B31,AE_weight!$U$40:$Y$72,C31+1) -> 0000 | F31: =VLOOKUP(B31,AE_weight!$U$76:$Y$108,C31+1) -> 2223 | G31: =VLOOKUP(B31,AE_weight!$U$112:$Y$144,C31+1) -> 2222 | H31: =VLOOKUP(B31,AE_weight!$U$149:$Y$180,C31+1) -> 0000 | I31: =VLOOKUP(B31,AE_weight!$U$185:$Y$216,C31+1) -> 0000 | J31: =VLOOKUP(B31,AE_weight!$U$221:$Y$252,C31+1) -> 0007 | K31: =VLOOKUP(B31,AE_weight!$U$257:$Y$288,C31+1) -> 0000 | L31: =VLOOKUP(B31,AE_weight!$U$293:$Y$324,C31+1) -> 0000 | M31: =VLOOKUP(B31,AE_weight!$U$329:$Y$360,C31+1) -> 1222 | N31: =VLOOKUP(B31,AE_weight!$U$365:$Y$396,C31+1) -> 2223 | O31: =VLOOKUP(B31,AE_weight!$U$401:$Y$432,C31+1) -> 3455 | P31: =VLOOKUP(B31,AE_weight!$U$437:$Y$468,C31+1) -> 3333
A32: =A31+1 -> 27 | B32: =B31 -> 6 | C32: 3 | D32: =VLOOKUP(B32,AE_weight!$U$4:$Y$36,C32+1) -> FFFF | E32: =VLOOKUP(B32,AE_weight!$U$40:$Y$72,C32+1) -> 0000 | F32: =VLOOKUP(B32,AE_weight!$U$76:$Y$108,C32+1) -> 3222 | G32: =VLOOKUP(B32,AE_weight!$U$112:$Y$144,C32+1) -> 2222 | H32: =VLOOKUP(B32,AE_weight!$U$149:$Y$180,C32+1) -> 0000 | I32: =VLOOKUP(B32,AE_weight!$U$185:$Y$216,C32+1) -> 0000 | J32: =VLOOKUP(B32,AE_weight!$U$221:$Y$252,C32+1) -> 7000 | K32: =VLOOKUP(B32,AE_weight!$U$257:$Y$288,C32+1) -> 0000 | L32: =VLOOKUP(B32,AE_weight!$U$293:$Y$324,C32+1) -> 0000 | M32: =VLOOKUP(B32,AE_weight!$U$329:$Y$360,C32+1) -> 2221 | N32: =VLOOKUP(B32,AE_weight!$U$365:$Y$396,C32+1) -> 3333 | O32: =VLOOKUP(B32,AE_weight!$U$401:$Y$432,C32+1) -> 5543 | P32: =VLOOKUP(B32,AE_weight!$U$437:$Y$468,C32+1) -> 3222
A33: =A32+1 -> 28 | B33: =B32 -> 6 | C33: 4 | D33: =VLOOKUP(B33,AE_weight!$U$4:$Y$36,C33+1) -> FFFF | E33: =VLOOKUP(B33,AE_weight!$U$40:$Y$72,C33+1) -> 0000 | F33: =VLOOKUP(B33,AE_weight!$U$76:$Y$108,C33+1) -> 0000 | G33: =VLOOKUP(B33,AE_weight!$U$112:$Y$144,C33+1) -> 2222 | H33: =VLOOKUP(B33,AE_weight!$U$149:$Y$180,C33+1) -> 0000 | I33: =VLOOKUP(B33,AE_weight!$U$185:$Y$216,C33+1) -> 0000 | J33: =VLOOKUP(B33,AE_weight!$U$221:$Y$252,C33+1) -> 0000 | K33: =VLOOKUP(B33,AE_weight!$U$257:$Y$288,C33+1) -> 0000 | L33: =VLOOKUP(B33,AE_weight!$U$293:$Y$324,C33+1) -> 0000 | M33: =VLOOKUP(B33,AE_weight!$U$329:$Y$360,C33+1) -> 1000 | N33: =VLOOKUP(B33,AE_weight!$U$365:$Y$396,C33+1) -> 3222 | O33: =VLOOKUP(B33,AE_weight!$U$401:$Y$432,C33+1) -> 2110 | P33: =VLOOKUP(B33,AE_weight!$U$437:$Y$468,C33+1) -> 1000
A34: =A33+1 -> 29 | B34: =B30+1 -> 7 | C34: 1 | D34: =VLOOKUP(B34,AE_weight!$U$4:$Y$36,C34+1) -> FFFF | E34: =VLOOKUP(B34,AE_weight!$U$40:$Y$72,C34+1) -> 0000 | F34: =VLOOKUP(B34,AE_weight!$U$76:$Y$108,C34+1) -> 0000 | G34: =VLOOKUP(B34,AE_weight!$U$112:$Y$144,C34+1) -> 2222 | H34: =VLOOKUP(B34,AE_weight!$U$149:$Y$180,C34+1) -> 0000 | I34: =VLOOKUP(B34,AE_weight!$U$185:$Y$216,C34+1) -> 0000 | J34: =VLOOKUP(B34,AE_weight!$U$221:$Y$252,C34+1) -> 0000 | K34: =VLOOKUP(B34,AE_weight!$U$257:$Y$288,C34+1) -> 0000 | L34: =VLOOKUP(B34,AE_weight!$U$293:$Y$324,C34+1) -> 0000 | M34: =VLOOKUP(B34,AE_weight!$U$329:$Y$360,C34+1) -> 0001 | N34: =VLOOKUP(B34,AE_weight!$U$365:$Y$396,C34+1) -> 0001 | O34: =VLOOKUP(B34,AE_weight!$U$401:$Y$432,C34+1) -> 0123 | P34: =VLOOKUP(B34,AE_weight!$U$437:$Y$468,C34+1) -> 3333
A35: =A34+1 -> 30 | B35: =B34 -> 7 | C35: 2 | D35: =VLOOKUP(B35,AE_weight!$U$4:$Y$36,C35+1) -> FFFF | E35: =VLOOKUP(B35,AE_weight!$U$40:$Y$72,C35+1) -> 0002 | F35: =VLOOKUP(B35,AE_weight!$U$76:$Y$108,C35+1) -> 2223 | G35: =VLOOKUP(B35,AE_weight!$U$112:$Y$144,C35+1) -> 2222 | H35: =VLOOKUP(B35,AE_weight!$U$149:$Y$180,C35+1) -> 0000 | I35: =VLOOKUP(B35,AE_weight!$U$185:$Y$216,C35+1) -> 0000 | J35: =VLOOKUP(B35,AE_weight!$U$221:$Y$252,C35+1) -> 0007 | K35: =VLOOKUP(B35,AE_weight!$U$257:$Y$288,C35+1) -> 0010 | L35: =VLOOKUP(B35,AE_weight!$U$293:$Y$324,C35+1) -> 0000 | M35: =VLOOKUP(B35,AE_weight!$U$329:$Y$360,C35+1) -> 2223 | N35: =VLOOKUP(B35,AE_weight!$U$365:$Y$396,C35+1) -> 2233 | O35: =VLOOKUP(B35,AE_weight!$U$401:$Y$432,C35+1) -> 3455 | P35: =VLOOKUP(B35,AE_weight!$U$437:$Y$468,C35+1) -> 3333
A36: =A35+1 -> 31 | B36: =B35 -> 7 | C36: 3 | D36: =VLOOKUP(B36,AE_weight!$U$4:$Y$36,C36+1) -> FFFF | E36: =VLOOKUP(B36,AE_weight!$U$40:$Y$72,C36+1) -> 2000 | F36: =VLOOKUP(B36,AE_weight!$U$76:$Y$108,C36+1) -> 3222 | G36: =VLOOKUP(B36,AE_weight!$U$112:$Y$144,C36+1) -> 2222 | H36: =VLOOKUP(B36,AE_weight!$U$149:$Y$180,C36+1) -> 0000 | I36: =VLOOKUP(B36,AE_weight!$U$185:$Y$216,C36+1) -> 0000 | J36: =VLOOKUP(B36,AE_weight!$U$221:$Y$252,C36+1) -> 7000 | K36: =VLOOKUP(B36,AE_weight!$U$257:$Y$288,C36+1) -> 0100 | L36: =VLOOKUP(B36,AE_weight!$U$293:$Y$324,C36+1) -> 0000 | M36: =VLOOKUP(B36,AE_weight!$U$329:$Y$360,C36+1) -> 3222 | N36: =VLOOKUP(B36,AE_weight!$U$365:$Y$396,C36+1) -> 3333 | O36: =VLOOKUP(B36,AE_weight!$U$401:$Y$432,C36+1) -> 5543 | P36: =VLOOKUP(B36,AE_weight!$U$437:$Y$468,C36+1) -> 3322
A37: =A36+1 -> 32 | B37: =B36 -> 7 | C37: 4 | D37: =VLOOKUP(B37,AE_weight!$U$4:$Y$36,C37+1) -> FFFF | E37: =VLOOKUP(B37,AE_weight!$U$40:$Y$72,C37+1) -> 0000 | F37: =VLOOKUP(B37,AE_weight!$U$76:$Y$108,C37+1) -> 0000 | G37: =VLOOKUP(B37,AE_weight!$U$112:$Y$144,C37+1) -> 2222 | H37: =VLOOKUP(B37,AE_weight!$U$149:$Y$180,C37+1) -> 0000 | I37: =VLOOKUP(B37,AE_weight!$U$185:$Y$216,C37+1) -> 0000 | J37: =VLOOKUP(B37,AE_weight!$U$221:$Y$252,C37+1) -> 0000 | K37: =VLOOKUP(B37,AE_weight!$U$257:$Y$288,C37+1) -> 0000 | L37: =VLOOKUP(B37,AE_weight!$U$293:$Y$324,C37+1) -> 0000 | M37: =VLOOKUP(B37,AE_weight!$U$329:$Y$360,C37+1) -> 1000 | N37: =VLOOKUP(B37,AE_weight!$U$365:$Y$396,C37+1) -> 3333 | O37: =VLOOKUP(B37,AE_weight!$U$401:$Y$432,C37+1) -> 3210 | P37: =VLOOKUP(B37,AE_weight!$U$437:$Y$468,C37+1) -> 1000
A38: =A37+1 -> 33 | B38: =B34+1 -> 8 | C38: 1 | D38: =VLOOKUP(B38,AE_weight!$U$4:$Y$36,C38+1) -> FFFF | E38: =VLOOKUP(B38,AE_weight!$U$40:$Y$72,C38+1) -> 0000 | F38: =VLOOKUP(B38,AE_weight!$U$76:$Y$108,C38+1) -> 0002 | G38: =VLOOKUP(B38,AE_weight!$U$112:$Y$144,C38+1) -> 2222 | H38: =VLOOKUP(B38,AE_weight!$U$149:$Y$180,C38+1) -> 0000 | I38: =VLOOKUP(B38,AE_weight!$U$185:$Y$216,C38+1) -> 0000 | J38: =VLOOKUP(B38,AE_weight!$U$221:$Y$252,C38+1) -> 0000 | K38: =VLOOKUP(B38,AE_weight!$U$257:$Y$288,C38+1) -> 0000 | L38: =VLOOKUP(B38,AE_weight!$U$293:$Y$324,C38+1) -> 0000 | M38: =VLOOKUP(B38,AE_weight!$U$329:$Y$360,C38+1) -> 0011 | N38: =VLOOKUP(B38,AE_weight!$U$365:$Y$396,C38+1) -> 0012 | O38: =VLOOKUP(B38,AE_weight!$U$401:$Y$432,C38+1) -> 0123 | P38: =VLOOKUP(B38,AE_weight!$U$437:$Y$468,C38+1) -> 3333
A39: =A38+1 -> 34 | B39: =B38 -> 8 | C39: 2 | D39: =VLOOKUP(B39,AE_weight!$U$4:$Y$36,C39+1) -> FFFF | E39: =VLOOKUP(B39,AE_weight!$U$40:$Y$72,C39+1) -> 2223 | F39: =VLOOKUP(B39,AE_weight!$U$76:$Y$108,C39+1) -> 2334 | G39: =VLOOKUP(B39,AE_weight!$U$112:$Y$144,C39+1) -> 2222 | H39: =VLOOKUP(B39,AE_weight!$U$149:$Y$180,C39+1) -> 0000 | I39: =VLOOKUP(B39,AE_weight!$U$185:$Y$216,C39+1) -> 0000 | J39: =VLOOKUP(B39,AE_weight!$U$221:$Y$252,C39+1) -> 0777 | K39: =VLOOKUP(B39,AE_weight!$U$257:$Y$288,C39+1) -> 0000 | L39: =VLOOKUP(B39,AE_weight!$U$293:$Y$324,C39+1) -> 0000 | M39: =VLOOKUP(B39,AE_weight!$U$329:$Y$360,C39+1) -> 2233 | N39: =VLOOKUP(B39,AE_weight!$U$365:$Y$396,C39+1) -> 2334 | O39: =VLOOKUP(B39,AE_weight!$U$401:$Y$432,C39+1) -> 3556 | P39: =VLOOKUP(B39,AE_weight!$U$437:$Y$468,C39+1) -> 4444
A40: =A39+1 -> 35 | B40: =B39 -> 8 | C40: 3 | D40: =VLOOKUP(B40,AE_weight!$U$4:$Y$36,C40+1) -> FFFF | E40: =VLOOKUP(B40,AE_weight!$U$40:$Y$72,C40+1) -> 3222 | F40: =VLOOKUP(B40,AE_weight!$U$76:$Y$108,C40+1) -> 4332 | G40: =VLOOKUP(B40,AE_weight!$U$112:$Y$144,C40+1) -> 2222 | H40: =VLOOKUP(B40,AE_weight!$U$149:$Y$180,C40+1) -> 0000 | I40: =VLOOKUP(B40,AE_weight!$U$185:$Y$216,C40+1) -> 0000 | J40: =VLOOKUP(B40,AE_weight!$U$221:$Y$252,C40+1) -> 7770 | K40: =VLOOKUP(B40,AE_weight!$U$257:$Y$288,C40+1) -> 0000 | L40: =VLOOKUP(B40,AE_weight!$U$293:$Y$324,C40+1) -> 0000 | M40: =VLOOKUP(B40,AE_weight!$U$329:$Y$360,C40+1) -> 3322 | N40: =VLOOKUP(B40,AE_weight!$U$365:$Y$396,C40+1) -> 4444 | O40: =VLOOKUP(B40,AE_weight!$U$401:$Y$432,C40+1) -> 6553 | P40: =VLOOKUP(B40,AE_weight!$U$437:$Y$468,C40+1) -> 4332
A41: =A40+1 -> 36 | B41: =B40 -> 8 | C41: 4 | D41: =VLOOKUP(B41,AE_weight!$U$4:$Y$36,C41+1) -> FFFF | E41: =VLOOKUP(B41,AE_weight!$U$40:$Y$72,C41+1) -> 0000 | F41: =VLOOKUP(B41,AE_weight!$U$76:$Y$108,C41+1) -> 2000 | G41: =VLOOKUP(B41,AE_weight!$U$112:$Y$144,C41+1) -> 2222 | H41: =VLOOKUP(B41,AE_weight!$U$149:$Y$180,C41+1) -> 0000 | I41: =VLOOKUP(B41,AE_weight!$U$185:$Y$216,C41+1) -> 0000 | J41: =VLOOKUP(B41,AE_weight!$U$221:$Y$252,C41+1) -> 0000 | K41: =VLOOKUP(B41,AE_weight!$U$257:$Y$288,C41+1) -> 0000 | L41: =VLOOKUP(B41,AE_weight!$U$293:$Y$324,C41+1) -> 0000 | M41: =VLOOKUP(B41,AE_weight!$U$329:$Y$360,C41+1) -> 1100 | N41: =VLOOKUP(B41,AE_weight!$U$365:$Y$396,C41+1) -> 3333 | O41: =VLOOKUP(B41,AE_weight!$U$401:$Y$432,C41+1) -> 3210 | P41: =VLOOKUP(B41,AE_weight!$U$437:$Y$468,C41+1) -> 2100
A42: =A41+1 -> 37 | B42: =B38+1 -> 9 | C42: 1 | D42: =VLOOKUP(B42,AE_weight!$U$4:$Y$36,C42+1) -> FFFF | E42: =VLOOKUP(B42,AE_weight!$U$40:$Y$72,C42+1) -> 0000 | F42: =VLOOKUP(B42,AE_weight!$U$76:$Y$108,C42+1) -> 0002 | G42: =VLOOKUP(B42,AE_weight!$U$112:$Y$144,C42+1) -> 2222 | H42: =VLOOKUP(B42,AE_weight!$U$149:$Y$180,C42+1) -> 0000 | I42: =VLOOKUP(B42,AE_weight!$U$185:$Y$216,C42+1) -> 0000 | J42: =VLOOKUP(B42,AE_weight!$U$221:$Y$252,C42+1) -> 0000 | K42: =VLOOKUP(B42,AE_weight!$U$257:$Y$288,C42+1) -> 0000 | L42: =VLOOKUP(B42,AE_weight!$U$293:$Y$324,C42+1) -> 0000 | M42: =VLOOKUP(B42,AE_weight!$U$329:$Y$360,C42+1) -> 0012 | N42: =VLOOKUP(B42,AE_weight!$U$365:$Y$396,C42+1) -> 0012 | O42: =VLOOKUP(B42,AE_weight!$U$401:$Y$432,C42+1) -> 0123 | P42: =VLOOKUP(B42,AE_weight!$U$437:$Y$468,C42+1) -> 3334
...
