Workbook

Sheet History
B2: ROM_MAP PRO Update History
B5: History
B6: Date | C6: Name | D6: Comment
BV115: s

Sheet ROM_MAP
C1: ROM_MAP PROマクロ
B5: Section | C5: Group | D5: Byte 数 | E5: MACRO | F5: address | G5: Name | I5: Init Value | J5: Update | K5: note
G6: 15 (even) 8 | H6: 7 (odd) 0 | I6: hexadecimal | L6: 0
B7: 1 | C7: AE Weight Table | E7: JDSPRO | F7: 0x00000000 | G7: AE_BLOCK_WEIGHT_0 | H7: AE_BLOCK_WEIGHT_1 | I7: ="0x"&AE_w_WORK!D6 -> 0x0000 | J7: 40473 | K7: All block integral | L7: =L6+2 -> 2
B8: 2 | E8: JDSPRO | F8: 0x00000002 | G8: AE_BLOCK_WEIGHT_2 | H8: AE_BLOCK_WEIGHT_3 | I8: ="0x"&AE_w_WORK!D7 -> 0x0000 | J8: 40473 | L8: =L7+2 -> 4
B9: 3 | E9: JDSPRO | F9: 0x00000004 | G9: AE_BLOCK_WEIGHT_4 | H9: AE_BLOCK_WEIGHT_5 | I9: ="0x"&AE_w_WORK!D8 -> 0x0000 | J9: 40473 | L9: =L8+2 -> 6
B10: 4 | E10: JDSPRO | F10: 0x00000006 | G10: AE_BLOCK_WEIGHT_6 | H10: AE_BLOCK_WEIGHT_7 | I10: ="0x"&AE_w_WORK!D9 -> 0x0000 | J10: 40473 | L10: =L9+2 -> 8
B11: 5 | E11: JDSPRO | F11: 0x00000008 | G11: AE_BLOCK_WEIGHT_8 | H11: AE_BLOCK_WEIGHT_9 | I11: ="0x"&AE_w_WORK!D10 -> 0x0000 | J11: 40473 | L11: =L10+2 -> 10
B12: 6 | E12: JDSPRO | F12: 0x0000000A | G12: AE_BLOCK_WEIGHT_10 | H12: AE_BLOCK_WEIGHT_11 | I12: ="0x"&AE_w_WORK!D11 -> 0x0000 | J12: 40473 | L12: =L11+2 -> 12
B13: 7 | E13: JDSPRO | F13: 0x0000000C | G13: AE_BLOCK_WEIGHT_12 | H13: AE_BLOCK_WEIGHT_13 | I13: ="0x"&AE_w_WORK!D12 -> 0x0000 | J13: 40473 | L13: =L12+2 -> 14
B14: 8 | E14: JDSPRO | F14: 0x0000000E | G14: AE_BLOCK_WEIGHT_14 | H14: AE_BLOCK_WEIGHT_15 | I14: ="0x"&AE_w_WORK!D13 -> 0x0000 | J14: 40473 | L14: =L13+2 -> 16
B15: 9 | E15: JDSPRO | F15: 0x00000010 | G15: AE_BLOCK_WEIGHT_16 | H15: AE_BLOCK_WEIGHT_17 | I15: ="0x"&AE_w_WORK!D14 -> 0x0000 | J15: 40473 | L15: =L14+2 -> 18
B16: 10 | E16: JDSPRO | F16: 0x00000012 | G16: AE_BLOCK_WEIGHT_18 | H16: AE_BLOCK_WEIGHT_19 | I16: ="0x"&AE_w_WORK!D15 -> 0x0000 | J16: 40473 | L16: =L15+2 -> 20
B17: 11 | E17: JDSPRO | F17: 0x00000014 | G17: AE_BLOCK_WEIGHT_20 | H17: AE_BLOCK_WEIGHT_21 | I17: ="0x"&AE_w_WORK!D16 -> 0x0000 | J17: 40473 | L17: =L16+2 -> 22
B18: 12 | E18: JDSPRO | F18: 0x00000016 | G18: AE_BLOCK_WEIGHT_22 | H18: AE_BLOCK_WEIGHT_23 | I18: ="0x"&AE_w_WORK!D17 -> 0x1111 | J18: 40473 | L18: =L17+2 -> 24
B19: 13 | E19: JDSPRO | F19: 0x00000018 | G19: AE_BLOCK_WEIGHT_24 | H19: AE_BLOCK_WEIGHT_25 | I19: ="0x"&AE_w_WORK!D18 -> 0x1111 | J19: 40473 | L19: =L18+2 -> 26
... B262: 256 | E262: JDSPRO | F262: 0x000001FE | G262: AE_BLOCK_WEIGHT_254 | H262: AE_BLOCK_WEIGHT_255 | I262: ="0x"&AE_w_WORK!D261 -> 0x0000 | J262: 40601 | L262: =L261+2 -> 512
B263: 257 | E263: JDSPRO | F263: 0x00000200 | G263: AE_BLOCK_WEIGHT_0 | H263: AE_BLOCK_WEIGHT_1 | I263: ="0x"&AE_w_WORK!E6 -> 0x2222 | J263: 40473 | K263: Center-weighted average 1 | L263: =L262+2 -> 514
B264: 258 | E264: JDSPRO | F264: 0x00000202 | G264: AE_BLOCK_WEIGHT_0 | H264: AE_BLOCK_WEIGHT_1 | I264: ="0x"&AE_w_WORK!E7 -> 0x2222 | J264: 40474 | L264: =L263+2 -> 516
B265: 259 | E265: JDSPRO | F265: 0x00000204 | G265: AE_BLOCK_WEIGHT_0 | H265: AE_BLOCK_WEIGHT_1 | I265: ="0x"&AE_w_WORK!E8 -> 0x2222 | J265: 40475 | L265: =L264+2 -> 518
B266: 260 | E266: JDSPRO | F266: 0x00000206 | G266: AE_BLOCK_WEIGHT_0 | H266: AE_BLOCK_WEIGHT_1 | I266: ="0x"&AE_w_WORK!E9 -> 0x2222 | J266: 40476 | L266: =L265+2 -> 520
B267: 261 | E267: JDSPRO | F267: 0x00000208 | G267: AE_BLOCK_WEIGHT_0 | H267: AE_BLOCK_WEIGHT_1 | I267: ="0x"&AE_w_WORK!E10 -> 0x2222 | J267: 40477 | L267: =L266+2 -> 522
B268: 262 | E268: JDSPRO | F268: 0x0000020A | G268: AE_BLOCK_WEIGHT_0 | H268: AE_BLOCK_WEIGHT_1 | I268: ="0x"&AE_w_WORK!E11 -> 0x2222 | J268: 40478 | L268: =L267+2 -> 524
B269: 263 | E269: JDSPRO | F269: 0x0000020C | G269: AE_BLOCK_WEIGHT_0 | H269: AE_BLOCK_WEIGHT_1 | I269: ="0x"&AE_w_WORK!E12 -> 0x2222 | J269: 40479 | L269: =L268+2 -> 526
B270: 264 | E270: JDSPRO | F270: 0x0000020E | G270: AE_BLOCK_WEIGHT_0 | H270: AE_BLOCK_WEIGHT_1 | I270: ="0x"&AE_w_WORK!E13 -> 0x2222 | J270: 40480 | L270: =L269+2 -> 528
B271: 265 | E271: JDSPRO | F271: 0x00000210 | G271: AE_BLOCK_WEIGHT_0 | H271: AE_BLOCK_WEIGHT_1 | I271: ="0x"&AE_w_WORK!E14 -> 0x2222 | J271: 40481 | L271: =L270+2 -> 530
B272: 266 | E272: JDSPRO | F272: 0x00000212 | G272: AE_BLOCK_WEIGHT_0 | H272: AE_BLOCK_WEIGHT_1 | I272: ="0x"&AE_w_WORK!E15 -> 0x2222 | J272: 40482 | L272: =L271+2 -> 532
B273: 267 | E273: JDSPRO | F273: 0x00000214 | G273: AE_BLOCK_WEIGHT_0 | H273: AE_BLOCK_WEIGHT_1 | I273: ="0x"&AE_w_WORK!E16 -> 0x2222 | J273: 40483 | L273: =L272+2 -> 534
B274: 268 | E274: JDSPRO | F274: 0x00000216 | G274: AE_BLOCK_WEIGHT_0 | H274: AE_BLOCK_WEIGHT_1 | I274: ="0x"&AE_w_WORK!E17 -> 0x2222 | J274: 40484 | L274: =L273+2 -> 536
B275: 269 | E275: JDSPRO | F275: 0x00000218 | G275: AE_BLOCK_WEIGHT_0 | H275: AE_BLOCK_WEIGHT_1 | I275: ="0x"&AE_w_WORK!E18 -> 0x2222 | J275: 40485 | L275: =L274+2 -> 538
... B518: 512 | E518: JDSPRO | F518: 0x000003FE | G518: AE_BLOCK_WEIGHT_0 | H518: AE_BLOCK_WEIGHT_1 | I518: ="0x"&AE_w_WORK!E261 -> 0x2222 | J518: 40728 | L518: =L517+2 -> 1024
B519: 513 | E519: JDSPRO | F519: 0x00000400 | G519: AE_BLOCK_WEIGHT_0 | H519: AE_BLOCK_WEIGHT_1 | I519: ="0x"&AE_w_WORK!F6 -> 0x0000 | J519: 40729 | K519: Center-weighted average 2 | L519: =L518+2 -> 1026
B520: 514 | E520: JDSPRO | F520: 0x00000402 | G520: AE_BLOCK_WEIGHT_0 | H520: AE_BLOCK_WEIGHT_1 | I520: ="0x"&AE_w_WORK!F7 -> 0x0000 | J520: 40730 | L520: =L519+2 -> 1028
B521: 515 | E521: JDSPRO | F521: 0x00000404 | G521: AE_BLOCK_WEIGHT_0 | H521: AE_BLOCK_WEIGHT_1 | I521: ="0x"&AE_w_WORK!F8 -> 0x0000 | J521: 40731 | L521: =L520+2 -> 1030
B522: 516 | E522: JDSPRO | F522: 0x00000406 | G522: AE_BLOCK_WEIGHT_0 | H522: AE_BLOCK_WEIGHT_1 | I522: ="0x"&AE_w_WORK!F9 -> 0x0000 | J522: 40732 | L522: =L521+2 -> 1032
B523: 517 | E523: JDSPRO | F523: 0x00000408 | G523: AE_BLOCK_WEIGHT_0 | H523: AE_BLOCK_WEIGHT_1 | I523: ="0x"&AE_w_WORK!F10 -> 0x0000 | J523: 40733 | L523: =L522+2 -> 1034
B524: 518 | E524: JDSPRO | F524: 0x0000040A | G524: AE_BLOCK_WEIGHT_0 | H524: AE_BLOCK_WEIGHT_1 | I524: ="0x"&AE_w_WORK!F11 -> 0x0000 | J524: 40734 | L524: =L523+2 -> 1036
B525: 519 | E525: JDSPRO | F525: 0x0000040C | G525: AE_BLOCK_WEIGHT_0 | H525: AE_BLOCK_WEIGHT_1 | I525: ="0x"&AE_w_WORK!F12 -> 0x0000 | J525: 40735 | L525: =L524+2 -> 1038
B526: 520 | E526: JDSPRO | F526: 0x0000040E | G526: AE_BLOCK_WEIGHT_0 | H526: AE_BLOCK_WEIGHT_1 | I526: ="0x"&AE_w_WORK!F13 -> 0x0000 | J526: 40736 | L526: =L525+2 -> 1040
B527: 521 | E527: JDSPRO | F527: 0x00000410 | G527: AE_BLOCK_WEIGHT_0 | H527: AE_BLOCK_WEIGHT_1 | I527: ="0x"&AE_w_WORK!F14 -> 0x0000 | J527: 40737 | L527: =L526+2 -> 1042
...

Sheet ROM_WORK
B6: Whole of ROM structure | C6: Name of BIN file | D6: AE_WEIGHT_MAP.BIN | F6: Detail:Detail information cell name(At the jump destination)
C7: Name of Header file | D7: ae_weight_map.h | F7: Structures:Structure:1 = array, 2 = structure, 3 = Register map, 4 = Menber
C8: Name of Memory File | D8: ae_weight_map.c | F8: Siz: Size: When using array, size of basic type
C9: Memory Map Address | D9: 0x0 | F9: Number of parameter set:When using 2 dimensional array, Number of elements of output data arrays
C10: Nameof Section | D10: AE_WEIGHT_MAP_SECTION | F10: Number of complete set:When using 3 dimensional array, Number of elements of output data arrays
C11: Name of variable | D11: AE_WEIGHT_MEM
C12: Name of Structure | D12: _AE_Weight_map
C13: Name of RAM MAP Add. | D13: ram_map.h
K14: Init Value
B15: Name | C15: Address | D15: Name of Structure | E15: Name of member variable | F15: Detail | G15: Strucures | H15: Size | I15: Number of parameter set | J15: Number of complete set | K15: Sheet | L15: Cell
B16: AE Weight Table | C16: =VLOOKUP(B16,ROM_MAP!$C$1:$F$27535,4,FALSE) -> 0x00000000 | D16: _ae_weight | E16: AE_WEIGHT | F16: ="B"&ROW(B23) -> B23 | G16: 2 | I16: 10
B17: End Address + 1 | C17: =VLOOKUP(B17,ROM_MAP!$C$7:$F$27535,4,FALSE) -> 0x00001400
B19: Data for detail refer
B22: Detail of AE Weight Table structure
B23: AE Weight Table | C23: =VLOOKUP(B23,B16:C16,2,FALSE) -> 0x00000000 | D23: _ae_weight | E23: AE_W | G23: 1 | H23: 1 | I23: 1 | J23: 1
B24: End Address + 1 | C24: ="0x"&DEC2HEX(HEX2DEC(REPLACE(C23,1,2,""))+512,8) -> 0x00000200

Sheet AE_weight
A1: ikuze
A2: * Only the value of a black, bold above the line is reflected in "ROM_MAP"sheet. The value of a possible setting is 0-7. | AP2: =A1&"Work領域" -> ikuzeWork領域 | BB2: テーブル色塗り範囲指定
A3: 1.Center-weighted average 1 (Storage to ROM) | AP3: =A3 -> 1.Center-weighted average 1 (Storage to ROM) | BB3: 下限 | BC3: 上限
C4: 0 | D4: 1 | E4: 2 | F4: 3 | G4: 4 | H4: 5 | I4: 6 | J4: 7 | K4: 8 | L4: 9 | M4: 10 | N4: 11 | O4: 12 | P4: 13 | Q4: 14 | R4: 15 | S4: 16 | T4: 17 | U4: 18 | V4: 19 | W4: 20 | X4: 21 | Y4: 22 | Z4: 23 | AA4: 24 | AB4: 25 | AC4: 26 | AD4: 27 | AE4: 28 | AF4: 29 | AG4: 30 | AH4: 31 | AQ4: =C4&D4&E4&F4 -> 0123 | AR4: =G4&H4&I4&J4 -> 4567 | AS4: =K4&L4&M4&N4 -> 891011 | AT4: =O4&P4&Q4&R4 -> 12131415 | AU4: 16171819 | AV4: 20212223 | AW4: 24252627 | AX4: 28293031 | BB4: 15 | BC4: 15
B5: 0 | C5: 0 | D5: 0 | E5: 0 | F5: 0 | G5: 0 | H5: 0 | I5: 0 | J5: 0 | K5: 0 | L5: 0 | M5: 0 | N5: 0 | O5: 0 | P5: 0 | Q5: 0 | R5: 0 | S5: 0 | T5: 0 | U5: 0 | V5: 0 | W5: 0 | X5: 0 | Y5: 0 | Z5: 0 | AA5: 0 | AB5: 0 | AC5: 0 | AD5: 0 | AE5: 0 | AF5: 0 | AG5: 0 | AH5: 0 | AP5: =B5 -> 0 | AQ5: =DEC2HEX(C5)&DEC2HEX(D5)&DEC2HEX(E5)&DEC2HEX(F5) -> 0000 | AR5: =DEC2HEX(G5)&DEC2HEX(H5)&DEC2HEX(I5)&DEC2HEX(J5) -> 0000 | AS5: =DEC2HEX(K5)&DEC2HEX(L5)&DEC2HEX(M5)&DEC2HEX(N5) -> 0000 | AT5: =DEC2HEX(O5)&DEC2HEX(P5)&DEC2HEX(Q5)&DEC2HEX(R5) -> 0000 | AU5: =DEC2HEX(S5)&DEC2HEX(T5)&DEC2HEX(U5)&DEC2HEX(V5) -> 0000 | AV5: =DEC2HEX(W5)&DEC2HEX(X5)&DEC2HEX(Y5)&DEC2HEX(Z5) -> 0000 | AW5: =DEC2HEX(AA5)&DEC2HEX(AB5)&DEC2HEX(AC5)&DEC2HEX(AD5) -> 0000 | AX5: =DEC2HEX(AE5)&DEC2HEX(AF5)&DEC2HEX(AG5)&DEC2HEX(AH5) -> 0000 | BB5: 13 | BC5: 13
B6: 1 | C6: 0 | D6: 0 | E6: 0 | F6: 0 | G6: 0 | H6: 0 | I6: 0 | J6: 0 | K6: 0 | L6: 0 | M6: 0 | N6: 0 | O6: 1 | P6: 1 | Q6: 1 | R6: 1 | S6: 1 | T6: 1 | U6: 1 | V6: 1 | W6: 0 | X6: 0 | Y6: 0 | Z6: 0 | AA6: 0 | AB6: 0 | AC6: 0 | AD6: 0 | AE6: 0 | AF6: 0 | AG6: 0 | AH6: 0 | AP6: =B6 -> 1 | AQ6: =DEC2HEX(C6)&DEC2HEX(D6)&DEC2HEX(E6)&DEC2HEX(F6) -> 0000 | AR6: =DEC2HEX(G6)&DEC2HEX(H6)&DEC2HEX(I6)&DEC2HEX(J6) -> 0000 | AS6: =DEC2HEX(K6)&DEC2HEX(L6)&DEC2HEX(M6)&DEC2HEX(N6) -> 0000 | AT6: =DEC2HEX(O6)&DEC2HEX(P6)&DEC2HEX(Q6)&DEC2HEX(R6) -> 1111 | AU6: =DEC2HEX(S6)&DEC2HEX(T6)&DEC2HEX(U6)&DEC2HEX(V6) -> 1111 | AV6: =DEC2HEX(W6)&DEC2HEX(X6)&DEC2HEX(Y6)&DEC2HEX(Z6) -> 0000 | AW6: =DEC2HEX(AA6)&DEC2HEX(AB6)&DEC2HEX(AC6)&DEC2HEX(AD6) -> 0000 | AX6: =DEC2HEX(AE6)&DEC2HEX(AF6)&DEC2HEX(AG6)&DEC2HEX(AH6) -> 0000 | BB6: 11 | BC6: 11
B7: 2 | C7: 0 | D7: 0 | E7: 0 | F7: 0 | G7: 0 | H7: 0 | I7: 0 | J7: 0 | K7: 0 | L7: 0 | M7: 1 | N7: 1 | O7: 1 | P7: 1 | Q7: 1 | R7: 1 | S7: 1 | T7: 1 | U7: 1 | V7: 1 | W7: 1 | X7: 1 | Y7: 0 | Z7: 0 | AA7: 0 | AB7: 0 | AC7: 0 | AD7: 0 | AE7: 0 | AF7: 0 | AG7: 0 | AH7: 0 | AP7: =B7 -> 2 | AQ7: =DEC2HEX(C7)&DEC2HEX(D7)&DEC2HEX(E7)&DEC2HEX(F7) -> 0000 | AR7: =DEC2HEX(G7)&DEC2HEX(H7)&DEC2HEX(I7)&DEC2HEX(J7) -> 0000 | AS7: =DEC2HEX(K7)&DEC2HEX(L7)&DEC2HEX(M7)&DEC2HEX(N7) -> 0011 | AT7: =DEC2HEX(O7)&DEC2HEX(P7)&DEC2HEX(Q7)&DEC2HEX(R7) -> 1111 | AU7: =DEC2HEX(S7)&DEC2HEX(T7)&DEC2HEX(U7)&DEC2HEX(V7) -> 1111 | AV7: =DEC2HEX(W7)&DEC2HEX(X7)&DEC2HEX(Y7)&DEC2HEX(Z7) -> 1100 | AW7: =DEC2HEX(AA7)&DEC2HEX(AB7)&DEC2HEX(AC7)&DEC2HEX(AD7) -> 0000 | AX7: =DEC2HEX(AE7)&DEC2HEX(AF7)&DEC2HEX(AG7)&DEC2HEX(AH7) -> 0000 | BB7: 8 | BC7: 8
B8: 3 | C8: 0 | D8: 0 | E8: 0 | F8: 0 | G8: 0 | H8: 0 | I8: 0 | J8: 0 | K8: 1 | L8: 1 | M8: 1 | N8: 1 | O8: 1 | P8: 1 | Q8: 1 | R8: 1 | S8: 1 | T8: 1 | U8: 1 | V8: 1 | W8: 1 | X8: 1 | Y8: 1 | Z8: 1 | AA8: 0 | AB8: 0 | AC8: 0 | AD8: 0 | AE8: 0 | AF8: 0 | AG8: 0 | AH8: 0 | AP8: =B8 -> 3 | AQ8: =DEC2HEX(C8)&DEC2HEX(D8)&DEC2HEX(E8)&DEC2HEX(F8) -> 0000 | AR8: =DEC2HEX(G8)&DEC2HEX(H8)&DEC2HEX(I8)&DEC2HEX(J8) -> 0000 | AS8: =DEC2HEX(K8)&DEC2HEX(L8)&DEC2HEX(M8)&DEC2HEX(N8) -> 1111 | AT8: =DEC2HEX(O8)&DEC2HEX(P8)&DEC2HEX(Q8)&DEC2HEX(R8) -> 1111 | AU8: =DEC2HEX(S8)&DEC2HEX(T8)&DEC2HEX(U8)&DEC2HEX(V8) -> 1111 | AV8: =DEC2HEX(W8)&DEC2HEX(X8)&DEC2HEX(Y8)&DEC2HEX(Z8) -> 1111 | AW8: =DEC2HEX(AA8)&DEC2HEX(AB8)&DEC2HEX(AC8)&DEC2HEX(AD8) -> 0000 | AX8: =DEC2HEX(AE8)&DEC2HEX(AF8)&DEC2HEX(AG8)&DEC2HEX(AH8) -> 0000 | BB8: 6 | BC8: 6
B9: 4 | C9: 0 | D9: 0 | E9: 0 | F9: 0 | G9: 0 | H9: 0 | I9: 1 | J9: 1 | K9: 1 | L9: 1 | M9: 1 | N9: 1 | O9: 2 | P9: 2 | Q9: 2 | R9: 2 | S9: 2 | T9: 2 | U9: 2 | V9: 2 | W9: 1 | X9: 1 | Y9: 1 | Z9: 1 | AA9: 1 | AB9: 1 | AC9: 0 | AD9: 0 | AE9: 0 | AF9: 0 | AG9: 0 | AH9: 0 | AP9: =B9 -> 4 | AQ9: =DEC2HEX(C9)&DEC2HEX(D9)&DEC2HEX(E9)&DEC2HEX(F9) -> 0000 | AR9: =DEC2HEX(G9)&DEC2HEX(H9)&DEC2HEX(I9)&DEC2HEX(J9) -> 0011 | AS9: =DEC2HEX(K9)&DEC2HEX(L9)&DEC2HEX(M9)&DEC2HEX(N9) -> 1111 | AT9: =DEC2HEX(O9)&DEC2HEX(P9)&DEC2HEX(Q9)&DEC2HEX(R9) -> 2222 | AU9: =DEC2HEX(S9)&DEC2HEX(T9)&DEC2HEX(U9)&DEC2HEX(V9) -> 2222 | AV9: =DEC2HEX(W9)&DEC2HEX(X9)&DEC2HEX(Y9)&DEC2HEX(Z9) -> 1111 | AW9: =DEC2HEX(AA9)&DEC2HEX(AB9)&DEC2HEX(AC9)&DEC2HEX(AD9) -> 1100 | AX9: =DEC2HEX(AE9)&DEC2HEX(AF9)&DEC2HEX(AG9)&DEC2HEX(AH9) -> 0000 | BB9: 4 | BC9: 4
B10: 5 | C10: 0 | D10: 0 | E10: 0 | F10: 0 | G10: 0 | H10: 0 | I10: 1 | J10: 1 | K10: 1 | L10: 1 | M10: 2 | N10: 2 | O10: 2 | P10: 2 | Q10: 2 | R10: 2 | S10: 2 | T10: 2 | U10: 2 | V10: 2 | W10: 2 | X10: 2 | Y10: 1 | Z10: 1 | AA10: 1 | AB10: 1 | AC10: 0 | AD10: 0 | AE10: 0 | AF10: 0 | AG10: 0 | AH10: 0 | AP10: =B10 -> 5 | AQ10: =DEC2HEX(C10)&DEC2HEX(D10)&DEC2HEX(E10)&DEC2HEX(F10) -> 0000 | AR10: =DEC2HEX(G10)&DEC2HEX(H10)&DEC2HEX(I10)&DEC2HEX(J10) -> 0011 | AS10: =DEC2HEX(K10)&DEC2HEX(L10)&DEC2HEX(M10)&DEC2HEX(N10) -> 1122 | AT10: =DEC2HEX(O10)&DEC2HEX(P10)&DEC2HEX(Q10)&DEC2HEX(R10) -> 2222 | AU10: =DEC2HEX(S10)&DEC2HEX(T10)&DEC2HEX(U10)&DEC2HEX(V10) -> 2222 | AV10: =DEC2HEX(W10)&DEC2HEX(X10)&DEC2HEX(Y10)&DEC2HEX(Z10) -> 2211 | AW10: =DEC2HEX(AA10)&DEC2HEX(AB10)&DEC2HEX(AC10)&DEC2HEX(AD10) -> 1100 | AX10: =DEC2HEX(AE10)&DEC2HEX(AF10)&DEC2HEX(AG10)&DEC2HEX(AH10) -> 0000 | BB10: 2 | BC10: 3
B11: 6 | C11: 0 | D11: 0 | E11: 0 | F11: 0 | G11: 1 | H11: 1 | I11: 1 | J11: 1 | K11: 2 | L11: 2 | M11: 2 | N11: 2 | O11: 2 | P11: 2 | Q11: 3 | R11: 3 | S11: 3 | T11: 3 | U11: 2 | V11: 2 | W11: 2 | X11: 2 | Y11: 2 | Z11: 2 | AA11: 1 | AB11: 1 | AC11: 1 | AD11: 1 | AE11: 0 | AF11: 0 | AG11: 0 | AH11: 0 | AP11: =B11 -> 6 | AQ11: =DEC2HEX(C11)&DEC2HEX(D11)&DEC2HEX(E11)&DEC2HEX(F11) -> 0000 | AR11: =DEC2HEX(G11)&DEC2HEX(H11)&DEC2HEX(I11)&DEC2HEX(J11) -> 1111 | AS11: =DEC2HEX(K11)&DEC2HEX(L11)&DEC2HEX(M11)&DEC2HEX(N11) -> 2222 | AT11: =DEC2HEX(O11)&DEC2HEX(P11)&DEC2HEX(Q11)&DEC2HEX(R11) -> 2233 | AU11: =DEC2HEX(S11)&DEC2HEX(T11)&DEC2HEX(U11)&DEC2HEX(V11) -> 3322 | AV11: =DEC2HEX(W11)&DEC2HEX(X11)&DEC2HEX(Y11)&DEC2HEX(Z11) -> 2222 | AW11: =DEC2HEX(AA11)&DEC2HEX(AB11)&DEC2HEX(AC11)&DEC2HEX(AD11) -> 1111 | AX11: =DEC2HEX(AE11)&DEC2HEX(AF11)&DEC2HEX(AG11)&DEC2HEX(AH11) -> 0000 | BB11: 1 | BC11: 1
B12: 7 | C12: 0 | D12: 0 | E12: 0 | F12: 0 | G12: 1 | H12: 1 | I12: 1 | J12: 1 | K12: 2 | L12: 2 | M12: 2 | N12: 2 | O12: 3 | P12: 3 | Q12: 4 | R12: 4 | S12: 3 | T12: 3 | U12: 4 | V12: 4 | W12: 2 | X12: 2 | Y12: 2 | Z12: 2 | AA12: 1 | AB12: 1 | AC12: 1 | AD12: 1 | AE12: 0 | AF12: 0 | AG12: 0 | AH12: 0 | AP12: =B12 -> 7 | AQ12: =DEC2HEX(C12)&DEC2HEX(D12)&DEC2HEX(E12)&DEC2HEX(F12) -> 0000 | AR12: =DEC2HEX(G12)&DEC2HEX(H12)&DEC2HEX(I12)&DEC2HEX(J12) -> 1111 | AS12: =DEC2HEX(K12)&DEC2HEX(L12)&DEC2HEX(M12)&DEC2HEX(N12) -> 2222 | AT12: =DEC2HEX(O12)&DEC2HEX(P12)&DEC2HEX(Q12)&DEC2HEX(R12) -> 3344 | AU12: =DEC2HEX(S12)&DEC2HEX(T12)&DEC2HEX(U12)&DEC2HEX(V12) -> 3344 | AV12: =DEC2HEX(W12)&DEC2HEX(X12)&DEC2HEX(Y12)&DEC2HEX(Z12) -> 2222 | AW12: =DEC2HEX(AA12)&DEC2HEX(AB12)&DEC2HEX(AC12)&DEC2HEX(AD12) -> 1111 | AX12: =DEC2HEX(AE12)&DEC2HEX(AF12)&DEC2HEX(AG12)&DEC2HEX(AH12) -> 0000
B13: 8 | C13: 0 | D13: 0 | E13: 1 | F13: 1 | G13: 1 | H13: 1 | I13: 2 | J13: 2 | K13: 2 | L13: 2 | M13: 3 | N13: 3 | O13: 3 | P13: 3 | Q13: 4 | R13: 4 | S13: 4 | T13: 4 | U13: 3 | V13: 3 | W13: 3 | X13: 3 | Y13: 2 | Z13: 2 | AA13: 2 | AB13: 2 | AC13: 1 | AD13: 1 | AE13: 1 | AF13: 1 | AG13: 0 | AH13: 0 | AP13: =B13 -> 8 | AQ13: =DEC2HEX(C13)&DEC2HEX(D13)&DEC2HEX(E13)&DEC2HEX(F13) -> 0011 | AR13: =DEC2HEX(G13)&DEC2HEX(H13)&DEC2HEX(I13)&DEC2HEX(J13) -> 1122 | AS13: =DEC2HEX(K13)&DEC2HEX(L13)&DEC2HEX(M13)&DEC2HEX(N13) -> 2233 | AT13: =DEC2HEX(O13)&DEC2HEX(P13)&DEC2HEX(Q13)&DEC2HEX(R13) -> 3344 | AU13: =DEC2HEX(S13)&DEC2HEX(T13)&DEC2HEX(U13)&DEC2HEX(V13) -> 4433 | AV13: =DEC2HEX(W13)&DEC2HEX(X13)&DEC2HEX(Y13)&DEC2HEX(Z13) -> 3322 | AW13: =DEC2HEX(AA13)&DEC2HEX(AB13)&DEC2HEX(AC13)&DEC2HEX(AD13) -> 2211 | AX13: =DEC2HEX(AE13)&DEC2HEX(AF13)&DEC2HEX(AG13)&DEC2HEX(AH13) -> 1100 | BB13: 重み係数指定
B14: 9 | C14: 0 | D14: 0 | E14: 1 | F14: 1 | G14: 1 | H14: 1 | I14: 2 | J14: 2 | K14: 3 | L14: 3 | M14: 3 | N14: 3 | O14: 4 | P14: 4 | Q14: 4 | R14: 4 | S14: 4 | T14: 4 | U14: 4 | V14: 4 | W14: 3 | X14: 3 | Y14: 3 | Z14: 3 | AA14: 2 | AB14: 2 | AC14: 1 | AD14: 1 | AE14: 1 | AF14: 1 | AG14: 0 | AH14: 0 | AP14: =B14 -> 9 | AQ14: =DEC2HEX(C14)&DEC2HEX(D14)&DEC2HEX(E14)&DEC2HEX(F14) -> 0011 | AR14: =DEC2HEX(G14)&DEC2HEX(H14)&DEC2HEX(I14)&DEC2HEX(J14) -> 1122 | AS14: =DEC2HEX(K14)&DEC2HEX(L14)&DEC2HEX(M14)&DEC2HEX(N14) -> 3333 | AT14: =DEC2HEX(O14)&DEC2HEX(P14)&DEC2HEX(Q14)&DEC2HEX(R14) -> 4444 | AU14: =DEC2HEX(S14)&DEC2HEX(T14)&DEC2HEX(U14)&DEC2HEX(V14) -> 4444 | AV14: =DEC2HEX(W14)&DEC2HEX(X14)&DEC2HEX(Y14)&DEC2HEX(Z14) -> 3333 | AW14: =DEC2HEX(AA14)&DEC2HEX(AB14)&DEC2HEX(AC14)&DEC2HEX(AD14) -> 2211 | AX14: =DEC2HEX(AE14)&DEC2HEX(AF14)&DEC2HEX(AG14)&DEC2HEX(AH14) -> 1100 | BB14: 設定値 | BC14: 重み係数
B15: 10 | C15: 0 | D15: 0 | E15: 1 | F15: 1 | G15: 2 | H15: 2 | I15: 2 | J15: 2 | K15: 3 | L15: 3 | M15: 4 | N15: 4 | O15: 4 | P15: 4 | Q15: 5 | R15: 5 | S15: 5 | T15: 5 | U15: 4 | V15: 4 | W15: 4 | X15: 4 | Y15: 3 | Z15: 3 | AA15: 2 | AB15: 2 | AC15: 2 | AD15: 2 | AE15: 1 | AF15: 1 | AG15: 0 | AH15: 0 | AP15: =B15 -> 10 | AQ15: =DEC2HEX(C15)&DEC2HEX(D15)&DEC2HEX(E15)&DEC2HEX(F15) -> 0011 | AR15: =DEC2HEX(G15)&DEC2HEX(H15)&DEC2HEX(I15)&DEC2HEX(J15) -> 2222 | AS15: =DEC2HEX(K15)&DEC2HEX(L15)&DEC2HEX(M15)&DEC2HEX(N15) -> 3344 | AT15: =DEC2HEX(O15)&DEC2HEX(P15)&DEC2HEX(Q15)&DEC2HEX(R15) -> 4455 | AU15: =DEC2HEX(S15)&DEC2HEX(T15)&DEC2HEX(U15)&DEC2HEX(V15) -> 5544 | AV15: =DEC2HEX(W15)&DEC2HEX(X15)&DEC2HEX(Y15)&DEC2HEX(Z15) -> 4433 | AW15: =DEC2HEX(AA15)&DEC2HEX(AB15)&DEC2HEX(AC15)&DEC2HEX(AD15) -> 2222 | AX15: =DEC2HEX(AE15)&DEC2HEX(AF15)&DEC2HEX(AG15)&DEC2HEX(AH15) -> 1100 | BB15: 0 | BC15: 積算しない
B16: 11 | C16: 0 | D16: 0 | E16: 1 | F16: 1 | G16: 2 | H16: 2 | I16: 3 | J16: 3 | K16: 4 | L16: 4 | M16: 4 | N16: 4 | O16: 5 | P16: 5 | Q16: 5 | R16: 5 | S16: 5 | T16: 5 | U16: 5 | V16: 5 | W16: 4 | X16: 4 | Y16: 4 | Z16: 4 | AA16: 3 | AB16: 3 | AC16: 2 | AD16: 2 | AE16: 1 | AF16: 1 | AG16: 0 | AH16: 0 | AP16: =B16 -> 11 | AQ16: =DEC2HEX(C16)&DEC2HEX(D16)&DEC2HEX(E16)&DEC2HEX(F16) -> 0011 | AR16: =DEC2HEX(G16)&DEC2HEX(H16)&DEC2HEX(I16)&DEC2HEX(J16) -> 2233 | AS16: =DEC2HEX(K16)&DEC2HEX(L16)&DEC2HEX(M16)&DEC2HEX(N16) -> 4444 | AT16: =DEC2HEX(O16)&DEC2HEX(P16)&DEC2HEX(Q16)&DEC2HEX(R16) -> 5555 | AU16: =DEC2HEX(S16)&DEC2HEX(T16)&DEC2HEX(U16)&DEC2HEX(V16) -> 5555 | AV16: =DEC2HEX(W16)&DEC2HEX(X16)&DEC2HEX(Y16)&DEC2HEX(Z16) -> 4444 | AW16: =DEC2HEX(AA16)&DEC2HEX(AB16)&DEC2HEX(AC16)&DEC2HEX(AD16) -> 3322 | AX16: =DEC2HEX(AE16)&DEC2HEX(AF16)&DEC2HEX(AG16)&DEC2HEX(AH16) -> 1100 | BB16: 1 | BC16: 積算結果 * 1/16
B17: 12 | C17: 0 | D17: 0 | E17: 1 | F17: 1 | G17: 2 | H17: 2 | I17: 3 | J17: 3 | K17: 4 | L17: 4 | M17: 5 | N17: 5 | O17: 5 | P17: 5 | Q17: 5 | R17: 5 | S17: 5 | T17: 5 | U17: 5 | V17: 5 | W17: 5 | X17: 5 | Y17: 4 | Z17: 4 | AA17: 3 | AB17: 3 | AC17: 2 | AD17: 2 | AE17: 1 | AF17: 1 | AG17: 0 | AH17: 0 | AP17: =B17 -> 12 | AQ17: =DEC2HEX(C17)&DEC2HEX(D17)&DEC2HEX(E17)&DEC2HEX(F17) -> 0011 | AR17: =DEC2HEX(G17)&DEC2HEX(H17)&DEC2HEX(I17)&DEC2HEX(J17) -> 2233 | AS17: =DEC2HEX(K17)&DEC2HEX(L17)&DEC2HEX(M17)&DEC2HEX(N17) -> 4455 | AT17: =DEC2HEX(O17)&DEC2HEX(P17)&DEC2HEX(Q17)&DEC2HEX(R17) -> 5555 | AU17: =DEC2HEX(S17)&DEC2HEX(T17)&DEC2HEX(U17)&DEC2HEX(V17) -> 5555 | AV17: =DEC2HEX(W17)&DEC2HEX(X17)&DEC2HEX(Y17)&DEC2HEX(Z17) -> 5544 | AW17: =DEC2HEX(AA17)&DEC2HEX(AB17)&DEC2HEX(AC17)&DEC2HEX(AD17) -> 3322 | AX17: =DEC2HEX(AE17)&DEC2HEX(AF17)&DEC2HEX(AG17)&DEC2HEX(AH17) -> 1100 | BB17: 2 | BC17: 積算結果 * 2/16
B18: 13 | C18: 0 | D18: 0 | E18: 1 | F18: 1 | G18: 2 | H18: 2 | I18: 3 | J18: 3 | K18: 4 | L18: 4 | M18: 5 | N18: 5 | O18: 5 | P18: 5 | Q18: 5 | R18: 5 | S18: 5 | T18: 5 | U18: 5 | V18: 5 | W18: 5 | X18: 5 | Y18: 4 | Z18: 4 | AA18: 3 | AB18: 3 | AC18: 2 | AD18: 2 | AE18: 1 | AF18: 1 | AG18: 0 | AH18: 0 | AP18: =B18 -> 13 | AQ18: =DEC2HEX(C18)&DEC2HEX(D18)&DEC2HEX(E18)&DEC2HEX(F18) -> 0011 | AR18: =DEC2HEX(G18)&DEC2HEX(H18)&DEC2HEX(I18)&DEC2HEX(J18) -> 2233 | AS18: =DEC2HEX(K18)&DEC2HEX(L18)&DEC2HEX(M18)&DEC2HEX(N18) -> 4455 | AT18: =DEC2HEX(O18)&DEC2HEX(P18)&DEC2HEX(Q18)&DEC2HEX(R18) -> 5555 | AU18: =DEC2HEX(S18)&DEC2HEX(T18)&DEC2HEX(U18)&DEC2HEX(V18) -> 5555 | AV18: =DEC2HEX(W18)&DEC2HEX(X18)&DEC2HEX(Y18)&DEC2HEX(Z18) -> 5544 | AW18: =DEC2HEX(AA18)&DEC2HEX(AB18)&DEC2HEX(AC18)&DEC2HEX(AD18) -> 3322 | AX18: =DEC2HEX(AE18)&DEC2HEX(AF18)&DEC2HEX(AG18)&DEC2HEX(AH18) -> 1100 | BB18: 3 | BC18: 積算結果 * 3/16
B19: 14 | C19: 0 | D19: 0 | E19: 1 | F19: 1 | G19: 2 | H19: 2 | I19: 3 | J19: 3 | K19: 4 | L19: 4 | M19: 5 | N19: 5 | O19: 5 | P19: 5 | Q19: 5 | R19: 5 | S19: 5 | T19: 5 | U19: 5 | V19: 5 | W19: 5 | X19: 5 | Y19: 4 | Z19: 4 | AA19: 4 | AB19: 4 | AC19: 2 | AD19: 2 | AE19: 1 | AF19: 1 | AG19: 0 | AH19: 0 | AP19: =B19 -> 14 | AQ19: =DEC2HEX(C19)&DEC2HEX(D19)&DEC2HEX(E19)&DEC2HEX(F19) -> 0011 | AR19: =DEC2HEX(G19)&DEC2HEX(H19)&DEC2HEX(I19)&DEC2HEX(J19) -> 2233 | AS19: =DEC2HEX(K19)&DEC2HEX(L19)&DEC2HEX(M19)&DEC2HEX(N19) -> 4455 | AT19: =DEC2HEX(O19)&DEC2HEX(P19)&DEC2HEX(Q19)&DEC2HEX(R19) -> 5555 | AU19: =DEC2HEX(S19)&DEC2HEX(T19)&DEC2HEX(U19)&DEC2HEX(V19) -> 5555 | AV19: =DEC2HEX(W19)&DEC2HEX(X19)&DEC2HEX(Y19)&DEC2HEX(Z19) -> 5544 | AW19: =DEC2HEX(AA19)&DEC2HEX(AB19)&DEC2HEX(AC19)&DEC2HEX(AD19) -> 4422 | AX19: =DEC2HEX(AE19)&DEC2HEX(AF19)&DEC2HEX(AG19)&DEC2HEX(AH19) -> 1100 | BB19: 4 | BC19: 積算結果 * 4/16
B20: 15 | C20: 0 | D20: 0 | E20: 1 | F20: 1 | G20: 2 | H20: 2 | I20: 4 | J20: 4 | K20: 4 | L20: 4 | M20: 5 | N20: 5 | O20: 5 | P20: 5 | Q20: 5 | R20: 5 | S20: 5 | T20: 5 | U20: 5 | V20: 5 | W20: 5 | X20: 5 | Y20: 4 | Z20: 4 | AA20: 3 | AB20: 3 | AC20: 2 | AD20: 2 | AE20: 1 | AF20: 1 | AG20: 0 | AH20: 0 | AP20: =B20 -> 15 | AQ20: =DEC2HEX(C20)&DEC2HEX(D20)&DEC2HEX(E20)&DEC2HEX(F20) -> 0011 | AR20: =DEC2HEX(G20)&DEC2HEX(H20)&DEC2HEX(I20)&DEC2HEX(J20) -> 2244 | AS20: =DEC2HEX(K20)&DEC2HEX(L20)&DEC2HEX(M20)&DEC2HEX(N20) -> 4455 | AT20: =DEC2HEX(O20)&DEC2HEX(P20)&DEC2HEX(Q20)&DEC2HEX(R20) -> 5555 | AU20: =DEC2HEX(S20)&DEC2HEX(T20)&DEC2HEX(U20)&DEC2HEX(V20) -> 5555 | AV20: =DEC2HEX(W20)&DEC2HEX(X20)&DEC2HEX(Y20)&DEC2HEX(Z20) -> 5544 | AW20: =DEC2HEX(AA20)&DEC2HEX(AB20)&DEC2HEX(AC20)&DEC2HEX(AD20) -> 3322 | AX20: =DEC2HEX(AE20)&DEC2HEX(AF20)&DEC2HEX(AG20)&DEC2HEX(AH20) -> 1100 | BB20: 5 | BC20: 積算結果 * 5/16
B21: 16 | C21: 0 | D21: 0 | E21: 1 | F21: 1 | G21: 2 | H21: 2 | I21: 3 | J21: 3 | K21: 4 | L21: 4 | M21: 5 | N21: 5 | O21: 5 | P21: 5 | Q21: 5 | R21: 5 | S21: 5 | T21: 5 | U21: 5 | V21: 5 | W21: 5 | X21: 5 | Y21: 4 | Z21: 4 | AA21: 4 | AB21: 4 | AC21: 2 | AD21: 2 | AE21: 1 | AF21: 1 | AG21: 0 | AH21: 0 | AP21: =B21 -> 16 | AQ21: =DEC2HEX(C21)&DEC2HEX(D21)&DEC2HEX(E21)&DEC2HEX(F21) -> 0011 | AR21: =DEC2HEX(G21)&DEC2HEX(H21)&DEC2HEX(I21)&DEC2HEX(J21) -> 2233 | AS21: =DEC2HEX(K21)&DEC2HEX(L21)&DEC2HEX(M21)&DEC2HEX(N21) -> 4455 | AT21: =DEC2HEX(O21)&DEC2HEX(P21)&DEC2HEX(Q21)&DEC2HEX(R21) -> 5555 | AU21: =DEC2HEX(S21)&DEC2HEX(T21)&DEC2HEX(U21)&DEC2HEX(V21) -> 5555 | AV21: =DEC2HEX(W21)&DEC2HEX(X21)&DEC2HEX(Y21)&DEC2HEX(Z21) -> 5544 | AW21: =DEC2HEX(AA21)&DEC2HEX(AB21)&DEC2HEX(AC21)&DEC2HEX(AD21) -> 4422 | AX21: =DEC2HEX(AE21)&DEC2HEX(AF21)&DEC2HEX(AG21)&DEC2HEX(AH21) -> 1100 | BB21: 6 | BC21: 積算結果 * 6/16
B22: 17 | C22: 0 | D22: 0 | E22: 1 | F22: 1 | G22: 2 | H22: 2 | I22: 4 | J22: 4 | K22: 4 | L22: 4 | M22: 5 | N22: 5 | O22: 5 | P22: 5 | Q22: 5 | R22: 5 | S22: 5 | T22: 5 | U22: 5 | V22: 5 | W22: 5 | X22: 5 | Y22: 4 | Z22: 4 | AA22: 3 | AB22: 3 | AC22: 2 | AD22: 2 | AE22: 1 | AF22: 1 | AG22: 0 | AH22: 0 | AP22: =B22 -> 17 | AQ22: =DEC2HEX(C22)&DEC2HEX(D22)&DEC2HEX(E22)&DEC2HEX(F22) -> 0011 | AR22: =DEC2HEX(G22)&DEC2HEX(H22)&DEC2HEX(I22)&DEC2HEX(J22) -> 2244 | AS22: =DEC2HEX(K22)&DEC2HEX(L22)&DEC2HEX(M22)&DEC2HEX(N22) -> 4455 | AT22: =DEC2HEX(O22)&DEC2HEX(P22)&DEC2HEX(Q22)&DEC2HEX(R22) -> 5555 | AU22: =DEC2HEX(S22)&DEC2HEX(T22)&DEC2HEX(U22)&DEC2HEX(V22) -> 5555 | AV22: =DEC2HEX(W22)&DEC2HEX(X22)&DEC2HEX(Y22)&DEC2HEX(Z22) -> 5544 | AW22: =DEC2HEX(AA22)&DEC2HEX(AB22)&DEC2HEX(AC22)&DEC2HEX(AD22) -> 3322 | AX22: =DEC2HEX(AE22)&DEC2HEX(AF22)&DEC2HEX(AG22)&DEC2HEX(AH22) -> 1100 | BB22: 7 | BC22: 積算結果 * 7/16
B23: 18 | C23: 0 | D23: 0 | E23: 1 | F23: 1 | G23: 2 | H23: 2 | I23: 3 | J23: 3 | K23: 4 | L23: 4 | M23: 5 | N23: 5 | O23: 5 | P23: 5 | Q23: 5 | R23: 5 | S23: 5 | T23: 5 | U23: 5 | V23: 5 | W23: 5 | X23: 5 | Y23: 4 | Z23: 4 | AA23: 3 | AB23: 3 | AC23: 2 | AD23: 2 | AE23: 1 | AF23: 1 | AG23: 0 | AH23: 0 | AP23: =B23 -> 18 | AQ23: =DEC2HEX(C23)&DEC2HEX(D23)&DEC2HEX(E23)&DEC2HEX(F23) -> 0011 | AR23: =DEC2HEX(G23)&DEC2HEX(H23)&DEC2HEX(I23)&DEC2HEX(J23) -> 2233 | AS23: =DEC2HEX(K23)&DEC2HEX(L23)&DEC2HEX(M23)&DEC2HEX(N23) -> 4455 | AT23: =DEC2HEX(O23)&DEC2HEX(P23)&DEC2HEX(Q23)&DEC2HEX(R23) -> 5555 | AU23: =DEC2HEX(S23)&DEC2HEX(T23)&DEC2HEX(U23)&DEC2HEX(V23) -> 5555 | AV23: =DEC2HEX(W23)&DEC2HEX(X23)&DEC2HEX(Y23)&DEC2HEX(Z23) -> 5544 | AW23: =DEC2HEX(AA23)&DEC2HEX(AB23)&DEC2HEX(AC23)&DEC2HEX(AD23) -> 3322 | AX23: =DEC2HEX(AE23)&DEC2HEX(AF23)&DEC2HEX(AG23)&DEC2HEX(AH23) -> 1100 | BB23: 8 | BC23: 積算結果 * 8/16
B24: 19 | C24: 0 | D24: 0 | E24: 1 | F24: 1 | G24: 2 | H24: 2 | I24: 3 | J24: 3 | K24: 4 | L24: 4 | M24: 5 | N24: 5 | O24: 5 | P24: 5 | Q24: 5 | R24: 5 | S24: 5 | T24: 5 | U24: 5 | V24: 5 | W24: 5 | X24: 5 | Y24: 4 | Z24: 4 | AA24: 3 | AB24: 3 | AC24: 2 | AD24: 2 | AE24: 1 | AF24: 1 | AG24: 0 | AH24: 0 | AP24: =B24 -> 19 | AQ24: =DEC2HEX(C24)&DEC2HEX(D24)&DEC2HEX(E24)&DEC2HEX(F24) -> 0011 | AR24: =DEC2HEX(G24)&DEC2HEX(H24)&DEC2HEX(I24)&DEC2HEX(J24) -> 2233 | AS24: =DEC2HEX(K24)&DEC2HEX(L24)&DEC2HEX(M24)&DEC2HEX(N24) -> 4455 | AT24: =DEC2HEX(O24)&DEC2HEX(P24)&DEC2HEX(Q24)&DEC2HEX(R24) -> 5555 | AU24: =DEC2HEX(S24)&DEC2HEX(T24)&DEC2HEX(U24)&DEC2HEX(V24) -> 5555 | AV24: =DEC2HEX(W24)&DEC2HEX(X24)&DEC2HEX(Y24)&DEC2HEX(Z24) -> 5544 | AW24: =DEC2HEX(AA24)&DEC2HEX(AB24)&DEC2HEX(AC24)&DEC2HEX(AD24) -> 3322 | AX24: =DEC2HEX(AE24)&DEC2HEX(AF24)&DEC2HEX(AG24)&DEC2HEX(AH24) -> 1100 | BB24: 9 | BC24: 積算結果 * 9/16
B25: 20 | C25: 0 | D25: 0 | E25: 1 | F25: 1 | G25: 2 | H25: 2 | I25: 3 | J25: 3 | K25: 4 | L25: 4 | M25: 4 | N25: 4 | O25: 5 | P25: 5 | Q25: 5 | R25: 5 | S25: 5 | T25: 5 | U25: 5 | V25: 5 | W25: 4 | X25: 4 | Y25: 4 | Z25: 4 | AA25: 3 | AB25: 3 | AC25: 2 | AD25: 2 | AE25: 1 | AF25: 1 | AG25: 0 | AH25: 0 | AP25: =B25 -> 20 | AQ25: =DEC2HEX(C25)&DEC2HEX(D25)&DEC2HEX(E25)&DEC2HEX(F25) -> 0011 | AR25: =DEC2HEX(G25)&DEC2HEX(H25)&DEC2HEX(I25)&DEC2HEX(J25) -> 2233 | AS25: =DEC2HEX(K25)&DEC2HEX(L25)&DEC2HEX(M25)&DEC2HEX(N25) -> 4444 | AT25: =DEC2HEX(O25)&DEC2HEX(P25)&DEC2HEX(Q25)&DEC2HEX(R25) -> 5555 | AU25: =DEC2HEX(S25)&DEC2HEX(T25)&DEC2HEX(U25)&DEC2HEX(V25) -> 5555 | AV25: =DEC2HEX(W25)&DEC2HEX(X25)&DEC2HEX(Y25)&DEC2HEX(Z25) -> 4444 | AW25: =DEC2HEX(AA25)&DEC2HEX(AB25)&DEC2HEX(AC25)&DEC2HEX(AD25) -> 3322 | AX25: =DEC2HEX(AE25)&DEC2HEX(AF25)&DEC2HEX(AG25)&DEC2HEX(AH25) -> 1100 | BB25: 10 | BC25: 積算結果 * 10/16
B26: 21 | C26: 0 | D26: 0 | E26: 1 | F26: 1 | G26: 2 | H26: 2 | I26: 2 | J26: 2 | K26: 3 | L26: 3 | M26: 4 | N26: 4 | O26: 4 | P26: 4 | Q26: 5 | R26: 5 | S26: 5 | T26: 5 | U26: 4 | V26: 4 | W26: 4 | X26: 4 | Y26: 3 | Z26: 3 | AA26: 2 | AB26: 2 | AC26: 2 | AD26: 2 | AE26: 1 | AF26: 1 | AG26: 0 | AH26: 0 | AP26: =B26 -> 21 | AQ26: =DEC2HEX(C26)&DEC2HEX(D26)&DEC2HEX(E26)&DEC2HEX(F26) -> 0011 | AR26: =DEC2HEX(G26)&DEC2HEX(H26)&DEC2HEX(I26)&DEC2HEX(J26) -> 2222 | AS26: =DEC2HEX(K26)&DEC2HEX(L26)&DEC2HEX(M26)&DEC2HEX(N26) -> 3344 | AT26: =DEC2HEX(O26)&DEC2HEX(P26)&DEC2HEX(Q26)&DEC2HEX(R26) -> 4455 | AU26: =DEC2HEX(S26)&DEC2HEX(T26)&DEC2HEX(U26)&DEC2HEX(V26) -> 5544 | AV26: =DEC2HEX(W26)&DEC2HEX(X26)&DEC2HEX(Y26)&DEC2HEX(Z26) -> 4433 | AW26: =DEC2HEX(AA26)&DEC2HEX(AB26)&DEC2HEX(AC26)&DEC2HEX(AD26) -> 2222 | AX26: =DEC2HEX(AE26)&DEC2HEX(AF26)&DEC2HEX(AG26)&DEC2HEX(AH26) -> 1100 | BB26: 11 | BC26: 積算結果 * 11/16
... B30: 25 | C30: 0 | D30: 0 | E30: 0 | F30: 0 | G30: 1 | H30: 1 | I30: 1 | J30: 1 | K30: 2 | L30: 2 | M30: 2 | N30: 2 | O30: 2 | P30: 2 | Q30: 3 | R30: 3 | S30: 3 | T30: 3 | U30: 2 | V30: 2 | W30: 2 | X30: 2 | Y30: 2 | Z30: 2 | AA30: 1 | AB30: 1 | AC30: 1 | AD30: 1 | AE30: 0 | AF30: 0 | AG30: 0 | AH30: 0 | AP30: =B30 -> 25 | AQ30: =DEC2HEX(C30)&DEC2HEX(D30)&DEC2HEX(E30)&DEC2HEX(F30) -> 0000 | AR30: =DEC2HEX(G30)&DEC2HEX(H30)&DEC2HEX(I30)&DEC2HEX(J30) -> 1111 | AS30: =DEC2HEX(K30)&DEC2HEX(L30)&DEC2HEX(M30)&DEC2HEX(N30) -> 2222 | AT30: =DEC2HEX(O30)&DEC2HEX(P30)&DEC2HEX(Q30)&DEC2HEX(R30) -> 2233 | AU30: =DEC2HEX(S30)&DEC2HEX(T30)&DEC2HEX(U30)&DEC2HEX(V30) -> 3322 | AV30: =DEC2HEX(W30)&DEC2HEX(X30)&DEC2HEX(Y30)&DEC2HEX(Z30) -> 2222 | AW30: =DEC2HEX(AA30)&DEC2HEX(AB30)&DEC2HEX(AC30)&DEC2HEX(AD30) -> 1111 | AX30: =DEC2HEX(AE30)&DEC2HEX(AF30)&DEC2HEX(AG30)&DEC2HEX(AH30) -> 0000 | BB30: 15 | BC30: 積算結果 * 15/16
B31: 26 | C31: 0 | D31: 0 | E31: 0 | F31: 0 | G31: 0 | H31: 0 | I31: 1 | J31: 1 | K31: 1 | L31: 1 | M31: 2 | N31: 2 | O31: 2 | P31: 2 | Q31: 2 | R31: 2 | S31: 2 | T31: 2 | U31: 2 | V31: 2 | W31: 2 | X31: 2 | Y31: 1 | Z31: 1 | AA31: 1 | AB31: 1 | AC31: 0 | AD31: 0 | AE31: 0 | AF31: 0 | AG31: 0 | AH31: 0 | AP31: =B31 -> 26 | AQ31: =DEC2HEX(C31)&DEC2HEX(D31)&DEC2HEX(E31)&DEC2HEX(F31) -> 0000 | AR31: =DEC2HEX(G31)&DEC2HEX(H31)&DEC2HEX(I31)&DEC2HEX(J31) -> 0011 | AS31: =DEC2HEX(K31)&DEC2HEX(L31)&DEC2HEX(M31)&DEC2HEX(N31) -> 1122 | AT31: =DEC2HEX(O31)&DEC2HEX(P31)&DEC2HEX(Q31)&DEC2HEX(R31) -> 2222 | AU31: =DEC2HEX(S31)&DEC2HEX(T31)&DEC2HEX(U31)&DEC2HEX(V31) -> 2222 | AV31: =DEC2HEX(W31)&DEC2HEX(X31)&DEC2HEX(Y31)&DEC2HEX(Z31) -> 2211 | AW31: =DEC2HEX(AA31)&DEC2HEX(AB31)&DEC2HEX(AC31)&DEC2HEX(AD31) -> 1100 | AX31: =DEC2HEX(AE31)&DEC2HEX(AF31)&DEC2HEX(AG31)&DEC2HEX(AH31) -> 0000
B32: 27 | C32: 0 | D32: 0 | E32: 0 | F32: 0 | G32: 0 | H32: 0 | I32: 1 | J32: 1 | K32: 1 | L32: 1 | M32: 1 | N32: 1 | O32: 2 | P32: 2 | Q32: 2 | R32: 2 | S32: 2 | T32: 2 | U32: 2 | V32: 2 | W32: 1 | X32: 1 | Y32: 1 | Z32: 1 | AA32: 0 | AB32: 0 | AC32: 0 | AD32: 0 | AE32: 0 | AF32: 0 | AG32: 0 | AH32: 0 | AP32: =B32 -> 27 | AQ32: =DEC2HEX(C32)&DEC2HEX(D32)&DEC2HEX(E32)&DEC2HEX(F32) -> 0000 | AR32: =DEC2HEX(G32)&DEC2HEX(H32)&DEC2HEX(I32)&DEC2HEX(J32) -> 0011 | AS32: =DEC2HEX(K32)&DEC2HEX(L32)&DEC2HEX(M32)&DEC2HEX(N32) -> 1111 | AT32: =DEC2HEX(O32)&DEC2HEX(P32)&DEC2HEX(Q32)&DEC2HEX(R32) -> 2222 | AU32: =DEC2HEX(S32)&DEC2HEX(T32)&DEC2HEX(U32)&DEC2HEX(V32) -> 2222 | AV32: =DEC2HEX(W32)&DEC2HEX(X32)&DEC2HEX(Y32)&DEC2HEX(Z32) -> 1111 | AW32: =DEC2HEX(AA32)&DEC2HEX(AB32)&DEC2HEX(AC32)&DEC2HEX(AD32) -> 0000 | AX32: =DEC2HEX(AE32)&DEC2HEX(AF32)&DEC2HEX(AG32)&DEC2HEX(AH32) -> 0000 | BB32: ※AE/AWB検波サイズが16x16の時は、
B33: 28 | C33: 0 | D33: 0 | E33: 0 | F33: 0 | G33: 0 | H33: 0 | I33: 0 | J33: 0 | K33: 1 | L33: 1 | M33: 1 | N33: 1 | O33: 1 | P33: 1 | Q33: 1 | R33: 1 | S33: 1 | T33: 1 | U33: 1 | V33: 1 | W33: 1 | X33: 1 | Y33: 1 | Z33: 1 | AA33: 0 | AB33: 0 | AC33: 0 | AD33: 0 | AE33: 0 | AF33: 0 | AG33: 0 | AH33: 0 | AP33: =B33 -> 28 | AQ33: =DEC2HEX(C33)&DEC2HEX(D33)&DEC2HEX(E33)&DEC2HEX(F33) -> 0000 | AR33: =DEC2HEX(G33)&DEC2HEX(H33)&DEC2HEX(I33)&DEC2HEX(J33) -> 0000 | AS33: =DEC2HEX(K33)&DEC2HEX(L33)&DEC2HEX(M33)&DEC2HEX(N33) -> 1111 | AT33: =DEC2HEX(O33)&DEC2HEX(P33)&DEC2HEX(Q33)&DEC2HEX(R33) -> 1111 | AU33: =DEC2HEX(S33)&DEC2HEX(T33)&DEC2HEX(U33)&DEC2HEX(V33) -> 1111 | AV33: =DEC2HEX(W33)&DEC2HEX(X33)&DEC2HEX(Y33)&DEC2HEX(Z33) -> 1111 | AW33: =DEC2HEX(AA33)&DEC2HEX(AB33)&DEC2HEX(AC33)&DEC2HEX(AD33) -> 0000 | AX33: =DEC2HEX(AE33)&DEC2HEX(AF33)&DEC2HEX(AG33)&DEC2HEX(AH33) -> 0000 | BB33: 垂直方向を1/2に間引いて設定するため
B34: 29 | C34: 0 | D34: 0 | E34: 0 | F34: 0 | G34: 0 | H34: 0 | I34: 0 | J34: 0 | K34: 0 | L34: 0 | M34: 1 | N34: 1 | O34: 1 | P34: 1 | Q34: 1 | R34: 1 | S34: 1 | T34: 1 | U34: 1 | V34: 1 | W34: 1 | X34: 1 | Y34: 0 | Z34: 0 | AA34: 0 | AB34: 0 | AC34: 0 | AD34: 0 | AE34: 0 | AF34: 0 | AG34: 0 | AH34: 0 | AP34: =B34 -> 29 | AQ34: =DEC2HEX(C34)&DEC2HEX(D34)&DEC2HEX(E34)&DEC2HEX(F34) -> 0000 | AR34: =DEC2HEX(G34)&DEC2HEX(H34)&DEC2HEX(I34)&DEC2HEX(J34) -> 0000 | AS34: =DEC2HEX(K34)&DEC2HEX(L34)&DEC2HEX(M34)&DEC2HEX(N34) -> 0011 | AT34: =DEC2HEX(O34)&DEC2HEX(P34)&DEC2HEX(Q34)&DEC2HEX(R34) -> 1111 | AU34: =DEC2HEX(S34)&DEC2HEX(T34)&DEC2HEX(U34)&DEC2HEX(V34) -> 1111 | AV34: =DEC2HEX(W34)&DEC2HEX(X34)&DEC2HEX(Y34)&DEC2HEX(Z34) -> 1100 | AW34: =DEC2HEX(AA34)&DEC2HEX(AB34)&DEC2HEX(AC34)&DEC2HEX(AD34) -> 0000 | AX34: =DEC2HEX(AE34)&DEC2HEX(AF34)&DEC2HEX(AG34)&DEC2HEX(AH34) -> 0000 | BB34: 奇数列を使用しないのでご注意ください。
B35: 30 | C35: 0 | D35: 0 | E35: 0 | F35: 0 | G35: 0 | H35: 0 | I35: 0 | J35: 0 | K35: 0 | L35: 0 | M35: 0 | N35: 0 | O35: 1 | P35: 1 | Q35: 1 | R35: 1 | S35: 1 | T35: 1 | U35: 1 | V35: 1 | W35: 0 | X35: 0 | Y35: 0 | Z35: 0 | AA35: 0 | AB35: 0 | AC35: 0 | AD35: 0 | AE35: 0 | AF35: 0 | AG35: 0 | AH35: 0 | AP35: =B35 -> 30 | AQ35: =DEC2HEX(C35)&DEC2HEX(D35)&DEC2HEX(E35)&DEC2HEX(F35) -> 0000 | AR35: =DEC2HEX(G35)&DEC2HEX(H35)&DEC2HEX(I35)&DEC2HEX(J35) -> 0000 | AS35: =DEC2HEX(K35)&DEC2HEX(L35)&DEC2HEX(M35)&DEC2HEX(N35) -> 0000 | AT35: =DEC2HEX(O35)&DEC2HEX(P35)&DEC2HEX(Q35)&DEC2HEX(R35) -> 1111 | AU35: =DEC2HEX(S35)&DEC2HEX(T35)&DEC2HEX(U35)&DEC2HEX(V35) -> 1111 | AV35: =DEC2HEX(W35)&DEC2HEX(X35)&DEC2HEX(Y35)&DEC2HEX(Z35) -> 0000 | AW35: =DEC2HEX(AA35)&DEC2HEX(AB35)&DEC2HEX(AC35)&DEC2HEX(AD35) -> 0000 | AX35: =DEC2HEX(AE35)&DEC2HEX(AF35)&DEC2HEX(AG35)&DEC2HEX(AH35) -> 0000 | BB35: ※重み係数はWD.cで変更できます。
B36: 31 | C36: 0 | D36: 0 | E36: 0 | F36: 0 | G36: 0 | H36: 0 | I36: 0 | J36: 0 | K36: 0 | L36: 0 | M36: 0 | N36: 0 | O36: 0 | P36: 0 | Q36: 0 | R36: 0 | S36: 0 | T36: 0 | U36: 0 | V36: 0 | W36: 0 | X36: 0 | Y36: 0 | Z36: 0 | AA36: 0 | AB36: 0 | AC36: 0 | AD36: 0 | AE36: 0 | AF36: 0 | AG36: 0 | AH36: 0 | AP36: =B36 -> 31 | AQ36: =DEC2HEX(C36)&DEC2HEX(D36)&DEC2HEX(E36)&DEC2HEX(F36) -> 0000 | AR36: =DEC2HEX(G36)&DEC2HEX(H36)&DEC2HEX(I36)&DEC2HEX(J36) -> 0000 | AS36: =DEC2HEX(K36)&DEC2HEX(L36)&DEC2HEX(M36)&DEC2HEX(N36) -> 0000 | AT36: =DEC2HEX(O36)&DEC2HEX(P36)&DEC2HEX(Q36)&DEC2HEX(R36) -> 0000 | AU36: =DEC2HEX(S36)&DEC2HEX(T36)&DEC2HEX(U36)&DEC2HEX(V36) -> 0000 | AV36: =DEC2HEX(W36)&DEC2HEX(X36)&DEC2HEX(Y36)&DEC2HEX(Z36) -> 0000 | AW36: =DEC2HEX(AA36)&DEC2HEX(AB36)&DEC2HEX(AC36)&DEC2HEX(AD36) -> 0000 | AX36: =DEC2HEX(AE36)&DEC2HEX(AF36)&DEC2HEX(AG36)&DEC2HEX(AH36) -> 0000
A39: 2.All block integral (Storage to ROM) | AP39: =A39 -> 2.All block integral (Storage to ROM)
C40: 0 | D40: 1 | E40: 2 | F40: 3 | G40: 4 | H40: 5 | I40: 6 | J40: 7 | K40: 8 | L40: 9 | M40: 10 | N40: 11 | O40: 12 | P40: 13 | Q40: 14 | R40: 15 | S40: 16 | T40: 17 | U40: 18 | V40: 19 | W40: 20 | X40: 21 | Y40: 22 | Z40: 23 | AA40: 24 | AB40: 25 | AC40: 26 | AD40: 27 | AE40: 28 | AF40: 29 | AG40: 30 | AH40: 31 | AQ40: =C40&D40&E40&F40 -> 0123 | AR40: =G40&H40&I40&J40 -> 4567 | AS40: =K40&L40&M40&N40 -> 891011 | AT40: =O40&P40&Q40&R40 -> 12131415 | AU40: 16171819 | AV40: 20212223 | AW40: 24252627 | AX40: 28293031
B41: 0 | C41: 2 | D41: 2 | E41: 2 | F41: 2 | G41: 2 | H41: 2 | I41: 2 | J41: 2 | K41: 2 | L41: 2 | M41: 2 | N41: 2 | O41: 2 | P41: 2 | Q41: 2 | R41: 2 | S41: 2 | T41: 2 | U41: 2 | V41: 2 | W41: 2 | X41: 2 | Y41: 2 | Z41: 2 | AA41: 2 | AB41: 2 | AC41: 2 | AD41: 2 | AE41: 2 | AF41: 2 | AG41: 2 | AH41: 2 | AP41: =B41 -> 0 | AQ41: =DEC2HEX(C41)&DEC2HEX(D41)&DEC2HEX(E41)&DEC2HEX(F41) -> 2222 | AR41: =DEC2HEX(G41)&DEC2HEX(H41)&DEC2HEX(I41)&DEC2HEX(J41) -> 2222 | AS41: =DEC2HEX(K41)&DEC2HEX(L41)&DEC2HEX(M41)&DEC2HEX(N41) -> 2222 | AT41: =DEC2HEX(O41)&DEC2HEX(P41)&DEC2HEX(Q41)&DEC2HEX(R41) -> 2222 | AU41: =DEC2HEX(S41)&DEC2HEX(T41)&DEC2HEX(U41)&DEC2HEX(V41) -> 2222 | AV41: =DEC2HEX(W41)&DEC2HEX(X41)&DEC2HEX(Y41)&DEC2HEX(Z41) -> 2222 | AW41: =DEC2HEX(AA41)&DEC2HEX(AB41)&DEC2HEX(AC41)&DEC2HEX(AD41) -> 2222 | AX41: =DEC2HEX(AE41)&DEC2HEX(AF41)&DEC2HEX(AG41)&DEC2HEX(AH41) -> 2222
B42: 1 | C42: 2 | D42: 2 | E42: 2 | F42: 2 | G42: 2 | H42: 2 | I42: 2 | J42: 2 | K42: 2 | L42: 2 | M42: 2 | N42: 2 | O42: 2 | P42: 2 | Q42: 2 | R42: 2 | S42: 2 | T42: 2 | U42: 2 | V42: 2 | W42: 2 | X42: 2 | Y42: 2 | Z42: 2 | AA42: 2 | AB42: 2 | AC42: 2 | AD42: 2 | AE42: 2 | AF42: 2 | AG42: 2 | AH42: 2 | AP42: =B42 -> 1 | AQ42: =DEC2HEX(C42)&DEC2HEX(D42)&DEC2HEX(E42)&DEC2HEX(F42) -> 2222 | AR42: =DEC2HEX(G42)&DEC2HEX(H42)&DEC2HEX(I42)&DEC2HEX(J42) -> 2222 | AS42: =DEC2HEX(K42)&DEC2HEX(L42)&DEC2HEX(M42)&DEC2HEX(N42) -> 2222 | AT42: =DEC2HEX(O42)&DEC2HEX(P42)&DEC2HEX(Q42)&DEC2HEX(R42) -> 2222 | AU42: =DEC2HEX(S42)&DEC2HEX(T42)&DEC2HEX(U42)&DEC2HEX(V42) -> 2222 | AV42: =DEC2HEX(W42)&DEC2HEX(X42)&DEC2HEX(Y42)&DEC2HEX(Z42) -> 2222 | AW42: =DEC2HEX(AA42)&DEC2HEX(AB42)&DEC2HEX(AC42)&DEC2HEX(AD42) -> 2222 | AX42: =DEC2HEX(AE42)&DEC2HEX(AF42)&DEC2HEX(AG42)&DEC2HEX(AH42) -> 2222
B43: 2 | C43: 2 | D43: 2 | E43: 2 | F43: 2 | G43: 2 | H43: 2 | I43: 2 | J43: 2 | K43: 2 | L43: 2 | M43: 2 | N43: 2 | O43: 2 | P43: 2 | Q43: 2 | R43: 2 | S43: 2 | T43: 2 | U43: 2 | V43: 2 | W43: 2 | X43: 2 | Y43: 2 | Z43: 2 | AA43: 2 | AB43: 2 | AC43: 2 | AD43: 2 | AE43: 2 | AF43: 2 | AG43: 2 | AH43: 2 | AP43: =B43 -> 2 | AQ43: =DEC2HEX(C43)&DEC2HEX(D43)&DEC2HEX(E43)&DEC2HEX(F43) -> 2222 | AR43: =DEC2HEX(G43)&DEC2HEX(H43)&DEC2HEX(I43)&DEC2HEX(J43) -> 2222 | AS43: =DEC2HEX(K43)&DEC2HEX(L43)&DEC2HEX(M43)&DEC2HEX(N43) -> 2222 | AT43: =DEC2HEX(O43)&DEC2HEX(P43)&DEC2HEX(Q43)&DEC2HEX(R43) -> 2222 | AU43: =DEC2HEX(S43)&DEC2HEX(T43)&DEC2HEX(U43)&DEC2HEX(V43) -> 2222 | AV43: =DEC2HEX(W43)&DEC2HEX(X43)&DEC2HEX(Y43)&DEC2HEX(Z43) -> 2222 | AW43: =DEC2HEX(AA43)&DEC2HEX(AB43)&DEC2HEX(AC43)&DEC2HEX(AD43) -> 2222 | AX43: =DEC2HEX(AE43)&DEC2HEX(AF43)&DEC2HEX(AG43)&DEC2HEX(AH43) -> 2222
B44: 3 | C44: 2 | D44: 2 | E44: 2 | F44: 2 | G44: 2 | H44: 2 | I44: 2 | J44: 2 | K44: 2 | L44: 2 | M44: 2 | N44: 2 | O44: 2 | P44: 2 | Q44: 2 | R44: 2 | S44: 2 | T44: 2 | U44: 2 | V44: 2 | W44: 2 | X44: 2 | Y44: 2 | Z44: 2 | AA44: 2 | AB44: 2 | AC44: 2 | AD44: 2 | AE44: 2 | AF44: 2 | AG44: 2 | AH44: 2 | AP44: =B44 -> 3 | AQ44: =DEC2HEX(C44)&DEC2HEX(D44)&DEC2HEX(E44)&DEC2HEX(F44) -> 2222 | AR44: =DEC2HEX(G44)&DEC2HEX(H44)&DEC2HEX(I44)&DEC2HEX(J44) -> 2222 | AS44: =DEC2HEX(K44)&DEC2HEX(L44)&DEC2HEX(M44)&DEC2HEX(N44) -> 2222 | AT44: =DEC2HEX(O44)&DEC2HEX(P44)&DEC2HEX(Q44)&DEC2HEX(R44) -> 2222 | AU44: =DEC2HEX(S44)&DEC2HEX(T44)&DEC2HEX(U44)&DEC2HEX(V44) -> 2222 | AV44: =DEC2HEX(W44)&DEC2HEX(X44)&DEC2HEX(Y44)&DEC2HEX(Z44) -> 2222 | AW44: =DEC2HEX(AA44)&DEC2HEX(AB44)&DEC2HEX(AC44)&DEC2HEX(AD44) -> 2222 | AX44: =DEC2HEX(AE44)&DEC2HEX(AF44)&DEC2HEX(AG44)&DEC2HEX(AH44) -> 2222
B45: 4 | C45: 2 | D45: 2 | E45: 2 | F45: 2 | G45: 2 | H45: 2 | I45: 2 | J45: 2 | K45: 2 | L45: 2 | M45: 2 | N45: 2 | O45: 2 | P45: 2 | Q45: 2 | R45: 2 | S45: 2 | T45: 2 | U45: 2 | V45: 2 | W45: 2 | X45: 2 | Y45: 2 | Z45: 2 | AA45: 2 | AB45: 2 | AC45: 2 | AD45: 2 | AE45: 2 | AF45: 2 | AG45: 2 | AH45: 2 | AP45: =B45 -> 4 | AQ45: =DEC2HEX(C45)&DEC2HEX(D45)&DEC2HEX(E45)&DEC2HEX(F45) -> 2222 | AR45: =DEC2HEX(G45)&DEC2HEX(H45)&DEC2HEX(I45)&DEC2HEX(J45) -> 2222 | AS45: =DEC2HEX(K45)&DEC2HEX(L45)&DEC2HEX(M45)&DEC2HEX(N45) -> 2222 | AT45: =DEC2HEX(O45)&DEC2HEX(P45)&DEC2HEX(Q45)&DEC2HEX(R45) -> 2222 | AU45: =DEC2HEX(S45)&DEC2HEX(T45)&DEC2HEX(U45)&DEC2HEX(V45) -> 2222 | AV45: =DEC2HEX(W45)&DEC2HEX(X45)&DEC2HEX(Y45)&DEC2HEX(Z45) -> 2222 | AW45: =DEC2HEX(AA45)&DEC2HEX(AB45)&DEC2HEX(AC45)&DEC2HEX(AD45) -> 2222 | AX45: =DEC2HEX(AE45)&DEC2HEX(AF45)&DEC2HEX(AG45)&DEC2HEX(AH45) -> 2222
...

Sheet AE_w_WORK
B2: Don't change the this sheet becouse of work area.
D4: 1 | E4: 2 | F4: 3 | G4: 4 | H4: 5 | I4: 6 | J4: 7 | K4: 8 | L4: 9 | M4: 10
A5: No | B5: 縦 | C5: 横
A6: 1 | B6: 0 | C6: 1 | D6: =VLOOKUP(B6,AE_weight!$AP$4:$AX$36,C6+1) -> 0000 | E6: =VLOOKUP(B6,AE_weight!$AP$40:$AX$72,C6+1) -> 2222 | F6: =VLOOKUP(B6,AE_weight!$AP$76:$AX$108,C6+1) -> 0000 | G6: =VLOOKUP(B6,AE_weight!$AP$112:$AX$144,C6+1) -> 2222 | H6: =VLOOKUP(B6,AE_weight!$AP$149:$AX$180,C6+1) -> 0000 | I6: =VLOOKUP(B6,AE_weight!$AP$185:$AX$216,C6+1) -> 0000 | J6: =VLOOKUP(B6,AE_weight!$AP$221:$AX$252,C6+1) -> 0000 | K6: =VLOOKUP(B6,AE_weight!$AP$257:$AX$288,C6+1) -> 0000 | L6: =VLOOKUP(B6,AE_weight!$AP$293:$AX$324,C6+1) -> 0000 | M6: =VLOOKUP(B6,AE_weight!$AP$329:$AX$360,C6+1) -> 0000
A7: =A6+1 -> 2 | B7: =B6 -> 0 | C7: 2 | D7: =VLOOKUP(B7,AE_weight!$AP$4:$AX$36,C7+1) -> 0000 | E7: =VLOOKUP(B7,AE_weight!$AP$40:$AX$72,C7+1) -> 2222 | F7: =VLOOKUP(B7,AE_weight!$AP$76:$AX$108,C7+1) -> 0000 | G7: =VLOOKUP(B7,AE_weight!$AP$112:$AX$144,C7+1) -> 2222 | H7: =VLOOKUP(B7,AE_weight!$AP$149:$AX$180,C7+1) -> 0000 | I7: =VLOOKUP(B7,AE_weight!$AP$185:$AX$216,C7+1) -> 0000 | J7: =VLOOKUP(B7,AE_weight!$AP$221:$AX$252,C7+1) -> 0000 | K7: =VLOOKUP(B7,AE_weight!$AP$257:$AX$288,C7+1) -> 0000 | L7: =VLOOKUP(B7,AE_weight!$AP$293:$AX$324,C7+1) -> 0000 | M7: =VLOOKUP(B7,AE_weight!$AP$329:$AX$360,C7+1) -> 0000
A8: =A7+1 -> 3 | B8: =B7 -> 0 | C8: 3 | D8: =VLOOKUP(B8,AE_weight!$AP$4:$AX$36,C8+1) -> 0000 | E8: =VLOOKUP(B8,AE_weight!$AP$40:$AX$72,C8+1) -> 2222 | F8: =VLOOKUP(B8,AE_weight!$AP$76:$AX$108,C8+1) -> 0000 | G8: =VLOOKUP(B8,AE_weight!$AP$112:$AX$144,C8+1) -> 2222 | H8: =VLOOKUP(B8,AE_weight!$AP$149:$AX$180,C8+1) -> 0000 | I8: =VLOOKUP(B8,AE_weight!$AP$185:$AX$216,C8+1) -> 0000 | J8: =VLOOKUP(B8,AE_weight!$AP$221:$AX$252,C8+1) -> 0000 | K8: =VLOOKUP(B8,AE_weight!$AP$257:$AX$288,C8+1) -> 0000 | L8: =VLOOKUP(B8,AE_weight!$AP$293:$AX$324,C8+1) -> 0000 | M8: =VLOOKUP(B8,AE_weight!$AP$329:$AX$360,C8+1) -> 0000
A9: =A8+1 -> 4 | B9: =B8 -> 0 | C9: 4 | D9: =VLOOKUP(B9,AE_weight!$AP$4:$AX$36,C9+1) -> 0000 | E9: =VLOOKUP(B9,AE_weight!$AP$40:$AX$72,C9+1) -> 2222 | F9: =VLOOKUP(B9,AE_weight!$AP$76:$AX$108,C9+1) -> 0000 | G9: =VLOOKUP(B9,AE_weight!$AP$112:$AX$144,C9+1) -> 2222 | H9: =VLOOKUP(B9,AE_weight!$AP$149:$AX$180,C9+1) -> 0000 | I9: =VLOOKUP(B9,AE_weight!$AP$185:$AX$216,C9+1) -> 0000 | J9: =VLOOKUP(B9,AE_weight!$AP$221:$AX$252,C9+1) -> 0000 | K9: =VLOOKUP(B9,AE_weight!$AP$257:$AX$288,C9+1) -> 0000 | L9: =VLOOKUP(B9,AE_weight!$AP$293:$AX$324,C9+1) -> 0000 | M9: =VLOOKUP(B9,AE_weight!$AP$329:$AX$360,C9+1) -> 0000
A10: =A9+1 -> 5 | B10: 0 | C10: 5 | D10: =VLOOKUP(B10,AE_weight!$AP$4:$AX$36,C10+1) -> 0000 | E10: =VLOOKUP(B10,AE_weight!$AP$40:$AX$72,C10+1) -> 2222 | F10: =VLOOKUP(B10,AE_weight!$AP$76:$AX$108,C10+1) -> 0000 | G10: =VLOOKUP(B10,AE_weight!$AP$112:$AX$144,C10+1) -> 2222 | H10: =VLOOKUP(B10,AE_weight!$AP$149:$AX$180,C10+1) -> 0000 | I10: =VLOOKUP(B10,AE_weight!$AP$185:$AX$216,C10+1) -> 0000 | J10: =VLOOKUP(B10,AE_weight!$AP$221:$AX$252,C10+1) -> 0000 | K10: =VLOOKUP(B10,AE_weight!$AP$257:$AX$288,C10+1) -> 0000 | L10: =VLOOKUP(B10,AE_weight!$AP$293:$AX$324,C10+1) -> 0000 | M10: =VLOOKUP(B10,AE_weight!$AP$329:$AX$360,C10+1) -> 0000
A11: =A10+1 -> 6 | B11: =B10 -> 0 | C11: 6 | D11: =VLOOKUP(B11,AE_weight!$AP$4:$AX$36,C11+1) -> 0000 | E11: =VLOOKUP(B11,AE_weight!$AP$40:$AX$72,C11+1) -> 2222 | F11: =VLOOKUP(B11,AE_weight!$AP$76:$AX$108,C11+1) -> 0000 | G11: =VLOOKUP(B11,AE_weight!$AP$112:$AX$144,C11+1) -> 2222 | H11: =VLOOKUP(B11,AE_weight!$AP$149:$AX$180,C11+1) -> 0000 | I11: =VLOOKUP(B11,AE_weight!$AP$185:$AX$216,C11+1) -> 0000 | J11: =VLOOKUP(B11,AE_weight!$AP$221:$AX$252,C11+1) -> 0000 | K11: =VLOOKUP(B11,AE_weight!$AP$257:$AX$288,C11+1) -> 0000 | L11: =VLOOKUP(B11,AE_weight!$AP$293:$AX$324,C11+1) -> 0000 | M11: =VLOOKUP(B11,AE_weight!$AP$329:$AX$360,C11+1) -> 0000
A12: =A11+1 -> 7 | B12: =B11 -> 0 | C12: 7 | D12: =VLOOKUP(B12,AE_weight!$AP$4:$AX$36,C12+1) -> 0000 | E12: =VLOOKUP(B12,AE_weight!$AP$40:$AX$72,C12+1) -> 2222 | F12: =VLOOKUP(B12,AE_weight!$AP$76:$AX$108,C12+1) -> 0000 | G12: =VLOOKUP(B12,AE_weight!$AP$112:$AX$144,C12+1) -> 2222 | H12: =VLOOKUP(B12,AE_weight!$AP$149:$AX$180,C12+1) -> 0000 | I12: =VLOOKUP(B12,AE_weight!$AP$185:$AX$216,C12+1) -> 0000 | J12: =VLOOKUP(B12,AE_weight!$AP$221:$AX$252,C12+1) -> 0000 | K12: =VLOOKUP(B12,AE_weight!$AP$257:$AX$288,C12+1) -> 0000 | L12: =VLOOKUP(B12,AE_weight!$AP$293:$AX$324,C12+1) -> 0000 | M12: =VLOOKUP(B12,AE_weight!$AP$329:$AX$360,C12+1) -> 0000
A13: =A12+1 -> 8 | B13: =B12 -> 0 | C13: 8 | D13: =VLOOKUP(B13,AE_weight!$AP$4:$AX$36,C13+1) -> 0000 | E13: =VLOOKUP(B13,AE_weight!$AP$40:$AX$72,C13+1) -> 2222 | F13: =VLOOKUP(B13,AE_weight!$AP$76:$AX$108,C13+1) -> 0000 | G13: =VLOOKUP(B13,AE_weight!$AP$112:$AX$144,C13+1) -> 2222 | H13: =VLOOKUP(B13,AE_weight!$AP$149:$AX$180,C13+1) -> 0000 | I13: =VLOOKUP(B13,AE_weight!$AP$185:$AX$216,C13+1) -> 0000 | J13: =VLOOKUP(B13,AE_weight!$AP$221:$AX$252,C13+1) -> 0000 | K13: =VLOOKUP(B13,AE_weight!$AP$257:$AX$288,C13+1) -> 0000 | L13: =VLOOKUP(B13,AE_weight!$AP$293:$AX$324,C13+1) -> 0000 | M13: =VLOOKUP(B13,AE_weight!$AP$329:$AX$360,C13+1) -> 0000
A14: =A13+1 -> 9 | B14: 1 | C14: 1 | D14: =VLOOKUP(B14,AE_weight!$AP$4:$AX$36,C14+1) -> 0000 | E14: =VLOOKUP(B14,AE_weight!$AP$40:$AX$72,C14+1) -> 2222 | F14: =VLOOKUP(B14,AE_weight!$AP$76:$AX$108,C14+1) -> 0000 | G14: =VLOOKUP(B14,AE_weight!$AP$112:$AX$144,C14+1) -> 2222 | H14: =VLOOKUP(B14,AE_weight!$AP$149:$AX$180,C14+1) -> 0000 | I14: =VLOOKUP(B14,AE_weight!$AP$185:$AX$216,C14+1) -> 0000 | J14: =VLOOKUP(B14,AE_weight!$AP$221:$AX$252,C14+1) -> 0000 | K14: =VLOOKUP(B14,AE_weight!$AP$257:$AX$288,C14+1) -> 0000 | L14: =VLOOKUP(B14,AE_weight!$AP$293:$AX$324,C14+1) -> 0000 | M14: =VLOOKUP(B14,AE_weight!$AP$329:$AX$360,C14+1) -> 0000
A15: =A14+1 -> 10 | B15: =B14 -> 1 | C15: 2 | D15: =VLOOKUP(B15,AE_weight!$AP$4:$AX$36,C15+1) -> 0000 | E15: =VLOOKUP(B15,AE_weight!$AP$40:$AX$72,C15+1) -> 2222 | F15: =VLOOKUP(B15,AE_weight!$AP$76:$AX$108,C15+1) -> 0000 | G15: =VLOOKUP(B15,AE_weight!$AP$112:$AX$144,C15+1) -> 2222 | H15: =VLOOKUP(B15,AE_weight!$AP$149:$AX$180,C15+1) -> 0000 | I15: =VLOOKUP(B15,AE_weight!$AP$185:$AX$216,C15+1) -> 0000 | J15: =VLOOKUP(B15,AE_weight!$AP$221:$AX$252,C15+1) -> 0000 | K15: =VLOOKUP(B15,AE_weight!$AP$257:$AX$288,C15+1) -> 0000 | L15: =VLOOKUP(B15,AE_weight!$AP$293:$AX$324,C15+1) -> 0000 | M15: =VLOOKUP(B15,AE_weight!$AP$329:$AX$360,C15+1) -> 0000
A16: =A15+1 -> 11 | B16: =B15 -> 1 | C16: 3 | D16: =VLOOKUP(B16,AE_weight!$AP$4:$AX$36,C16+1) -> 0000 | E16: =VLOOKUP(B16,AE_weight!$AP$40:$AX$72,C16+1) -> 2222 | F16: =VLOOKUP(B16,AE_weight!$AP$76:$AX$108,C16+1) -> 0000 | G16: =VLOOKUP(B16,AE_weight!$AP$112:$AX$144,C16+1) -> 2222 | H16: =VLOOKUP(B16,AE_weight!$AP$149:$AX$180,C16+1) -> 0000 | I16: =VLOOKUP(B16,AE_weight!$AP$185:$AX$216,C16+1) -> 0000 | J16: =VLOOKUP(B16,AE_weight!$AP$221:$AX$252,C16+1) -> 0000 | K16: =VLOOKUP(B16,AE_weight!$AP$257:$AX$288,C16+1) -> 0000 | L16: =VLOOKUP(B16,AE_weight!$AP$293:$AX$324,C16+1) -> 0000 | M16: =VLOOKUP(B16,AE_weight!$AP$329:$AX$360,C16+1) -> 0000
A17: =A16+1 -> 12 | B17: =B16 -> 1 | C17: 4 | D17: =VLOOKUP(B17,AE_weight!$AP$4:$AX$36,C17+1) -> 1111 | E17: =VLOOKUP(B17,AE_weight!$AP$40:$AX$72,C17+1) -> 2222 | F17: =VLOOKUP(B17,AE_weight!$AP$76:$AX$108,C17+1) -> 0000 | G17: =VLOOKUP(B17,AE_weight!$AP$112:$AX$144,C17+1) -> 2222 | H17: =VLOOKUP(B17,AE_weight!$AP$149:$AX$180,C17+1) -> 0000 | I17: =VLOOKUP(B17,AE_weight!$AP$185:$AX$216,C17+1) -> 0000 | J17: =VLOOKUP(B17,AE_weight!$AP$221:$AX$252,C17+1) -> 0000 | K17: =VLOOKUP(B17,AE_weight!$AP$257:$AX$288,C17+1) -> 0000 | L17: =VLOOKUP(B17,AE_weight!$AP$293:$AX$324,C17+1) -> 0000 | M17: =VLOOKUP(B17,AE_weight!$AP$329:$AX$360,C17+1) -> 0000
A18: =A17+1 -> 13 | B18: 1 | C18: 5 | D18: =VLOOKUP(B18,AE_weight!$AP$4:$AX$36,C18+1) -> 1111 | E18: =VLOOKUP(B18,AE_weight!$AP$40:$AX$72,C18+1) -> 2222 | F18: =VLOOKUP(B18,AE_weight!$AP$76:$AX$108,C18+1) -> 0000 | G18: =VLOOKUP(B18,AE_weight!$AP$112:$AX$144,C18+1) -> 2222 | H18: =VLOOKUP(B18,AE_weight!$AP$149:$AX$180,C18+1) -> 0000 | I18: =VLOOKUP(B18,AE_weight!$AP$185:$AX$216,C18+1) -> 0000 | J18: =VLOOKUP(B18,AE_weight!$AP$221:$AX$252,C18+1) -> 0000 | K18: =VLOOKUP(B18,AE_weight!$AP$257:$AX$288,C18+1) -> 0000 | L18: =VLOOKUP(B18,AE_weight!$AP$293:$AX$324,C18+1) -> 0000 | M18: =VLOOKUP(B18,AE_weight!$AP$329:$AX$360,C18+1) -> 0000
A19: =A18+1 -> 14 | B19: =B18 -> 1 | C19: 6 | D19: =VLOOKUP(B19,AE_weight!$AP$4:$AX$36,C19+1) -> 0000 | E19: =VLOOKUP(B19,AE_weight!$AP$40:$AX$72,C19+1) -> 2222 | F19: =VLOOKUP(B19,AE_weight!$AP$76:$AX$108,C19+1) -> 0000 | G19: =VLOOKUP(B19,AE_weight!$AP$112:$AX$144,C19+1) -> 2222 | H19: =VLOOKUP(B19,AE_weight!$AP$149:$AX$180,C19+1) -> 0000 | I19: =VLOOKUP(B19,AE_weight!$AP$185:$AX$216,C19+1) -> 0000 | J19: =VLOOKUP(B19,AE_weight!$AP$221:$AX$252,C19+1) -> 0000 | K19: =VLOOKUP(B19,AE_weight!$AP$257:$AX$288,C19+1) -> 0000 | L19: =VLOOKUP(B19,AE_weight!$AP$293:$AX$324,C19+1) -> 0000 | M19: =VLOOKUP(B19,AE_weight!$AP$329:$AX$360,C19+1) -> 0000
A20: =A19+1 -> 15 | B20: =B19 -> 1 | C20: 7 | D20: =VLOOKUP(B20,AE_weight!$AP$4:$AX$36,C20+1) -> 0000 | E20: =VLOOKUP(B20,AE_weight!$AP$40:$AX$72,C20+1) -> 2222 | F20: =VLOOKUP(B20,AE_weight!$AP$76:$AX$108,C20+1) -> 0000 | G20: =VLOOKUP(B20,AE_weight!$AP$112:$AX$144,C20+1) -> 2222 | H20: =VLOOKUP(B20,AE_weight!$AP$149:$AX$180,C20+1) -> 0000 | I20: =VLOOKUP(B20,AE_weight!$AP$185:$AX$216,C20+1) -> 0000 | J20: =VLOOKUP(B20,AE_weight!$AP$221:$AX$252,C20+1) -> 0000 | K20: =VLOOKUP(B20,AE_weight!$AP$257:$AX$288,C20+1) -> 0000 | L20: =VLOOKUP(B20,AE_weight!$AP$293:$AX$324,C20+1) -> 0000 | M20: =VLOOKUP(B20,AE_weight!$AP$329:$AX$360,C20+1) -> 0000
A21: =A20+1 -> 16 | B21: =B20 -> 1 | C21: 8 | D21: =VLOOKUP(B21,AE_weight!$AP$4:$AX$36,C21+1) -> 0000 | E21: =VLOOKUP(B21,AE_weight!$AP$40:$AX$72,C21+1) -> 2222 | F21: =VLOOKUP(B21,AE_weight!$AP$76:$AX$108,C21+1) -> 0000 | G21: =VLOOKUP(B21,AE_weight!$AP$112:$AX$144,C21+1) -> 2222 | H21: =VLOOKUP(B21,AE_weight!$AP$149:$AX$180,C21+1) -> 0000 | I21: =VLOOKUP(B21,AE_weight!$AP$185:$AX$216,C21+1) -> 0000 | J21: =VLOOKUP(B21,AE_weight!$AP$221:$AX$252,C21+1) -> 0000 | K21: =VLOOKUP(B21,AE_weight!$AP$257:$AX$288,C21+1) -> 0000 | L21: =VLOOKUP(B21,AE_weight!$AP$293:$AX$324,C21+1) -> 0000 | M21: =VLOOKUP(B21,AE_weight!$AP$329:$AX$360,C21+1) -> 0000
A22: =A21+1 -> 17 | B22: 2 | C22: 1 | D22: =VLOOKUP(B22,AE_weight!$AP$4:$AX$36,C22+1) -> 0000 | E22: =VLOOKUP(B22,AE_weight!$AP$40:$AX$72,C22+1) -> 2222 | F22: =VLOOKUP(B22,AE_weight!$AP$76:$AX$108,C22+1) -> 0000 | G22: =VLOOKUP(B22,AE_weight!$AP$112:$AX$144,C22+1) -> 2222 | H22: =VLOOKUP(B22,AE_weight!$AP$149:$AX$180,C22+1) -> 0000 | I22: =VLOOKUP(B22,AE_weight!$AP$185:$AX$216,C22+1) -> 0000 | J22: =VLOOKUP(B22,AE_weight!$AP$221:$AX$252,C22+1) -> 0000 | K22: =VLOOKUP(B22,AE_weight!$AP$257:$AX$288,C22+1) -> 0000 | L22: =VLOOKUP(B22,AE_weight!$AP$293:$AX$324,C22+1) -> 0000 | M22: =VLOOKUP(B22,AE_weight!$AP$329:$AX$360,C22+1) -> 0000
A23: =A22+1 -> 18 | B23: =B22 -> 2 | C23: 2 | D23: =VLOOKUP(B23,AE_weight!$AP$4:$AX$36,C23+1) -> 0000 | E23: =VLOOKUP(B23,AE_weight!$AP$40:$AX$72,C23+1) -> 2222 | F23: =VLOOKUP(B23,AE_weight!$AP$76:$AX$108,C23+1) -> 0000 | G23: =VLOOKUP(B23,AE_weight!$AP$112:$AX$144,C23+1) -> 2222 | H23: =VLOOKUP(B23,AE_weight!$AP$149:$AX$180,C23+1) -> 0000 | I23: =VLOOKUP(B23,AE_weight!$AP$185:$AX$216,C23+1) -> 0000 | J23: =VLOOKUP(B23,AE_weight!$AP$221:$AX$252,C23+1) -> 0000 | K23: =VLOOKUP(B23,AE_weight!$AP$257:$AX$288,C23+1) -> 0000 | L23: =VLOOKUP(B23,AE_weight!$AP$293:$AX$324,C23+1) -> 0000 | M23: =VLOOKUP(B23,AE_weight!$AP$329:$AX$360,C23+1) -> 0000
A24: =A23+1 -> 19 | B24: =B23 -> 2 | C24: 3 | D24: =VLOOKUP(B24,AE_weight!$AP$4:$AX$36,C24+1) -> 0011 | E24: =VLOOKUP(B24,AE_weight!$AP$40:$AX$72,C24+1) -> 2222 | F24: =VLOOKUP(B24,AE_weight!$AP$76:$AX$108,C24+1) -> 0000 | G24: =VLOOKUP(B24,AE_weight!$AP$112:$AX$144,C24+1) -> 2222 | H24: =VLOOKUP(B24,AE_weight!$AP$149:$AX$180,C24+1) -> 0000 | I24: =VLOOKUP(B24,AE_weight!$AP$185:$AX$216,C24+1) -> 0000 | J24: =VLOOKUP(B24,AE_weight!$AP$221:$AX$252,C24+1) -> 0000 | K24: =VLOOKUP(B24,AE_weight!$AP$257:$AX$288,C24+1) -> 0000 | L24: =VLOOKUP(B24,AE_weight!$AP$293:$AX$324,C24+1) -> 0000 | M24: =VLOOKUP(B24,AE_weight!$AP$329:$AX$360,C24+1) -> 0000
A25: =A24+1 -> 20 | B25: =B24 -> 2 | C25: 4 | D25: =VLOOKUP(B25,AE_weight!$AP$4:$AX$36,C25+1) -> 1111 | E25: =VLOOKUP(B25,AE_weight!$AP$40:$AX$72,C25+1) -> 2222 | F25: =VLOOKUP(B25,AE_weight!$AP$76:$AX$108,C25+1) -> 0000 | G25: =VLOOKUP(B25,AE_weight!$AP$112:$AX$144,C25+1) -> 2222 | H25: =VLOOKUP(B25,AE_weight!$AP$149:$AX$180,C25+1) -> 0000 | I25: =VLOOKUP(B25,AE_weight!$AP$185:$AX$216,C25+1) -> 0000 | J25: =VLOOKUP(B25,AE_weight!$AP$221:$AX$252,C25+1) -> 0000 | K25: =VLOOKUP(B25,AE_weight!$AP$257:$AX$288,C25+1) -> 0000 | L25: =VLOOKUP(B25,AE_weight!$AP$293:$AX$324,C25+1) -> 0000 | M25: =VLOOKUP(B25,AE_weight!$AP$329:$AX$360,C25+1) -> 0000
A26: =A25+1 -> 21 | B26: 2 | C26: 5 | D26: =VLOOKUP(B26,AE_weight!$AP$4:$AX$36,C26+1) -> 1111 | E26: =VLOOKUP(B26,AE_weight!$AP$40:$AX$72,C26+1) -> 2222 | F26: =VLOOKUP(B26,AE_weight!$AP$76:$AX$108,C26+1) -> 0000 | G26: =VLOOKUP(B26,AE_weight!$AP$112:$AX$144,C26+1) -> 2222 | H26: =VLOOKUP(B26,AE_weight!$AP$149:$AX$180,C26+1) -> 0000 | I26: =VLOOKUP(B26,AE_weight!$AP$185:$AX$216,C26+1) -> 0000 | J26: =VLOOKUP(B26,AE_weight!$AP$221:$AX$252,C26+1) -> 0000 | K26: =VLOOKUP(B26,AE_weight!$AP$257:$AX$288,C26+1) -> 0000 | L26: =VLOOKUP(B26,AE_weight!$AP$293:$AX$324,C26+1) -> 0000 | M26: =VLOOKUP(B26,AE_weight!$AP$329:$AX$360,C26+1) -> 0000
A27: =A26+1 -> 22 | B27: =B26 -> 2 | C27: 6 | D27: =VLOOKUP(B27,AE_weight!$AP$4:$AX$36,C27+1) -> 1100 | E27: =VLOOKUP(B27,AE_weight!$AP$40:$AX$72,C27+1) -> 2222 | F27: =VLOOKUP(B27,AE_weight!$AP$76:$AX$108,C27+1) -> 0000 | G27: =VLOOKUP(B27,AE_weight!$AP$112:$AX$144,C27+1) -> 2222 | H27: =VLOOKUP(B27,AE_weight!$AP$149:$AX$180,C27+1) -> 0000 | I27: =VLOOKUP(B27,AE_weight!$AP$185:$AX$216,C27+1) -> 0000 | J27: =VLOOKUP(B27,AE_weight!$AP$221:$AX$252,C27+1) -> 0000 | K27: =VLOOKUP(B27,AE_weight!$AP$257:$AX$288,C27+1) -> 0000 | L27: =VLOOKUP(B27,AE_weight!$AP$293:$AX$324,C27+1) -> 0000 | M27: =VLOOKUP(B27,AE_weight!$AP$329:$AX$360,C27+1) -> 0000
A28: =A27+1 -> 23 | B28: =B27 -> 2 | C28: 7 | D28: =VLOOKUP(B28,AE_weight!$AP$4:$AX$36,C28+1) -> 0000 | E28: =VLOOKUP(B28,AE_weight!$AP$40:$AX$72,C28+1) -> 2222 | F28: =VLOOKUP(B28,AE_weight!$AP$76:$AX$108,C28+1) -> 0000 | G28: =VLOOKUP(B28,AE_weight!$AP$112:$AX$144,C28+1) -> 2222 | H28: =VLOOKUP(B28,AE_weight!$AP$149:$AX$180,C28+1) -> 0000 | I28: =VLOOKUP(B28,AE_weight!$AP$185:$AX$216,C28+1) -> 0000 | J28: =VLOOKUP(B28,AE_weight!$AP$221:$AX$252,C28+1) -> 0000 | K28: =VLOOKUP(B28,AE_weight!$AP$257:$AX$288,C28+1) -> 0000 | L28: =VLOOKUP(B28,AE_weight!$AP$293:$AX$324,C28+1) -> 0000 | M28: =VLOOKUP(B28,AE_weight!$AP$329:$AX$360,C28+1) -> 0000
A29: =A28+1 -> 24 | B29: =B28 -> 2 | C29: 8 | D29: =VLOOKUP(B29,AE_weight!$AP$4:$AX$36,C29+1) -> 0000 | E29: =VLOOKUP(B29,AE_weight!$AP$40:$AX$72,C29+1) -> 2222 | F29: =VLOOKUP(B29,AE_weight!$AP$76:$AX$108,C29+1) -> 0000 | G29: =VLOOKUP(B29,AE_weight!$AP$112:$AX$144,C29+1) -> 2222 | H29: =VLOOKUP(B29,AE_weight!$AP$149:$AX$180,C29+1) -> 0000 | I29: =VLOOKUP(B29,AE_weight!$AP$185:$AX$216,C29+1) -> 0000 | J29: =VLOOKUP(B29,AE_weight!$AP$221:$AX$252,C29+1) -> 0000 | K29: =VLOOKUP(B29,AE_weight!$AP$257:$AX$288,C29+1) -> 0000 | L29: =VLOOKUP(B29,AE_weight!$AP$293:$AX$324,C29+1) -> 0000 | M29: =VLOOKUP(B29,AE_weight!$AP$329:$AX$360,C29+1) -> 0000
A30: =A29+1 -> 25 | B30: 3 | C30: 1 | D30: =VLOOKUP(B30,AE_weight!$AP$4:$AX$36,C30+1) -> 0000 | E30: =VLOOKUP(B30,AE_weight!$AP$40:$AX$72,C30+1) -> 2222 | F30: =VLOOKUP(B30,AE_weight!$AP$76:$AX$108,C30+1) -> 0000 | G30: =VLOOKUP(B30,AE_weight!$AP$112:$AX$144,C30+1) -> 2222 | H30: =VLOOKUP(B30,AE_weight!$AP$149:$AX$180,C30+1) -> 0000 | I30: =VLOOKUP(B30,AE_weight!$AP$185:$AX$216,C30+1) -> 0000 | J30: =VLOOKUP(B30,AE_weight!$AP$221:$AX$252,C30+1) -> 0000 | K30: =VLOOKUP(B30,AE_weight!$AP$257:$AX$288,C30+1) -> 0000 | L30: =VLOOKUP(B30,AE_weight!$AP$293:$AX$324,C30+1) -> 0000 | M30: =VLOOKUP(B30,AE_weight!$AP$329:$AX$360,C30+1) -> 0000
A31: =A30+1 -> 26 | B31: =B30 -> 3 | C31: 2 | D31: =VLOOKUP(B31,AE_weight!$AP$4:$AX$36,C31+1) -> 0000 | E31: =VLOOKUP(B31,AE_weight!$AP$40:$AX$72,C31+1) -> 2222 | F31: =VLOOKUP(B31,AE_weight!$AP$76:$AX$108,C31+1) -> 0000 | G31: =VLOOKUP(B31,AE_weight!$AP$112:$AX$144,C31+1) -> 2222 | H31: =VLOOKUP(B31,AE_weight!$AP$149:$AX$180,C31+1) -> 0000 | I31: =VLOOKUP(B31,AE_weight!$AP$185:$AX$216,C31+1) -> 0000 | J31: =VLOOKUP(B31,AE_weight!$AP$221:$AX$252,C31+1) -> 0000 | K31: =VLOOKUP(B31,AE_weight!$AP$257:$AX$288,C31+1) -> 0000 | L31: =VLOOKUP(B31,AE_weight!$AP$293:$AX$324,C31+1) -> 0000 | M31: =VLOOKUP(B31,AE_weight!$AP$329:$AX$360,C31+1) -> 0000
A32: =A31+1 -> 27 | B32: =B31 -> 3 | C32: 3 | D32: =VLOOKUP(B32,AE_weight!$AP$4:$AX$36,C32+1) -> 1111 | E32: =VLOOKUP(B32,AE_weight!$AP$40:$AX$72,C32+1) -> 2222 | F32: =VLOOKUP(B32,AE_weight!$AP$76:$AX$108,C32+1) -> 0000 | G32: =VLOOKUP(B32,AE_weight!$AP$112:$AX$144,C32+1) -> 2222 | H32: =VLOOKUP(B32,AE_weight!$AP$149:$AX$180,C32+1) -> 0000 | I32: =VLOOKUP(B32,AE_weight!$AP$185:$AX$216,C32+1) -> 0000 | J32: =VLOOKUP(B32,AE_weight!$AP$221:$AX$252,C32+1) -> 0000 | K32: =VLOOKUP(B32,AE_weight!$AP$257:$AX$288,C32+1) -> 0000 | L32: =VLOOKUP(B32,AE_weight!$AP$293:$AX$324,C32+1) -> 0000 | M32: =VLOOKUP(B32,AE_weight!$AP$329:$AX$360,C32+1) -> 0000
A33: =A32+1 -> 28 | B33: =B32 -> 3 | C33: 4 | D33: =VLOOKUP(B33,AE_weight!$AP$4:$AX$36,C33+1) -> 1111 | E33: =VLOOKUP(B33,AE_weight!$AP$40:$AX$72,C33+1) -> 2222 | F33: =VLOOKUP(B33,AE_weight!$AP$76:$AX$108,C33+1) -> 0000 | G33: =VLOOKUP(B33,AE_weight!$AP$112:$AX$144,C33+1) -> 2222 | H33: =VLOOKUP(B33,AE_weight!$AP$149:$AX$180,C33+1) -> 0000 | I33: =VLOOKUP(B33,AE_weight!$AP$185:$AX$216,C33+1) -> 0000 | J33: =VLOOKUP(B33,AE_weight!$AP$221:$AX$252,C33+1) -> 0000 | K33: =VLOOKUP(B33,AE_weight!$AP$257:$AX$288,C33+1) -> 0000 | L33: =VLOOKUP(B33,AE_weight!$AP$293:$AX$324,C33+1) -> 0000 | M33: =VLOOKUP(B33,AE_weight!$AP$329:$AX$360,C33+1) -> 1111
A34: =A33+1 -> 29 | B34: 3 | C34: 5 | D34: =VLOOKUP(B34,AE_weight!$AP$4:$AX$36,C34+1) -> 1111 | E34: =VLOOKUP(B34,AE_weight!$AP$40:$AX$72,C34+1) -> 2222 | F34: =VLOOKUP(B34,AE_weight!$AP$76:$AX$108,C34+1) -> 0000 | G34: =VLOOKUP(B34,AE_weight!$AP$112:$AX$144,C34+1) -> 2222 | H34: =VLOOKUP(B34,AE_weight!$AP$149:$AX$180,C34+1) -> 0000 | I34: =VLOOKUP(B34,AE_weight!$AP$185:$AX$216,C34+1) -> 0000 | J34: =VLOOKUP(B34,AE_weight!$AP$221:$AX$252,C34+1) -> 0000 | K34: =VLOOKUP(B34,AE_weight!$AP$257:$AX$288,C34+1) -> 0000 | L34: =VLOOKUP(B34,AE_weight!$AP$293:$AX$324,C34+1) -> 0000 | M34: =VLOOKUP(B34,AE_weight!$AP$329:$AX$360,C34+1) -> 1111
A35: =A34+1 -> 30 | B35: =B34 -> 3 | C35: 6 | D35: =VLOOKUP(B35,AE_weight!$AP$4:$AX$36,C35+1) -> 1111 | E35: =VLOOKUP(B35,AE_weight!$AP$40:$AX$72,C35+1) -> 2222 | F35: =VLOOKUP(B35,AE_weight!$AP$76:$AX$108,C35+1) -> 0000 | G35: =VLOOKUP(B35,AE_weight!$AP$112:$AX$144,C35+1) -> 2222 | H35: =VLOOKUP(B35,AE_weight!$AP$149:$AX$180,C35+1) -> 0000 | I35: =VLOOKUP(B35,AE_weight!$AP$185:$AX$216,C35+1) -> 0000 | J35: =VLOOKUP(B35,AE_weight!$AP$221:$AX$252,C35+1) -> 0000 | K35: =VLOOKUP(B35,AE_weight!$AP$257:$AX$288,C35+1) -> 0000 | L35: =VLOOKUP(B35,AE_weight!$AP$293:$AX$324,C35+1) -> 0000 | M35: =VLOOKUP(B35,AE_weight!$AP$329:$AX$360,C35+1) -> 0000
A36: =A35+1 -> 31 | B36: =B35 -> 3 | C36: 7 | D36: =VLOOKUP(B36,AE_weight!$AP$4:$AX$36,C36+1) -> 0000 | E36: =VLOOKUP(B36,AE_weight!$AP$40:$AX$72,C36+1) -> 2222 | F36: =VLOOKUP(B36,AE_weight!$AP$76:$AX$108,C36+1) -> 0000 | G36: =VLOOKUP(B36,AE_weight!$AP$112:$AX$144,C36+1) -> 2222 | H36: =VLOOKUP(B36,AE_weight!$AP$149:$AX$180,C36+1) -> 0000 | I36: =VLOOKUP(B36,AE_weight!$AP$185:$AX$216,C36+1) -> 0000 | J36: =VLOOKUP(B36,AE_weight!$AP$221:$AX$252,C36+1) -> 0000 | K36: =VLOOKUP(B36,AE_weight!$AP$257:$AX$288,C36+1) -> 0000 | L36: =VLOOKUP(B36,AE_weight!$AP$293:$AX$324,C36+1) -> 0000 | M36: =VLOOKUP(B36,AE_weight!$AP$329:$AX$360,C36+1) -> 0000
